Workbook
Name Data: #REF!
Name FS1_formula: #REF!
Name FS2_f: #REF!
Name FS3_f: #REF!
Name FS3_formula: #REF!
Name FS4_formula: #REF!
Name FS5_formula: #REF!
Name FS6_f: #REF!
Name FS6B_f: #REF!
Name FS7_f: #REF!
Name FS7_formula: 'FS7 PY'!$AE$4:$AW$26
Name FS7_formula: #REF!
Name FS8_f: #REF!
Name FS8B_f: #REF!
Name FS8C_f: #REF!
Name FS8D_f: #REF!
Name FS9_f: #REF!
Name FS9_formula: [1]FS9!#REF!
Name HR2_f: #REF!
Name HR2_formula: #REF!
Name HR3_formula: #REF!
Name HR4_formula: #REF!
Name HR5_formula: #REF!

Sheet Cover
A6: 2025_26
A7: Operational Statistics Collection
A8: FS Tables Incomplete Storeys
A10: =VLOOKUP(B250,B251:D316,2,FALSE) -> Shropshire
A11: =VLOOKUP(B250,B251:D316,3,FALSE) -> E31000032
A13: Index of Tables | B13: Description
A14: FS1 | B14: Fire Safety Audits and Outcomes
A15: FS2 | B15: Number of premises and other fire safety activities
A16: FS6a | B16: Non-compliance resulting in action of any type (excluding prosecutions) Art 8-19
A17: FS6b | B17: Non-compliance resulting in action of any type (excluding prosecutions) Art.20-24, 27, 29-32, 37-38
A18: FS7 | B18: Prosecutions
A19: FS8a | B19: Prosecutions - convictions Art.8-19
A20: FS8b | B20: Prosecutions - convictions Art.20-24, 27, 29-32, 37-38
A21: FS8c | B21: Prosecutions - acquittals Art.8-19
A22: FS8d | B22: Prosecutions - acquittals Art.20-24, 27, 29-32, 37-38
A23: FS9 | B23: Petroleum, explosives and dangerous substances
A24: FS10 | B24: Number of staff employed by FRS for Fire safety activities
A25: Guidance | B25: Guidance notes
A27: Key
A28: 999999 | B28: Cells highlighted yellow following data entry indicate a significant change in the figures inputted relative to the previous year. Please double check the relevant figures prior to submitting this return.
A30: Please complete by Friday 1 May 2026 and send the spreadsheet as an attachment via e-mail to firestatistics@homeoffice.gov.uk
A32: Contact
A33: E-mail Address
A35: If you have any comments on the data submitted please provide them in the box below. If not, please leave blank.
A250: FRS Selector>>>>> | B250: 35 | C250: =MAX(B251:B316) -> 44
B251: 1 | C251: Avon | D251: E31000001
B252: 2 | C252: Bedfordshire | D252: E31000002
B253: 3 | C253: Berkshire | D253: E31000003
B254: 4 | C254: Buckinghamshire | D254: E31000004
B255: 5 | C255: Cambridgeshire | D255: E31000005
B256: 6 | C256: Cheshire | D256: E31000006
B257: 7 | C257: Cleveland | D257: E31000007
B258: 8 | C258: Cornwall | D258: E31000008
B259: 9 | C259: Cumbria | D259: E31000009
B260: 10 | C260: Derbyshire | D260: E31000010
B261: 11 | C261: Devon and Somerset | D261: E31000011
B262: 12 | C262: Dorset and Wiltshire | D262: E31000047
... B294: 44 | C294: West Yorkshire | D294: E31000045
B316: 0 | C316: Template FRS | D316: 0
B319: 2023_24 | C319: 2023 | D319: 2022/23
...

Sheet Guidance
A1: Guidance notes for the completion of Fire Safety forms (FS1-FS10)
A2: The fire safety returns (FS1 to FS10) collect data on:
A4: § Fire safety enforcement activity under the Regulatory Reform (Fire Safety) Order 2005 (FSO)
A6: § Enforcement activity under additional legislation
A7: Ø the Dangerous Substances and Explosive Atmosphere Regulations 2002 (DSEAR)
A8: Ø the Petroleum (Consolidation) Act 1928
A9: Ø the Manufacture and Storage of Explosives Regulations 2005 and
A10: Ø the Fireworks Regulations 2004 for which some FRAs are responsible.
A11: § Other fire safety activity such as building regulations consultations
A13: The Home Office uses this data to deliver its policy responsibilities to Parliament and Ministers and to inform policy development over time.
A14: Recording enforcement activity
A15: When recording time spent on Fire Safety Order (FSO) enforcement activities, no distinction should be made between operational and specialist staff. All staff involved in FSO enforcement must be competent to carry out their specific tasks. For reference, see the Competence Framework for Fire Safety Regulators:
... A31: Definitions
A33: Fire Safety audit: | B33: A fire safety audit refers to a scheduled or planned visit conducted by an appropriately skilled fire safety inspector (minimum of a Level 3 qualification in Fire Safety) to carry out a comprehensive assessment of compliance with the Fire Safety Order (FSO). The scope of this assessment is outlined in Part B of the CFOA Fire Safety Audit and Information Gathering Form (CFOA Circular 2008/1016). Fire safety checks should not be counted as an audit, instead these checks should be recorded under fire safety activities.
A35: Short audit: | B35: A short audit is conducted using the CFOA short audit form.
A36: Satisfactory audit: | B36: An audit should be recorded as satisfactory if the premises broadly comply with the FSO and no further action is necessary
A38: Unsatisfactory audit: | B38: An audit should be recorded as unsatisfactory if further action is required to bring the premises into compliance. • Each audit must be recorded only once as either satisfactory or unsatisfactory, regardless of any follow-up actions resulting from an unsatisfactory audit. • Each separate enforcement action taken (formal or informal) must be recorded in the relevant column.
A40: Recording hours: | B40: The number of hours recorded must include all those taken to complete the original fire safety audit. Where the outcome of the audit is unsatisfactory the total time spent on all the subsequent enforcement activity related to the original audit, regardless of the type (including, where applicable, prosecutions) and any other follow up visits, must be included as part of the total spent against the original audit.
B41: The total number of hours recorded should include: • Time spent conducting the initial fire safety audit. • Time spent on all subsequent enforcement activities (including prosecutions). • Administrative tasks, such as file research, travel, and correspondence. • Telephone and electronic communications related to the audit. • Time spent at the premises performing tasks.
B42: Examples to illustrate how to calculate ‘hours’:
B44: Outcome of initial audit - satisfactory
B46: Time to complete fire safety audit | C46: 2 hours
B48: Time to complete all other associated tasks e.g. file research, telephone calls, travelling, audit, administration, etc. | C48: 2.25 hours
B50: Total time of the audit to be recorded | C50: 4.25 hours
B52: Outcome of initial audit - unsatisfactory
B54: Time to complete initial audit | C54: 4 hours
B55: Time to issue enforcement notice | C55: 2 hours
B56: Time to consider informal appeal | C56: 2 hours
B57: Time to issue new enforcement notice | C57: 2 hours
B58: Follow up visit (e.g. to check compliance with enforcement notice) | C58: 1 hour
B59: Time to complete all other associated tasks e.g. file search, telephone calls, correspondence etc. | C59: 1.5 hours
B61: Total time of the audit to be recorded | C61: 12.5 hours
B63: Recording Time Periods: • The total time should be recorded only once, at the end of all actions related to the original audit. • If audit-related work extends beyond the reporting period, it should be recorded in the latter period. • Other inspections (e.g., complaint-driven inspections or mini-audits) should be recorded under FS2 (Other Fire Safety Activity), not FS1.
A65: Enforcement and compliance actions
A66: Informal notification: | B66: Any non-legally binding action resulting from an unsatisfactory audit, such as an informal notification or an agreed action plan, should be recorded under this category.
A68: Enforcement Notices Served: | B68: If staged enforcement action occurs (e.g., informal action followed by an enforcement notice), entries should be made in both relevant columns. • The total hours for each action must be recorded against the initial unsatisfactory audit.
A69: Prosecutions of Offences: | B69: Prosecution cases often take considerable time before a judicial decision is reached. • The total hours recorded for an audit must include all time spent up to the conclusion of the prosecution. • If legal proceedings involve other enforcement actions, all related hours should be included in the total time recorded for the original audit.
A70: Satisfactory Following Enforcement: | B70: If an audit is initially recorded as unsatisfactory but subsequent enforcement leads to compliance, the outcome should be recorded in this column. • In such cases, a new audit (Part B form) must be completed to reflect the reduced risk. • This should not be counted as a separate audit but as part of the total time recorded for the original audit.
A72: FS2 – Number of Premises and Other Fire Safety Activities
A74: General Guidance
...

Sheet FS1 PY
D4: FS1 | E4: =VLOOKUP(Cover!A6,Cover!B319:E325,3,FALSE) -> 2024/25 | F4: =Cover!A10 -> Shropshire
B10: Satisfactory Number of Audits or Inspections | C10: Satisfactory Hours of Audits or Inspections | D10: Unsatisfactory Number of Audits or Inspections | E10: Unsatisfactory Hours of Audits or Inspections | F10: Number of Premises Satisfactory Following Enforcement Action | G10: Number of Informal Notifications | H10: Number of Alteration Notices served under Article 29 | I10: Number of Enforcement Notices Served under Article 30 | J10: Number of Prohibition Notices Served Under Article 31 | K10: Number of Prosecutions for Offences under Article 32 | L10: Total Number of Audits or Inspections | M10: Audits or Inspections of which short audits | N10: Total number of formal notifications: sum of Articles 29, 30, 31 and 32
A11: Hospitals
A12: Care homes
A13: Houses in Multiple Occupation (HMO)
A14: Purpose built flats 1-3 storeys
A15: Purpose built flats 4-5 storeys
A16: Purpose built flats 6-9 storeys
A17: Purpose built flats >=10 storeys
A18: Purpose built flats >= 4 storeys*
A19: Hostels
A20: Hotels
A21: Houses converted to flats
A22: Other sleeping accommodation
... A31: Other
A32: Total | B32: {=SUMPRODUCT(('FS1 - PY data'!$A$2:$A$10000='FS1 PY'!$D$4)*('FS1 - PY data'!$B$2:$B$10000='FS1 PY'!$E$4)*('FS1 - PY data'!$C$2:$C$10000='FS1 PY'!$F$4)*('FS1 - PY data'!$D$2:$D$10000=B10)*('FS1 - PY data'!$E$2:$E$10000))} -> 0 | C32: {=SUMPRODUCT(('FS1 - PY data'!$A$2:$A$10000='FS1 PY'!$D$4)*('FS1 - PY data'!$B$2:$B$10000='FS1 PY'!$E$4)*('FS1 - PY data'!$C$2:$C$10000='FS1 PY'!$F$4)*('FS1 - PY data'!$D$2:$D$10000=C10)*('FS1 - PY data'!$E$2:$E$10000))} -> 0 | D32: {=SUMPRODUCT(('FS1 - PY data'!$A$2:$A$10000='FS1 PY'!$D$4)*('FS1 - PY data'!$B$2:$B$10000='FS1 PY'!$E$4)*('FS1 - PY data'!$C$2:$C$10000='FS1 PY'!$F$4)*('FS1 - PY data'!$D$2:$D$10000=D10)*('FS1 - PY data'!$E$2:$E$10000))} -> 0 | E32: {=SUMPRODUCT(('FS1 - PY data'!$A$2:$A$10000='FS1 PY'!$D$4)*('FS1 - PY data'!$B$2:$B$10000='FS1 PY'!$E$4)*('FS1 - PY data'!$C$2:$C$10000='FS1 PY'!$F$4)*('FS1 - PY data'!$D$2:$D$10000=E10)*('FS1 - PY data'!$E$2:$E$10000))} -> 0 | F32: {=SUMPRODUCT(('FS1 - PY data'!$A$2:$A$10000='FS1 PY'!$D$4)*('FS1 - PY data'!$B$2:$B$10000='FS1 PY'!$E$4)*('FS1 - PY data'!$C$2:$C$10000='FS1 PY'!$F$4)*('FS1 - PY data'!$D$2:$D$10000=F10)*('FS1 - PY data'!$E$2:$E$10000))} -> 0 | G32: {=SUMPRODUCT(('FS1 - PY data'!$A$2:$A$10000='FS1 PY'!$D$4)*('FS1 - PY data'!$B$2:$B$10000='FS1 PY'!$E$4)*('FS1 - PY data'!$C$2:$C$10000='FS1 PY'!$F$4)*('FS1 - PY data'!$D$2:$D$10000=G10)*('FS1 - PY data'!$E$2:$E$10000))} -> 0 | H32: {=SUMPRODUCT(('FS1 - PY data'!$A$2:$A$10000='FS1 PY'!$D$4)*('FS1 - PY data'!$B$2:$B$10000='FS1 PY'!$E$4)*('FS1 - PY data'!$C$2:$C$10000='FS1 PY'!$F$4)*('FS1 - PY data'!$D$2:$D$10000=H10)*('FS1 - PY data'!$E$2:$E$10000))} -> 0 | I32: {=SUMPRODUCT(('FS1 - PY data'!$A$2:$A$10000='FS1 PY'!$D$4)*('FS1 - PY data'!$B$2:$B$10000='FS1 PY'!$E$4)*('FS1 - PY data'!$C$2:$C$10000='FS1 PY'!$F$4)*('FS1 - PY data'!$D$2:$D$10000=I10)*('FS1 - PY data'!$E$2:$E$10000))} -> 0 | ... N32: {=SUMPRODUCT(('FS1 - PY data'!$A$2:$A$10000='FS1 PY'!$D$4)*('FS1 - PY data'!$B$2:$B$10000='FS1 PY'!$E$4)*('FS1 - PY data'!$C$2:$C$10000='FS1 PY'!$F$4)*('FS1 - PY data'!$D$2:$D$10000=N10)*('FS1 - PY data'!$E$2:$E$10000))} -> 0

Sheet FS1 - PY data
A1: SHEET | B1: FINANCIAL_YEAR | C1: FRS_NAME | D1: INSPECTION_TYPE | E1: TOTAL

Sheet FS1
C3: =Cover!A10 -> Shropshire
A7: FS1 - Fire Safety Audits and Outcomes FSO ONLY | R7: QA checks versus data submitted last year
A8: If a cell is highlighted yellow following data entry this indicates the figure inputted is significantly different to the figure inputted in the previous year. Please double check these figures prior to submitting this return. | R8: Cells highlighted yellow following data entry indicate a significant change between the figures inputted this year relative to the previous year. Please double check the relevant figures prior to submitting this return and provide explanation of why there is a significant increase/decrease in the numbers
A9: Fire Safety Audits and Outcomes
B10: Satisfactory (Number) | C10: Satisfactory (Hours) | D10: Unsatisfactory (Number) | E10: Unsatisfactory (Hours) | F10: Number of Premises Satisfactory Following Enforcement Action | G10: Number of Informal Notifications | H10: Number of Alteration Notices served under Article 29 | I10: Number of Enforcement Notices Served Under Article 30 | J10: Number of Prohibition Notices Served Under Article 31 | K10: Number of Prosecutions of Offences Under Article 32 (FS7) | L10: Total number of audits (sum of satisfactory and non satisfactory audits) | M10: Of which: The number of short audits (see guidance) | N10: Total number of formal notifications (Sum of articles 29, 30, 31, 32)
A11: Hospitals | K11: =IF('FS7'!C11="",0,'FS7'!C11) -> 0 | L11: =B11+D11 -> 0 | N11: =SUM(H11:K11) -> 0
A12: Care homes | K12: =IF('FS7'!C12="",0,'FS7'!C12) -> 0 | L12: =B12+D12 -> 0 | N12: =SUM(H12:K12) -> 0
A13: Houses in Multiple Occupation (HMO) | K13: =IF('FS7'!C13="",0,'FS7'!C13) -> 0 | L13: =B13+D13 -> 0 | N13: =SUM(H13:K13) -> 0
A14: Purpose built flats 1-3 storeys | K14: =IF('FS7'!C14="",0,'FS7'!C14) -> 0 | L14: =B14+D14 -> 0 | N14: =SUM(H14:K14) -> 0
A15: Purpose built flats 4-5 storeys | K15: =IF('FS7'!C15="",0,'FS7'!C15) -> 0 | L15: =B15+D15 -> 0 | N15: =SUM(H15:K15) -> 0
A16: Purpose built flats 6-9 storeys | K16: =IF('FS7'!C16="",0,'FS7'!C16) -> 0 | L16: =B16+D16 -> 0 | N16: =SUM(H16:K16) -> 0
A17: Purpose built flats >=10 storeys | K17: =IF('FS7'!C17="",0,'FS7'!C17) -> 0 | L17: =B17+D17 -> 0 | N17: =SUM(H17:K17) -> 0
A18: Purpose built flats >= 4 storeys* | K18: =IF('FS7'!C18="",0,'FS7'!C18) -> 0 | L18: =B18+D18 -> 0 | N18: =SUM(H18:K18) -> 0
A19: Hostels | K19: =IF('FS7'!C19="",0,'FS7'!C19) -> 0 | L19: =B19+D19 -> 0 | N19: =SUM(H19:K19) -> 0
A20: Hotels | K20: =IF('FS7'!C20="",0,'FS7'!C20) -> 0 | L20: =B20+D20 -> 0 | N20: =SUM(H20:K20) -> 0
A21: Houses converted to flats | K21: =IF('FS7'!C21="",0,'FS7'!C21) -> 0 | L21: =B21+D21 -> 0 | N21: =SUM(H21:K21) -> 0
A22: Other sleeping accommodation | K22: =IF('FS7'!C22="",0,'FS7'!C22) -> 0 | L22: =B22+D22 -> 0 | N22: =SUM(H22:K22) -> 0
... A31: Other | K31: =IF('FS7'!C31="",0,'FS7'!C31) -> 0 | L31: =B31+D31 -> 0 | N31: =SUM(H31:K31) -> 0
A32: Total | B32: =SUM(B11:B31) -> 0 | C32: =SUM(C11:C31) -> 0 | D32: =SUM(D11:D31) -> 0 | E32: =SUM(E11:E31) -> 0 | F32: =SUM(F11:F31) -> 0 | G32: =SUM(G11:G31) -> 0 | H32: =SUM(H11:H31) -> 0 | I32: =SUM(I11:I31) -> 0 | ... N32: =SUM(N11:N31) -> 0
B36: FRS Notes

Sheet FS2 - PY data
A1: SHEET | B1: FINANCIAL_YEAR | C1: FRS_NAME | D1: PREMISES_TYPE | E1: INSPECTION_TYPE | F1: TOTAL

Sheet FS2 PY
D4: FS2 | E4: =VLOOKUP(Cover!A6,Cover!B319:E325,3,FALSE) -> 2024/25 | F4: =Cover!A10 -> Shropshire
B10: Premises known | C10: Building regulations consultations number | D10: Other consultations number | E10: Other FS activities number | F10: Self assessments* | G10: Total number | H10: Building regulations consultations hours | I10: Other consultations hours | J10: Other FS activities hours | K10: Self assessments* | L10: Total hours
A11: Hospitals | B11: {=SUMPRODUCT(('FS2 - PY data'!$A$2:$A$10000=$D$4)*('FS2 - PY data'!$B$2:$B$10000=$E$4)*('FS2 - PY data'!$C$2:$C$10000=$F$4)*('FS2 - PY data'!$D$2:$D$10000=$A11)*('FS2 - PY data'!$E$2:$E$10000=B$10)*('FS2 - PY data'!$F$2:$F$10000))} -> 0 | C11: {=SUMPRODUCT(('FS2 - PY data'!$A$2:$A$10000=$D$4)*('FS2 - PY data'!$B$2:$B$10000=$E$4)*('FS2 - PY data'!$C$2:$C$10000=$F$4)*('FS2 - PY data'!$D$2:$D$10000=$A11)*('FS2 - PY data'!$E$2:$E$10000=C$10)*('FS2 - PY data'!$F$2:$F$10000))} -> 0 | D11: {=SUMPRODUCT(('FS2 - PY data'!$A$2:$A$10000=$D$4)*('FS2 - PY data'!$B$2:$B$10000=$E$4)*('FS2 - PY data'!$C$2:$C$10000=$F$4)*('FS2 - PY data'!$D$2:$D$10000=$A11)*('FS2 - PY data'!$E$2:$E$10000=D$10)*('FS2 - PY data'!$F$2:$F$10000))} -> 0 | E11: {=SUMPRODUCT(('FS2 - PY data'!$A$2:$A$10000=$D$4)*('FS2 - PY data'!$B$2:$B$10000=$E$4)*('FS2 - PY data'!$C$2:$C$10000=$F$4)*('FS2 - PY data'!$D$2:$D$10000=$A11)*('FS2 - PY data'!$E$2:$E$10000=E$10)*('FS2 - PY data'!$F$2:$F$10000))} -> 0 | F11: {=SUMPRODUCT(('FS2 - PY data'!$A$2:$A$10000=$D$4)*('FS2 - PY data'!$B$2:$B$10000=$E$4)*('FS2 - PY data'!$C$2:$C$10000=$F$4)*('FS2 - PY data'!$D$2:$D$10000=$A11)*('FS2 - PY data'!$E$2:$E$10000=F$10)*('FS2 - PY data'!$F$2:$F$10000))} -> 0 | G11: {=SUMPRODUCT(('FS2 - PY data'!$A$2:$A$10000=$D$4)*('FS2 - PY data'!$B$2:$B$10000=$E$4)*('FS2 - PY data'!$C$2:$C$10000=$F$4)*('FS2 - PY data'!$D$2:$D$10000=$A11)*('FS2 - PY data'!$E$2:$E$10000=G$10)*('FS2 - PY data'!$F$2:$F$10000))} -> 0 | H11: {=SUMPRODUCT(('FS2 - PY data'!$A$2:$A$10000=$D$4)*('FS2 - PY data'!$B$2:$B$10000=$E$4)*('FS2 - PY data'!$C$2:$C$10000=$F$4)*('FS2 - PY data'!$D$2:$D$10000=$A11)*('FS2 - PY data'!$E$2:$E$10000=H$10)*('FS2 - PY data'!$F$2:$F$10000))} -> 0 | I11: {=SUMPRODUCT(('FS2 - PY data'!$A$2:$A$10000=$D$4)*('FS2 - PY data'!$B$2:$B$10000=$E$4)*('FS2 - PY data'!$C$2:$C$10000=$F$4)*('FS2 - PY data'!$D$2:$D$10000=$A11)*('FS2 - PY data'!$E$2:$E$10000=I$10)*('FS2 - PY data'!$F$2:$F$10000))} -> 0 | ... L11: {=SUMPRODUCT(('FS2 - PY data'!$A$2:$A$10000=$D$4)*('FS2 - PY data'!$B$2:$B$10000=$E$4)*('FS2 - PY data'!$C$2:$C$10000=$F$4)*('FS2 - PY data'!$D$2:$D$10000=$A11)*('FS2 - PY data'!$E$2:$E$10000=L$10)*('FS2 - PY data'!$F$2:$F$10000))} -> 0
A12: Care homes | B12: {=SUMPRODUCT(('FS2 - PY data'!$A$2:$A$10000=$D$4)*('FS2 - PY data'!$B$2:$B$10000=$E$4)*('FS2 - PY data'!$C$2:$C$10000=$F$4)*('FS2 - PY data'!$D$2:$D$10000=$A12)*('FS2 - PY data'!$E$2:$E$10000=B$10)*('FS2 - PY data'!$F$2:$F$10000))} -> 0 | C12: {=SUMPRODUCT(('FS2 - PY data'!$A$2:$A$10000=$D$4)*('FS2 - PY data'!$B$2:$B$10000=$E$4)*('FS2 - PY data'!$C$2:$C$10000=$F$4)*('FS2 - PY data'!$D$2:$D$10000=$A12)*('FS2 - PY data'!$E$2:$E$10000=C$10)*('FS2 - PY data'!$F$2:$F$10000))} -> 0 | D12: {=SUMPRODUCT(('FS2 - PY data'!$A$2:$A$10000=$D$4)*('FS2 - PY data'!$B$2:$B$10000=$E$4)*('FS2 - PY data'!$C$2:$C$10000=$F$4)*('FS2 - PY data'!$D$2:$D$10000=$A12)*('FS2 - PY data'!$E$2:$E$10000=D$10)*('FS2 - PY data'!$F$2:$F$10000))} -> 0 | E12: {=SUMPRODUCT(('FS2 - PY data'!$A$2:$A$10000=$D$4)*('FS2 - PY data'!$B$2:$B$10000=$E$4)*('FS2 - PY data'!$C$2:$C$10000=$F$4)*('FS2 - PY data'!$D$2:$D$10000=$A12)*('FS2 - PY data'!$E$2:$E$10000=E$10)*('FS2 - PY data'!$F$2:$F$10000))} -> 0 | F12: {=SUMPRODUCT(('FS2 - PY data'!$A$2:$A$10000=$D$4)*('FS2 - PY data'!$B$2:$B$10000=$E$4)*('FS2 - PY data'!$C$2:$C$10000=$F$4)*('FS2 - PY data'!$D$2:$D$10000=$A12)*('FS2 - PY data'!$E$2:$E$10000=F$10)*('FS2 - PY data'!$F$2:$F$10000))} -> 0 | G12: {=SUMPRODUCT(('FS2 - PY data'!$A$2:$A$10000=$D$4)*('FS2 - PY data'!$B$2:$B$10000=$E$4)*('FS2 - PY data'!$C$2:$C$10000=$F$4)*('FS2 - PY data'!$D$2:$D$10000=$A12)*('FS2 - PY data'!$E$2:$E$10000=G$10)*('FS2 - PY data'!$F$2:$F$10000))} -> 0 | H12: {=SUMPRODUCT(('FS2 - PY data'!$A$2:$A$10000=$D$4)*('FS2 - PY data'!$B$2:$B$10000=$E$4)*('FS2 - PY data'!$C$2:$C$10000=$F$4)*('FS2 - PY data'!$D$2:$D$10000=$A12)*('FS2 - PY data'!$E$2:$E$10000=H$10)*('FS2 - PY data'!$F$2:$F$10000))} -> 0 | I12: {=SUMPRODUCT(('FS2 - PY data'!$A$2:$A$10000=$D$4)*('FS2 - PY data'!$B$2:$B$10000=$E$4)*('FS2 - PY data'!$C$2:$C$10000=$F$4)*('FS2 - PY data'!$D$2:$D$10000=$A12)*('FS2 - PY data'!$E$2:$E$10000=I$10)*('FS2 - PY data'!$F$2:$F$10000))} -> 0 | ... L12: {=SUMPRODUCT(('FS2 - PY data'!$A$2:$A$10000=$D$4)*('FS2 - PY data'!$B$2:$B$10000=$E$4)*('FS2 - PY data'!$C$2:$C$10000=$F$4)*('FS2 - PY data'!$D$2:$D$10000=$A12)*('FS2 - PY data'!$E$2:$E$10000=L$10)*('FS2 - PY data'!$F$2:$F$10000))} -> 0
A13: HMOs | B13: {=SUMPRODUCT(('FS2 - PY data'!$A$2:$A$10000=$D$4)*('FS2 - PY data'!$B$2:$B$10000=$E$4)*('FS2 - PY data'!$C$2:$C$10000=$F$4)*('FS2 - PY data'!$D$2:$D$10000=$A13)*('FS2 - PY data'!$E$2:$E$10000=B$10)*('FS2 - PY data'!$F$2:$F$10000))} -> 0 | C13: {=SUMPRODUCT(('FS2 - PY data'!$A$2:$A$10000=$D$4)*('FS2 - PY data'!$B$2:$B$10000=$E$4)*('FS2 - PY data'!$C$2:$C$10000=$F$4)*('FS2 - PY data'!$D$2:$D$10000=$A13)*('FS2 - PY data'!$E$2:$E$10000=C$10)*('FS2 - PY data'!$F$2:$F$10000))} -> 0 | D13: {=SUMPRODUCT(('FS2 - PY data'!$A$2:$A$10000=$D$4)*('FS2 - PY data'!$B$2:$B$10000=$E$4)*('FS2 - PY data'!$C$2:$C$10000=$F$4)*('FS2 - PY data'!$D$2:$D$10000=$A13)*('FS2 - PY data'!$E$2:$E$10000=D$10)*('FS2 - PY data'!$F$2:$F$10000))} -> 0 | E13: {=SUMPRODUCT(('FS2 - PY data'!$A$2:$A$10000=$D$4)*('FS2 - PY data'!$B$2:$B$10000=$E$4)*('FS2 - PY data'!$C$2:$C$10000=$F$4)*('FS2 - PY data'!$D$2:$D$10000=$A13)*('FS2 - PY data'!$E$2:$E$10000=E$10)*('FS2 - PY data'!$F$2:$F$10000))} -> 0 | F13: {=SUMPRODUCT(('FS2 - PY data'!$A$2:$A$10000=$D$4)*('FS2 - PY data'!$B$2:$B$10000=$E$4)*('FS2 - PY data'!$C$2:$C$10000=$F$4)*('FS2 - PY data'!$D$2:$D$10000=$A13)*('FS2 - PY data'!$E$2:$E$10000=F$10)*('FS2 - PY data'!$F$2:$F$10000))} -> 0 | G13: {=SUMPRODUCT(('FS2 - PY data'!$A$2:$A$10000=$D$4)*('FS2 - PY data'!$B$2:$B$10000=$E$4)*('FS2 - PY data'!$C$2:$C$10000=$F$4)*('FS2 - PY data'!$D$2:$D$10000=$A13)*('FS2 - PY data'!$E$2:$E$10000=G$10)*('FS2 - PY data'!$F$2:$F$10000))} -> 0 | H13: {=SUMPRODUCT(('FS2 - PY data'!$A$2:$A$10000=$D$4)*('FS2 - PY data'!$B$2:$B$10000=$E$4)*('FS2 - PY data'!$C$2:$C$10000=$F$4)*('FS2 - PY data'!$D$2:$D$10000=$A13)*('FS2 - PY data'!$E$2:$E$10000=H$10)*('FS2 - PY data'!$F$2:$F$10000))} -> 0 | I13: {=SUMPRODUCT(('FS2 - PY data'!$A$2:$A$10000=$D$4)*('FS2 - PY data'!$B$2:$B$10000=$E$4)*('FS2 - PY data'!$C$2:$C$10000=$F$4)*('FS2 - PY data'!$D$2:$D$10000=$A13)*('FS2 - PY data'!$E$2:$E$10000=I$10)*('FS2 - PY data'!$F$2:$F$10000))} -> 0 | ... L13: {=SUMPRODUCT(('FS2 - PY data'!$A$2:$A$10000=$D$4)*('FS2 - PY data'!$B$2:$B$10000=$E$4)*('FS2 - PY data'!$C$2:$C$10000=$F$4)*('FS2 - PY data'!$D$2:$D$10000=$A13)*('FS2 - PY data'!$E$2:$E$10000=L$10)*('FS2 - PY data'!$F$2:$F$10000))} -> 0
A14: Purpose built flats 1 to 3 storeys | B14: {=SUMPRODUCT(('FS2 - PY data'!$A$2:$A$10000=$D$4)*('FS2 - PY data'!$B$2:$B$10000=$E$4)*('FS2 - PY data'!$C$2:$C$10000=$F$4)*('FS2 - PY data'!$D$2:$D$10000=$A14)*('FS2 - PY data'!$E$2:$E$10000=B$10)*('FS2 - PY data'!$F$2:$F$10000))} -> 0 | C14: {=SUMPRODUCT(('FS2 - PY data'!$A$2:$A$10000=$D$4)*('FS2 - PY data'!$B$2:$B$10000=$E$4)*('FS2 - PY data'!$C$2:$C$10000=$F$4)*('FS2 - PY data'!$D$2:$D$10000=$A14)*('FS2 - PY data'!$E$2:$E$10000=C$10)*('FS2 - PY data'!$F$2:$F$10000))} -> 0 | D14: {=SUMPRODUCT(('FS2 - PY data'!$A$2:$A$10000=$D$4)*('FS2 - PY data'!$B$2:$B$10000=$E$4)*('FS2 - PY data'!$C$2:$C$10000=$F$4)*('FS2 - PY data'!$D$2:$D$10000=$A14)*('FS2 - PY data'!$E$2:$E$10000=D$10)*('FS2 - PY data'!$F$2:$F$10000))} -> 0 | E14: {=SUMPRODUCT(('FS2 - PY data'!$A$2:$A$10000=$D$4)*('FS2 - PY data'!$B$2:$B$10000=$E$4)*('FS2 - PY data'!$C$2:$C$10000=$F$4)*('FS2 - PY data'!$D$2:$D$10000=$A14)*('FS2 - PY data'!$E$2:$E$10000=E$10)*('FS2 - PY data'!$F$2:$F$10000))} -> 0 | F14: {=SUMPRODUCT(('FS2 - PY data'!$A$2:$A$10000=$D$4)*('FS2 - PY data'!$B$2:$B$10000=$E$4)*('FS2 - PY data'!$C$2:$C$10000=$F$4)*('FS2 - PY data'!$D$2:$D$10000=$A14)*('FS2 - PY data'!$E$2:$E$10000=F$10)*('FS2 - PY data'!$F$2:$F$10000))} -> 0 | G14: {=SUMPRODUCT(('FS2 - PY data'!$A$2:$A$10000=$D$4)*('FS2 - PY data'!$B$2:$B$10000=$E$4)*('FS2 - PY data'!$C$2:$C$10000=$F$4)*('FS2 - PY data'!$D$2:$D$10000=$A14)*('FS2 - PY data'!$E$2:$E$10000=G$10)*('FS2 - PY data'!$F$2:$F$10000))} -> 0 | H14: {=SUMPRODUCT(('FS2 - PY data'!$A$2:$A$10000=$D$4)*('FS2 - PY data'!$B$2:$B$10000=$E$4)*('FS2 - PY data'!$C$2:$C$10000=$F$4)*('FS2 - PY data'!$D$2:$D$10000=$A14)*('FS2 - PY data'!$E$2:$E$10000=H$10)*('FS2 - PY data'!$F$2:$F$10000))} -> 0 | I14: {=SUMPRODUCT(('FS2 - PY data'!$A$2:$A$10000=$D$4)*('FS2 - PY data'!$B$2:$B$10000=$E$4)*('FS2 - PY data'!$C$2:$C$10000=$F$4)*('FS2 - PY data'!$D$2:$D$10000=$A14)*('FS2 - PY data'!$E$2:$E$10000=I$10)*('FS2 - PY data'!$F$2:$F$10000))} -> 0 | ... L14: {=SUMPRODUCT(('FS2 - PY data'!$A$2:$A$10000=$D$4)*('FS2 - PY data'!$B$2:$B$10000=$E$4)*('FS2 - PY data'!$C$2:$C$10000=$F$4)*('FS2 - PY data'!$D$2:$D$10000=$A14)*('FS2 - PY data'!$E$2:$E$10000=L$10)*('FS2 - PY data'!$F$2:$F$10000))} -> 0
A15: Purpose built flats 4 to 5 storeys | B15: {=SUMPRODUCT(('FS2 - PY data'!$A$2:$A$10000=$D$4)*('FS2 - PY data'!$B$2:$B$10000=$E$4)*('FS2 - PY data'!$C$2:$C$10000=$F$4)*('FS2 - PY data'!$D$2:$D$10000=$A15)*('FS2 - PY data'!$E$2:$E$10000=B$10)*('FS2 - PY data'!$F$2:$F$10000))} -> 0 | C15: {=SUMPRODUCT(('FS2 - PY data'!$A$2:$A$10000=$D$4)*('FS2 - PY data'!$B$2:$B$10000=$E$4)*('FS2 - PY data'!$C$2:$C$10000=$F$4)*('FS2 - PY data'!$D$2:$D$10000=$A15)*('FS2 - PY data'!$E$2:$E$10000=C$10)*('FS2 - PY data'!$F$2:$F$10000))} -> 0 | D15: {=SUMPRODUCT(('FS2 - PY data'!$A$2:$A$10000=$D$4)*('FS2 - PY data'!$B$2:$B$10000=$E$4)*('FS2 - PY data'!$C$2:$C$10000=$F$4)*('FS2 - PY data'!$D$2:$D$10000=$A15)*('FS2 - PY data'!$E$2:$E$10000=D$10)*('FS2 - PY data'!$F$2:$F$10000))} -> 0 | E15: {=SUMPRODUCT(('FS2 - PY data'!$A$2:$A$10000=$D$4)*('FS2 - PY data'!$B$2:$B$10000=$E$4)*('FS2 - PY data'!$C$2:$C$10000=$F$4)*('FS2 - PY data'!$D$2:$D$10000=$A15)*('FS2 - PY data'!$E$2:$E$10000=E$10)*('FS2 - PY data'!$F$2:$F$10000))} -> 0 | F15: {=SUMPRODUCT(('FS2 - PY data'!$A$2:$A$10000=$D$4)*('FS2 - PY data'!$B$2:$B$10000=$E$4)*('FS2 - PY data'!$C$2:$C$10000=$F$4)*('FS2 - PY data'!$D$2:$D$10000=$A15)*('FS2 - PY data'!$E$2:$E$10000=F$10)*('FS2 - PY data'!$F$2:$F$10000))} -> 0 | G15: {=SUMPRODUCT(('FS2 - PY data'!$A$2:$A$10000=$D$4)*('FS2 - PY data'!$B$2:$B$10000=$E$4)*('FS2 - PY data'!$C$2:$C$10000=$F$4)*('FS2 - PY data'!$D$2:$D$10000=$A15)*('FS2 - PY data'!$E$2:$E$10000=G$10)*('FS2 - PY data'!$F$2:$F$10000))} -> 0 | H15: {=SUMPRODUCT(('FS2 - PY data'!$A$2:$A$10000=$D$4)*('FS2 - PY data'!$B$2:$B$10000=$E$4)*('FS2 - PY data'!$C$2:$C$10000=$F$4)*('FS2 - PY data'!$D$2:$D$10000=$A15)*('FS2 - PY data'!$E$2:$E$10000=H$10)*('FS2 - PY data'!$F$2:$F$10000))} -> 0 | I15: {=SUMPRODUCT(('FS2 - PY data'!$A$2:$A$10000=$D$4)*('FS2 - PY data'!$B$2:$B$10000=$E$4)*('FS2 - PY data'!$C$2:$C$10000=$F$4)*('FS2 - PY data'!$D$2:$D$10000=$A15)*('FS2 - PY data'!$E$2:$E$10000=I$10)*('FS2 - PY data'!$F$2:$F$10000))} -> 0 | ... L15: {=SUMPRODUCT(('FS2 - PY data'!$A$2:$A$10000=$D$4)*('FS2 - PY data'!$B$2:$B$10000=$E$4)*('FS2 - PY data'!$C$2:$C$10000=$F$4)*('FS2 - PY data'!$D$2:$D$10000=$A15)*('FS2 - PY data'!$E$2:$E$10000=L$10)*('FS2 - PY data'!$F$2:$F$10000))} -> 0
A16: Purpose built flats 6 to 9 storeys | B16: {=SUMPRODUCT(('FS2 - PY data'!$A$2:$A$10000=$D$4)*('FS2 - PY data'!$B$2:$B$10000=$E$4)*('FS2 - PY data'!$C$2:$C$10000=$F$4)*('FS2 - PY data'!$D$2:$D$10000=$A16)*('FS2 - PY data'!$E$2:$E$10000=B$10)*('FS2 - PY data'!$F$2:$F$10000))} -> 0 | C16: {=SUMPRODUCT(('FS2 - PY data'!$A$2:$A$10000=$D$4)*('FS2 - PY data'!$B$2:$B$10000=$E$4)*('FS2 - PY data'!$C$2:$C$10000=$F$4)*('FS2 - PY data'!$D$2:$D$10000=$A16)*('FS2 - PY data'!$E$2:$E$10000=C$10)*('FS2 - PY data'!$F$2:$F$10000))} -> 0 | D16: {=SUMPRODUCT(('FS2 - PY data'!$A$2:$A$10000=$D$4)*('FS2 - PY data'!$B$2:$B$10000=$E$4)*('FS2 - PY data'!$C$2:$C$10000=$F$4)*('FS2 - PY data'!$D$2:$D$10000=$A16)*('FS2 - PY data'!$E$2:$E$10000=D$10)*('FS2 - PY data'!$F$2:$F$10000))} -> 0 | E16: {=SUMPRODUCT(('FS2 - PY data'!$A$2:$A$10000=$D$4)*('FS2 - PY data'!$B$2:$B$10000=$E$4)*('FS2 - PY data'!$C$2:$C$10000=$F$4)*('FS2 - PY data'!$D$2:$D$10000=$A16)*('FS2 - PY data'!$E$2:$E$10000=E$10)*('FS2 - PY data'!$F$2:$F$10000))} -> 0 | F16: {=SUMPRODUCT(('FS2 - PY data'!$A$2:$A$10000=$D$4)*('FS2 - PY data'!$B$2:$B$10000=$E$4)*('FS2 - PY data'!$C$2:$C$10000=$F$4)*('FS2 - PY data'!$D$2:$D$10000=$A16)*('FS2 - PY data'!$E$2:$E$10000=F$10)*('FS2 - PY data'!$F$2:$F$10000))} -> 0 | G16: {=SUMPRODUCT(('FS2 - PY data'!$A$2:$A$10000=$D$4)*('FS2 - PY data'!$B$2:$B$10000=$E$4)*('FS2 - PY data'!$C$2:$C$10000=$F$4)*('FS2 - PY data'!$D$2:$D$10000=$A16)*('FS2 - PY data'!$E$2:$E$10000=G$10)*('FS2 - PY data'!$F$2:$F$10000))} -> 0 | H16: {=SUMPRODUCT(('FS2 - PY data'!$A$2:$A$10000=$D$4)*('FS2 - PY data'!$B$2:$B$10000=$E$4)*('FS2 - PY data'!$C$2:$C$10000=$F$4)*('FS2 - PY data'!$D$2:$D$10000=$A16)*('FS2 - PY data'!$E$2:$E$10000=H$10)*('FS2 - PY data'!$F$2:$F$10000))} -> 0 | I16: {=SUMPRODUCT(('FS2 - PY data'!$A$2:$A$10000=$D$4)*('FS2 - PY data'!$B$2:$B$10000=$E$4)*('FS2 - PY data'!$C$2:$C$10000=$F$4)*('FS2 - PY data'!$D$2:$D$10000=$A16)*('FS2 - PY data'!$E$2:$E$10000=I$10)*('FS2 - PY data'!$F$2:$F$10000))} -> 0 | ... L16: {=SUMPRODUCT(('FS2 - PY data'!$A$2:$A$10000=$D$4)*('FS2 - PY data'!$B$2:$B$10000=$E$4)*('FS2 - PY data'!$C$2:$C$10000=$F$4)*('FS2 - PY data'!$D$2:$D$10000=$A16)*('FS2 - PY data'!$E$2:$E$10000=L$10)*('FS2 - PY data'!$F$2:$F$10000))} -> 0
A17: Purpose built flats 10 plus storeys | B17: {=SUMPRODUCT(('FS2 - PY data'!$A$2:$A$10000=$D$4)*('FS2 - PY data'!$B$2:$B$10000=$E$4)*('FS2 - PY data'!$C$2:$C$10000=$F$4)*('FS2 - PY data'!$D$2:$D$10000=$A17)*('FS2 - PY data'!$E$2:$E$10000=B$10)*('FS2 - PY data'!$F$2:$F$10000))} -> 0 | C17: {=SUMPRODUCT(('FS2 - PY data'!$A$2:$A$10000=$D$4)*('FS2 - PY data'!$B$2:$B$10000=$E$4)*('FS2 - PY data'!$C$2:$C$10000=$F$4)*('FS2 - PY data'!$D$2:$D$10000=$A17)*('FS2 - PY data'!$E$2:$E$10000=C$10)*('FS2 - PY data'!$F$2:$F$10000))} -> 0 | D17: {=SUMPRODUCT(('FS2 - PY data'!$A$2:$A$10000=$D$4)*('FS2 - PY data'!$B$2:$B$10000=$E$4)*('FS2 - PY data'!$C$2:$C$10000=$F$4)*('FS2 - PY data'!$D$2:$D$10000=$A17)*('FS2 - PY data'!$E$2:$E$10000=D$10)*('FS2 - PY data'!$F$2:$F$10000))} -> 0 | E17: {=SUMPRODUCT(('FS2 - PY data'!$A$2:$A$10000=$D$4)*('FS2 - PY data'!$B$2:$B$10000=$E$4)*('FS2 - PY data'!$C$2:$C$10000=$F$4)*('FS2 - PY data'!$D$2:$D$10000=$A17)*('FS2 - PY data'!$E$2:$E$10000=E$10)*('FS2 - PY data'!$F$2:$F$10000))} -> 0 | F17: {=SUMPRODUCT(('FS2 - PY data'!$A$2:$A$10000=$D$4)*('FS2 - PY data'!$B$2:$B$10000=$E$4)*('FS2 - PY data'!$C$2:$C$10000=$F$4)*('FS2 - PY data'!$D$2:$D$10000=$A17)*('FS2 - PY data'!$E$2:$E$10000=F$10)*('FS2 - PY data'!$F$2:$F$10000))} -> 0 | G17: {=SUMPRODUCT(('FS2 - PY data'!$A$2:$A$10000=$D$4)*('FS2 - PY data'!$B$2:$B$10000=$E$4)*('FS2 - PY data'!$C$2:$C$10000=$F$4)*('FS2 - PY data'!$D$2:$D$10000=$A17)*('FS2 - PY data'!$E$2:$E$10000=G$10)*('FS2 - PY data'!$F$2:$F$10000))} -> 0 | H17: {=SUMPRODUCT(('FS2 - PY data'!$A$2:$A$10000=$D$4)*('FS2 - PY data'!$B$2:$B$10000=$E$4)*('FS2 - PY data'!$C$2:$C$10000=$F$4)*('FS2 - PY data'!$D$2:$D$10000=$A17)*('FS2 - PY data'!$E$2:$E$10000=H$10)*('FS2 - PY data'!$F$2:$F$10000))} -> 0 | I17: {=SUMPRODUCT(('FS2 - PY data'!$A$2:$A$10000=$D$4)*('FS2 - PY data'!$B$2:$B$10000=$E$4)*('FS2 - PY data'!$C$2:$C$10000=$F$4)*('FS2 - PY data'!$D$2:$D$10000=$A17)*('FS2 - PY data'!$E$2:$E$10000=I$10)*('FS2 - PY data'!$F$2:$F$10000))} -> 0 | ... L17: {=SUMPRODUCT(('FS2 - PY data'!$A$2:$A$10000=$D$4)*('FS2 - PY data'!$B$2:$B$10000=$E$4)*('FS2 - PY data'!$C$2:$C$10000=$F$4)*('FS2 - PY data'!$D$2:$D$10000=$A17)*('FS2 - PY data'!$E$2:$E$10000=L$10)*('FS2 - PY data'!$F$2:$F$10000))} -> 0
A18: Purpose built flats 4 plus storeys (no breakdown available) | B18: {=SUMPRODUCT(('FS2 - PY data'!$A$2:$A$10000=$D$4)*('FS2 - PY data'!$B$2:$B$10000=$E$4)*('FS2 - PY data'!$C$2:$C$10000=$F$4)*('FS2 - PY data'!$D$2:$D$10000=$A18)*('FS2 - PY data'!$E$2:$E$10000=B$10)*('FS2 - PY data'!$F$2:$F$10000))} -> 0 | C18: {=SUMPRODUCT(('FS2 - PY data'!$A$2:$A$10000=$D$4)*('FS2 - PY data'!$B$2:$B$10000=$E$4)*('FS2 - PY data'!$C$2:$C$10000=$F$4)*('FS2 - PY data'!$D$2:$D$10000=$A18)*('FS2 - PY data'!$E$2:$E$10000=C$10)*('FS2 - PY data'!$F$2:$F$10000))} -> 0 | D18: {=SUMPRODUCT(('FS2 - PY data'!$A$2:$A$10000=$D$4)*('FS2 - PY data'!$B$2:$B$10000=$E$4)*('FS2 - PY data'!$C$2:$C$10000=$F$4)*('FS2 - PY data'!$D$2:$D$10000=$A18)*('FS2 - PY data'!$E$2:$E$10000=D$10)*('FS2 - PY data'!$F$2:$F$10000))} -> 0 | E18: {=SUMPRODUCT(('FS2 - PY data'!$A$2:$A$10000=$D$4)*('FS2 - PY data'!$B$2:$B$10000=$E$4)*('FS2 - PY data'!$C$2:$C$10000=$F$4)*('FS2 - PY data'!$D$2:$D$10000=$A18)*('FS2 - PY data'!$E$2:$E$10000=E$10)*('FS2 - PY data'!$F$2:$F$10000))} -> 0 | F18: {=SUMPRODUCT(('FS2 - PY data'!$A$2:$A$10000=$D$4)*('FS2 - PY data'!$B$2:$B$10000=$E$4)*('FS2 - PY data'!$C$2:$C$10000=$F$4)*('FS2 - PY data'!$D$2:$D$10000=$A18)*('FS2 - PY data'!$E$2:$E$10000=F$10)*('FS2 - PY data'!$F$2:$F$10000))} -> 0 | G18: {=SUMPRODUCT(('FS2 - PY data'!$A$2:$A$10000=$D$4)*('FS2 - PY data'!$B$2:$B$10000=$E$4)*('FS2 - PY data'!$C$2:$C$10000=$F$4)*('FS2 - PY data'!$D$2:$D$10000=$A18)*('FS2 - PY data'!$E$2:$E$10000=G$10)*('FS2 - PY data'!$F$2:$F$10000))} -> 0 | H18: {=SUMPRODUCT(('FS2 - PY data'!$A$2:$A$10000=$D$4)*('FS2 - PY data'!$B$2:$B$10000=$E$4)*('FS2 - PY data'!$C$2:$C$10000=$F$4)*('FS2 - PY data'!$D$2:$D$10000=$A18)*('FS2 - PY data'!$E$2:$E$10000=H$10)*('FS2 - PY data'!$F$2:$F$10000))} -> 0 | I18: {=SUMPRODUCT(('FS2 - PY data'!$A$2:$A$10000=$D$4)*('FS2 - PY data'!$B$2:$B$10000=$E$4)*('FS2 - PY data'!$C$2:$C$10000=$F$4)*('FS2 - PY data'!$D$2:$D$10000=$A18)*('FS2 - PY data'!$E$2:$E$10000=I$10)*('FS2 - PY data'!$F$2:$F$10000))} -> 0 | ... L18: {=SUMPRODUCT(('FS2 - PY data'!$A$2:$A$10000=$D$4)*('FS2 - PY data'!$B$2:$B$10000=$E$4)*('FS2 - PY data'!$C$2:$C$10000=$F$4)*('FS2 - PY data'!$D$2:$D$10000=$A18)*('FS2 - PY data'!$E$2:$E$10000=L$10)*('FS2 - PY data'!$F$2:$F$10000))} -> 0
A19: Hostels | B19: {=SUMPRODUCT(('FS2 - PY data'!$A$2:$A$10000=$D$4)*('FS2 - PY data'!$B$2:$B$10000=$E$4)*('FS2 - PY data'!$C$2:$C$10000=$F$4)*('FS2 - PY data'!$D$2:$D$10000=$A19)*('FS2 - PY data'!$E$2:$E$10000=B$10)*('FS2 - PY data'!$F$2:$F$10000))} -> 0 | C19: {=SUMPRODUCT(('FS2 - PY data'!$A$2:$A$10000=$D$4)*('FS2 - PY data'!$B$2:$B$10000=$E$4)*('FS2 - PY data'!$C$2:$C$10000=$F$4)*('FS2 - PY data'!$D$2:$D$10000=$A19)*('FS2 - PY data'!$E$2:$E$10000=C$10)*('FS2 - PY data'!$F$2:$F$10000))} -> 0 | D19: {=SUMPRODUCT(('FS2 - PY data'!$A$2:$A$10000=$D$4)*('FS2 - PY data'!$B$2:$B$10000=$E$4)*('FS2 - PY data'!$C$2:$C$10000=$F$4)*('FS2 - PY data'!$D$2:$D$10000=$A19)*('FS2 - PY data'!$E$2:$E$10000=D$10)*('FS2 - PY data'!$F$2:$F$10000))} -> 0 | E19: {=SUMPRODUCT(('FS2 - PY data'!$A$2:$A$10000=$D$4)*('FS2 - PY data'!$B$2:$B$10000=$E$4)*('FS2 - PY data'!$C$2:$C$10000=$F$4)*('FS2 - PY data'!$D$2:$D$10000=$A19)*('FS2 - PY data'!$E$2:$E$10000=E$10)*('FS2 - PY data'!$F$2:$F$10000))} -> 0 | F19: {=SUMPRODUCT(('FS2 - PY data'!$A$2:$A$10000=$D$4)*('FS2 - PY data'!$B$2:$B$10000=$E$4)*('FS2 - PY data'!$C$2:$C$10000=$F$4)*('FS2 - PY data'!$D$2:$D$10000=$A19)*('FS2 - PY data'!$E$2:$E$10000=F$10)*('FS2 - PY data'!$F$2:$F$10000))} -> 0 | G19: {=SUMPRODUCT(('FS2 - PY data'!$A$2:$A$10000=$D$4)*('FS2 - PY data'!$B$2:$B$10000=$E$4)*('FS2 - PY data'!$C$2:$C$10000=$F$4)*('FS2 - PY data'!$D$2:$D$10000=$A19)*('FS2 - PY data'!$E$2:$E$10000=G$10)*('FS2 - PY data'!$F$2:$F$10000))} -> 0 | H19: {=SUMPRODUCT(('FS2 - PY data'!$A$2:$A$10000=$D$4)*('FS2 - PY data'!$B$2:$B$10000=$E$4)*('FS2 - PY data'!$C$2:$C$10000=$F$4)*('FS2 - PY data'!$D$2:$D$10000=$A19)*('FS2 - PY data'!$E$2:$E$10000=H$10)*('FS2 - PY data'!$F$2:$F$10000))} -> 0 | I19: {=SUMPRODUCT(('FS2 - PY data'!$A$2:$A$10000=$D$4)*('FS2 - PY data'!$B$2:$B$10000=$E$4)*('FS2 - PY data'!$C$2:$C$10000=$F$4)*('FS2 - PY data'!$D$2:$D$10000=$A19)*('FS2 - PY data'!$E$2:$E$10000=I$10)*('FS2 - PY data'!$F$2:$F$10000))} -> 0 | ... L19: {=SUMPRODUCT(('FS2 - PY data'!$A$2:$A$10000=$D$4)*('FS2 - PY data'!$B$2:$B$10000=$E$4)*('FS2 - PY data'!$C$2:$C$10000=$F$4)*('FS2 - PY data'!$D$2:$D$10000=$A19)*('FS2 - PY data'!$E$2:$E$10000=L$10)*('FS2 - PY data'!$F$2:$F$10000))} -> 0
A20: Hotels | B20: {=SUMPRODUCT(('FS2 - PY data'!$A$2:$A$10000=$D$4)*('FS2 - PY data'!$B$2:$B$10000=$E$4)*('FS2 - PY data'!$C$2:$C$10000=$F$4)*('FS2 - PY data'!$D$2:$D$10000=$A20)*('FS2 - PY data'!$E$2:$E$10000=B$10)*('FS2 - PY data'!$F$2:$F$10000))} -> 0 | C20: {=SUMPRODUCT(('FS2 - PY data'!$A$2:$A$10000=$D$4)*('FS2 - PY data'!$B$2:$B$10000=$E$4)*('FS2 - PY data'!$C$2:$C$10000=$F$4)*('FS2 - PY data'!$D$2:$D$10000=$A20)*('FS2 - PY data'!$E$2:$E$10000=C$10)*('FS2 - PY data'!$F$2:$F$10000))} -> 0 | D20: {=SUMPRODUCT(('FS2 - PY data'!$A$2:$A$10000=$D$4)*('FS2 - PY data'!$B$2:$B$10000=$E$4)*('FS2 - PY data'!$C$2:$C$10000=$F$4)*('FS2 - PY data'!$D$2:$D$10000=$A20)*('FS2 - PY data'!$E$2:$E$10000=D$10)*('FS2 - PY data'!$F$2:$F$10000))} -> 0 | E20: {=SUMPRODUCT(('FS2 - PY data'!$A$2:$A$10000=$D$4)*('FS2 - PY data'!$B$2:$B$10000=$E$4)*('FS2 - PY data'!$C$2:$C$10000=$F$4)*('FS2 - PY data'!$D$2:$D$10000=$A20)*('FS2 - PY data'!$E$2:$E$10000=E$10)*('FS2 - PY data'!$F$2:$F$10000))} -> 0 | F20: {=SUMPRODUCT(('FS2 - PY data'!$A$2:$A$10000=$D$4)*('FS2 - PY data'!$B$2:$B$10000=$E$4)*('FS2 - PY data'!$C$2:$C$10000=$F$4)*('FS2 - PY data'!$D$2:$D$10000=$A20)*('FS2 - PY data'!$E$2:$E$10000=F$10)*('FS2 - PY data'!$F$2:$F$10000))} -> 0 | G20: {=SUMPRODUCT(('FS2 - PY data'!$A$2:$A$10000=$D$4)*('FS2 - PY data'!$B$2:$B$10000=$E$4)*('FS2 - PY data'!$C$2:$C$10000=$F$4)*('FS2 - PY data'!$D$2:$D$10000=$A20)*('FS2 - PY data'!$E$2:$E$10000=G$10)*('FS2 - PY data'!$F$2:$F$10000))} -> 0 | H20: {=SUMPRODUCT(('FS2 - PY data'!$A$2:$A$10000=$D$4)*('FS2 - PY data'!$B$2:$B$10000=$E$4)*('FS2 - PY data'!$C$2:$C$10000=$F$4)*('FS2 - PY data'!$D$2:$D$10000=$A20)*('FS2 - PY data'!$E$2:$E$10000=H$10)*('FS2 - PY data'!$F$2:$F$10000))} -> 0 | I20: {=SUMPRODUCT(('FS2 - PY data'!$A$2:$A$10000=$D$4)*('FS2 - PY data'!$B$2:$B$10000=$E$4)*('FS2 - PY data'!$C$2:$C$10000=$F$4)*('FS2 - PY data'!$D$2:$D$10000=$A20)*('FS2 - PY data'!$E$2:$E$10000=I$10)*('FS2 - PY data'!$F$2:$F$10000))} -> 0 | ... L20: {=SUMPRODUCT(('FS2 - PY data'!$A$2:$A$10000=$D$4)*('FS2 - PY data'!$B$2:$B$10000=$E$4)*('FS2 - PY data'!$C$2:$C$10000=$F$4)*('FS2 - PY data'!$D$2:$D$10000=$A20)*('FS2 - PY data'!$E$2:$E$10000=L$10)*('FS2 - PY data'!$F$2:$F$10000))} -> 0
A21: Houses converted to flats | B21: {=SUMPRODUCT(('FS2 - PY data'!$A$2:$A$10000=$D$4)*('FS2 - PY data'!$B$2:$B$10000=$E$4)*('FS2 - PY data'!$C$2:$C$10000=$F$4)*('FS2 - PY data'!$D$2:$D$10000=$A21)*('FS2 - PY data'!$E$2:$E$10000=B$10)*('FS2 - PY data'!$F$2:$F$10000))} -> 0 | C21: {=SUMPRODUCT(('FS2 - PY data'!$A$2:$A$10000=$D$4)*('FS2 - PY data'!$B$2:$B$10000=$E$4)*('FS2 - PY data'!$C$2:$C$10000=$F$4)*('FS2 - PY data'!$D$2:$D$10000=$A21)*('FS2 - PY data'!$E$2:$E$10000=C$10)*('FS2 - PY data'!$F$2:$F$10000))} -> 0 | D21: {=SUMPRODUCT(('FS2 - PY data'!$A$2:$A$10000=$D$4)*('FS2 - PY data'!$B$2:$B$10000=$E$4)*('FS2 - PY data'!$C$2:$C$10000=$F$4)*('FS2 - PY data'!$D$2:$D$10000=$A21)*('FS2 - PY data'!$E$2:$E$10000=D$10)*('FS2 - PY data'!$F$2:$F$10000))} -> 0 | E21: {=SUMPRODUCT(('FS2 - PY data'!$A$2:$A$10000=$D$4)*('FS2 - PY data'!$B$2:$B$10000=$E$4)*('FS2 - PY data'!$C$2:$C$10000=$F$4)*('FS2 - PY data'!$D$2:$D$10000=$A21)*('FS2 - PY data'!$E$2:$E$10000=E$10)*('FS2 - PY data'!$F$2:$F$10000))} -> 0 | F21: {=SUMPRODUCT(('FS2 - PY data'!$A$2:$A$10000=$D$4)*('FS2 - PY data'!$B$2:$B$10000=$E$4)*('FS2 - PY data'!$C$2:$C$10000=$F$4)*('FS2 - PY data'!$D$2:$D$10000=$A21)*('FS2 - PY data'!$E$2:$E$10000=F$10)*('FS2 - PY data'!$F$2:$F$10000))} -> 0 | G21: {=SUMPRODUCT(('FS2 - PY data'!$A$2:$A$10000=$D$4)*('FS2 - PY data'!$B$2:$B$10000=$E$4)*('FS2 - PY data'!$C$2:$C$10000=$F$4)*('FS2 - PY data'!$D$2:$D$10000=$A21)*('FS2 - PY data'!$E$2:$E$10000=G$10)*('FS2 - PY data'!$F$2:$F$10000))} -> 0 | H21: {=SUMPRODUCT(('FS2 - PY data'!$A$2:$A$10000=$D$4)*('FS2 - PY data'!$B$2:$B$10000=$E$4)*('FS2 - PY data'!$C$2:$C$10000=$F$4)*('FS2 - PY data'!$D$2:$D$10000=$A21)*('FS2 - PY data'!$E$2:$E$10000=H$10)*('FS2 - PY data'!$F$2:$F$10000))} -> 0 | I21: {=SUMPRODUCT(('FS2 - PY data'!$A$2:$A$10000=$D$4)*('FS2 - PY data'!$B$2:$B$10000=$E$4)*('FS2 - PY data'!$C$2:$C$10000=$F$4)*('FS2 - PY data'!$D$2:$D$10000=$A21)*('FS2 - PY data'!$E$2:$E$10000=I$10)*('FS2 - PY data'!$F$2:$F$10000))} -> 0 | ... L21: {=SUMPRODUCT(('FS2 - PY data'!$A$2:$A$10000=$D$4)*('FS2 - PY data'!$B$2:$B$10000=$E$4)*('FS2 - PY data'!$C$2:$C$10000=$F$4)*('FS2 - PY data'!$D$2:$D$10000=$A21)*('FS2 - PY data'!$E$2:$E$10000=L$10)*('FS2 - PY data'!$F$2:$F$10000))} -> 0
A22: Other sleeping accommodation | B22: {=SUMPRODUCT(('FS2 - PY data'!$A$2:$A$10000=$D$4)*('FS2 - PY data'!$B$2:$B$10000=$E$4)*('FS2 - PY data'!$C$2:$C$10000=$F$4)*('FS2 - PY data'!$D$2:$D$10000=$A22)*('FS2 - PY data'!$E$2:$E$10000=B$10)*('FS2 - PY data'!$F$2:$F$10000))} -> 0 | C22: {=SUMPRODUCT(('FS2 - PY data'!$A$2:$A$10000=$D$4)*('FS2 - PY data'!$B$2:$B$10000=$E$4)*('FS2 - PY data'!$C$2:$C$10000=$F$4)*('FS2 - PY data'!$D$2:$D$10000=$A22)*('FS2 - PY data'!$E$2:$E$10000=C$10)*('FS2 - PY data'!$F$2:$F$10000))} -> 0 | D22: {=SUMPRODUCT(('FS2 - PY data'!$A$2:$A$10000=$D$4)*('FS2 - PY data'!$B$2:$B$10000=$E$4)*('FS2 - PY data'!$C$2:$C$10000=$F$4)*('FS2 - PY data'!$D$2:$D$10000=$A22)*('FS2 - PY data'!$E$2:$E$10000=D$10)*('FS2 - PY data'!$F$2:$F$10000))} -> 0 | E22: {=SUMPRODUCT(('FS2 - PY data'!$A$2:$A$10000=$D$4)*('FS2 - PY data'!$B$2:$B$10000=$E$4)*('FS2 - PY data'!$C$2:$C$10000=$F$4)*('FS2 - PY data'!$D$2:$D$10000=$A22)*('FS2 - PY data'!$E$2:$E$10000=E$10)*('FS2 - PY data'!$F$2:$F$10000))} -> 0 | F22: {=SUMPRODUCT(('FS2 - PY data'!$A$2:$A$10000=$D$4)*('FS2 - PY data'!$B$2:$B$10000=$E$4)*('FS2 - PY data'!$C$2:$C$10000=$F$4)*('FS2 - PY data'!$D$2:$D$10000=$A22)*('FS2 - PY data'!$E$2:$E$10000=F$10)*('FS2 - PY data'!$F$2:$F$10000))} -> 0 | G22: {=SUMPRODUCT(('FS2 - PY data'!$A$2:$A$10000=$D$4)*('FS2 - PY data'!$B$2:$B$10000=$E$4)*('FS2 - PY data'!$C$2:$C$10000=$F$4)*('FS2 - PY data'!$D$2:$D$10000=$A22)*('FS2 - PY data'!$E$2:$E$10000=G$10)*('FS2 - PY data'!$F$2:$F$10000))} -> 0 | H22: {=SUMPRODUCT(('FS2 - PY data'!$A$2:$A$10000=$D$4)*('FS2 - PY data'!$B$2:$B$10000=$E$4)*('FS2 - PY data'!$C$2:$C$10000=$F$4)*('FS2 - PY data'!$D$2:$D$10000=$A22)*('FS2 - PY data'!$E$2:$E$10000=H$10)*('FS2 - PY data'!$F$2:$F$10000))} -> 0 | I22: {=SUMPRODUCT(('FS2 - PY data'!$A$2:$A$10000=$D$4)*('FS2 - PY data'!$B$2:$B$10000=$E$4)*('FS2 - PY data'!$C$2:$C$10000=$F$4)*('FS2 - PY data'!$D$2:$D$10000=$A22)*('FS2 - PY data'!$E$2:$E$10000=I$10)*('FS2 - PY data'!$F$2:$F$10000))} -> 0 | ... L22: {=SUMPRODUCT(('FS2 - PY data'!$A$2:$A$10000=$D$4)*('FS2 - PY data'!$B$2:$B$10000=$E$4)*('FS2 - PY data'!$C$2:$C$10000=$F$4)*('FS2 - PY data'!$D$2:$D$10000=$A22)*('FS2 - PY data'!$E$2:$E$10000=L$10)*('FS2 - PY data'!$F$2:$F$10000))} -> 0
... A32: Total | B32: {=SUMPRODUCT(('FS2 - PY data'!$A$2:$A$10000=$D$4)*('FS2 - PY data'!$B$2:$B$10000=$E$4)*('FS2 - PY data'!$C$2:$C$10000=$F$4)*('FS2 - PY data'!$D$2:$D$10000=$A32)*('FS2 - PY data'!$E$2:$E$10000=B$10)*('FS2 - PY data'!$F$2:$F$10000))} -> 0 | C32: {=SUMPRODUCT(('FS2 - PY data'!$A$2:$A$10000=$D$4)*('FS2 - PY data'!$B$2:$B$10000=$E$4)*('FS2 - PY data'!$C$2:$C$10000=$F$4)*('FS2 - PY data'!$D$2:$D$10000=$A32)*('FS2 - PY data'!$E$2:$E$10000=C$10)*('FS2 - PY data'!$F$2:$F$10000))} -> 0 | D32: {=SUMPRODUCT(('FS2 - PY data'!$A$2:$A$10000=$D$4)*('FS2 - PY data'!$B$2:$B$10000=$E$4)*('FS2 - PY data'!$C$2:$C$10000=$F$4)*('FS2 - PY data'!$D$2:$D$10000=$A32)*('FS2 - PY data'!$E$2:$E$10000=D$10)*('FS2 - PY data'!$F$2:$F$10000))} -> 0 | E32: {=SUMPRODUCT(('FS2 - PY data'!$A$2:$A$10000=$D$4)*('FS2 - PY data'!$B$2:$B$10000=$E$4)*('FS2 - PY data'!$C$2:$C$10000=$F$4)*('FS2 - PY data'!$D$2:$D$10000=$A32)*('FS2 - PY data'!$E$2:$E$10000=E$10)*('FS2 - PY data'!$F$2:$F$10000))} -> 0 | F32: {=SUMPRODUCT(('FS2 - PY data'!$A$2:$A$10000=$D$4)*('FS2 - PY data'!$B$2:$B$10000=$E$4)*('FS2 - PY data'!$C$2:$C$10000=$F$4)*('FS2 - PY data'!$D$2:$D$10000=$A32)*('FS2 - PY data'!$E$2:$E$10000=F$10)*('FS2 - PY data'!$F$2:$F$10000))} -> 0 | G32: {=SUMPRODUCT(('FS2 - PY data'!$A$2:$A$10000=$D$4)*('FS2 - PY data'!$B$2:$B$10000=$E$4)*('FS2 - PY data'!$C$2:$C$10000=$F$4)*('FS2 - PY data'!$D$2:$D$10000=$A32)*('FS2 - PY data'!$E$2:$E$10000=G$10)*('FS2 - PY data'!$F$2:$F$10000))} -> 0 | H32: {=SUMPRODUCT(('FS2 - PY data'!$A$2:$A$10000=$D$4)*('FS2 - PY data'!$B$2:$B$10000=$E$4)*('FS2 - PY data'!$C$2:$C$10000=$F$4)*('FS2 - PY data'!$D$2:$D$10000=$A32)*('FS2 - PY data'!$E$2:$E$10000=H$10)*('FS2 - PY data'!$F$2:$F$10000))} -> 0 | I32: {=SUMPRODUCT(('FS2 - PY data'!$A$2:$A$10000=$D$4)*('FS2 - PY data'!$B$2:$B$10000=$E$4)*('FS2 - PY data'!$C$2:$C$10000=$F$4)*('FS2 - PY data'!$D$2:$D$10000=$A32)*('FS2 - PY data'!$E$2:$E$10000=I$10)*('FS2 - PY data'!$F$2:$F$10000))} -> 0 | ... L32: {=SUMPRODUCT(('FS2 - PY data'!$A$2:$A$10000=$D$4)*('FS2 - PY data'!$B$2:$B$10000=$E$4)*('FS2 - PY data'!$C$2:$C$10000=$F$4)*('FS2 - PY data'!$D$2:$D$10000=$A32)*('FS2 - PY data'!$E$2:$E$10000=L$10)*('FS2 - PY data'!$F$2:$F$10000))} -> 0
B33: =B32-SUM(B11:B31) -> 0 | C33: =C32-SUM(C11:C31) -> 0 | D33: =D32-SUM(D11:D31) -> 0 | E33: =E32-SUM(E11:E31) -> 0 | F33: =F32-SUM(F11:F31) -> 0 | G33: =G32-SUM(G11:G31) -> 0 | H33: =H32-SUM(H11:H31) -> 0 | I33: =I32-SUM(I11:I31) -> 0 | ... L33: =L32-SUM(L11:L31) -> 0

Sheet FS2
C3: =Cover!A10 -> Shropshire
A7: FS2 - Number of premises and other fire safety activities (including statutory consultations from building control bodies and self assessments received through the Fire Gateway web site) FSO ONLY | O7: QA checks versus data submitted last year
A8: If a cell is highlighted yellow following data entry this indicates the figure inputted is significantly different to the figure inputted in the previous year. Please double check these figures prior to submitting this return. | O8: Cells highlighted yellow following data entry indicate a significant change between the figures inputted this year relative to the previous year. Please double check the relevant figures prior to submitting this return and provide explanation of why there is a significant increase/decrease in the numbers
B9: Number of: | H9: Hours spent on:
B10: Premises known (Please specify data source below) | C10: Building regulations consultations | D10: Other consultations | E10: Other FS activities | F10: Self assessments* | G10: Total number | H10: Building regulations consultations | I10: Other consultations | J10: Other FS activities | K10: Self assessments* | L10: Total hours
A11: Hospitals | G11: =SUM(C11:E11) -> 0 | L11: =SUM(H11:J11) -> 0
A12: Care homes | G12: =SUM(C12:E12) -> 0 | L12: =SUM(H12:J12) -> 0
A13: Houses in Multiple Occupation (HMO) | G13: =SUM(C13:E13) -> 0 | L13: =SUM(H13:J13) -> 0
A14: Purpose built flats 1-3 storeys | G14: =SUM(C14:E14) -> 0 | L14: =SUM(H14:J14) -> 0
A15: Purpose built flats 4-5 storeys | G15: =SUM(C15:E15) -> 0 | L15: =SUM(H15:J15) -> 0
A16: Purpose built flats 6-9 storeys | G16: =SUM(C16:E16) -> 0 | L16: =SUM(H16:J16) -> 0
A17: Purpose built flats >=10 storeys | G17: =SUM(C17:E17) -> 0 | L17: =SUM(H17:J17) -> 0
A18: Purpose built flats >= 4 storeys* | G18: =SUM(C18:E18) -> 0 | L18: =SUM(H18:J18) -> 0
A19: Hostels | G19: =SUM(C19:E19) -> 0 | L19: =SUM(H19:J19) -> 0
A20: Hotels | G20: =SUM(C20:E20) -> 0 | L20: =SUM(H20:J20) -> 0
A21: Houses converted to flats | G21: =SUM(C21:E21) -> 0 | L21: =SUM(H21:J21) -> 0
A22: Other sleeping accommodation | G22: =SUM(C22:E22) -> 0 | L22: =SUM(H22:J22) -> 0
... A31: Other | G31: =SUM(C31:E31) -> 0 | L31: =SUM(H31:J31) -> 0
A32: Total | B32: =SUM(B11:B31) -> 0 | C32: =SUM(C11:C31) -> 0 | D32: =SUM(D11:D31) -> 0 | E32: =SUM(E11:E31) -> 0 | F32: =SUM(F11:F31) -> 0 | G32: =SUM(G11:G31) -> 0 | H32: =SUM(H11:H31) -> 0 | I32: =SUM(I11:I31) -> 0 | ... L32: =SUM(L11:L31) -> 0
A36: FRS Notes
A37: Data source for number of premises

Sheet FS6a
D3: =Cover!A10 -> Shropshire
A6: FS6a - Non-compliance resulting in action of any type (excluding prosecutions) FSO ONLY
A7: If a cell is highlighted yellow following data entry this indicates the figure inputted is significantly different to the figure inputted in the previous year. Please double check these figures prior to submitting this return.
A8: Non-compliance resulting in action of any type (excluding prosecutions)
C9: Duty to take general fire precautions (Article 8) | D9: Risk Assessment (Article 9) | E9: Principles of prevention to be applied (Article 10) | F9: Fire safety arrangements (Article 11) | G9: Elimination or reduction of risks from dangerous substances (Article 12) | H9: Fire-fighting and fire detection (Article 13) | I9: Emergency routes and exits (Article 14) | J9: Procedures for serious and imminent danger and for danger areas (Article 15) | K9: Additional emergency measures in respect of dangerous substances (Article 16) | L9: Maintenance (Article 17) | M9: Safety assistance (Article 18) | N9: Provision of information to employees (Article 19)
C10: art8 | D10: art9 | E10: art10 | F10: art11 | G10: art12 | H10: art13 | I10: art14 | J10: art15 | K10: art16 | L10: art17 | M10: art18 | N10: art19
A11: Hospitals | B11: hospitals
A12: Care homes | B12: care
A13: Houses in Multiple Occupation (HMO) | B13: hmo
A14: Purpose built flats 1-3 storeys
A15: Purpose built flats 4-5 storeys
A16: Purpose built flats 6-9 storeys
A17: Purpose built flats >=10 storeys
A18: Purpose built flats >= 4 storeys* | B18: flat
A19: Hostels | B19: hostel
A20: Hotels | B20: hotel
A21: Houses converted to flats | B21: converted
A22: Other sleeping accommodation | B22: othersleep
A23: Further education | B23: fured
A24: Public buildings | B24: public
A25: Licensed premises | B25: licensed
A26: Schools | B26: schools
A27: Shops | B27: shops
A28: Other premises open to public | B28: otherprem
A29: Factories or warehouses | B29: factories
... A31: Other | B31: other
A32: Total | C32: =SUM(C11:C31) -> 0 | D32: =SUM(D11:D31) -> 0 | E32: =SUM(E11:E31) -> 0 | F32: =SUM(F11:F31) -> 0 | G32: =SUM(G11:G31) -> 0 | H32: =SUM(H11:H31) -> 0 | I32: =SUM(I11:I31) -> 0 | J32: =SUM(J11:J31) -> 0 | ... N32: =SUM(N11:N31) -> 0
C36: FRS Notes

Sheet FS6b
D3: =Cover!A10 -> Shropshire
A6: FS6b - Non-compliance resulting in action of any type (excluding prosecutions) FSO ONLY
A7: If a cell is highlighted yellow following data entry this indicates the figure inputted is significantly different to the figure inputted in the previous year. Please double check these figures prior to submitting this return.
A8: Non-compliance resulting in action of any type (excluding prosecutions) - Continued
C9: Provision of information to employers and the self-employed from outside undertakings (Article 20) | D9: Training (Article 21) | E9: Co-operation and co-ordination (Article 22) | F9: General duties of employees at work (Article 23) | G9: Power to make regulations about fire precautions (Article 24) | H9: Powers of inspectors (Article 27) | I9: Failure to comply with Alteration Notices (Article 29) | J9: Failure to comply with Enforcement Notices (Article 30) | K9: Failure to comply with Prohibition Notices (Article 31) | L9: Firefighters' switches for luminous tube signs, etc (Article 37) | M9: Maintenance of measures provided for protection of firefighters (Article 38) | N9: Other matters not recorded elsewhere (Article 32)
C10: art20 | D10: art21 | E10: art22 | F10: art23 | G10: art24 | H10: art27 | I10: art29fail | J10: art30fail | K10: art31fail | L10: art37 | M10: art38 | N10: art32
A11: Hospitals | B11: hospitals
A12: Care homes | B12: care
A13: Houses in Multiple Occupation (HMO) | B13: hmo
A14: Purpose built flats 1-3 storeys
A15: Purpose built flats 4-5 storeys
A16: Purpose built flats 6-9 storeys
A17: Purpose built flats >=10 storeys
A18: Purpose built flats >= 4 storeys* | B18: flat
A19: Hostels | B19: hostel
A20: Hotels | B20: hotel
A21: Houses converted to flats | B21: converted
A22: Other sleeping accommodation | B22: othersleep
A23: Further education | B23: fured
A24: Public buildings | B24: public
A25: Licensed premises | B25: licensed
A26: Schools | B26: schools
A27: Shops | B27: shops
A28: Other premises open to public | B28: otherprem
A29: Factories or warehouses | B29: factories
... A31: Other | B31: other
A32: Total | C32: =SUM(C11:C31) -> 0 | D32: =SUM(D11:D31) -> 0 | E32: =SUM(E11:E31) -> 0 | F32: =SUM(F11:F31) -> 0 | G32: =SUM(G11:G31) -> 0 | H32: =SUM(H11:H31) -> 0 | I32: =SUM(I11:I31) -> 0 | J32: =SUM(J11:J31) -> 0 | ... N32: =SUM(N11:N31) -> 0
C36: FRS Notes

Sheet FS7
D3: =Cover!A10 -> Shropshire
A6: FS7 - Prosecutions FSO ONLY
A7: If a cell is highlighted yellow following data entry this indicates the figure inputted is significantly different to the figure inputted in the previous year. Please double check these figures prior to submitting this return.
A8: Number of prosecutions
C9: Number of Prosecutions under Article 32 | D9: Number of appeals against conviction resulting in acquittal | E9: Number of appeals against conviction resulting in conviction upheld | F9: Number of prosecutions not yet heard/determined | G9: Number of prosecutions withdrawn by enforcing authority | H9: Number of prosecutions brought forward from the previous reporting period | I9: Number of prosecutions carried forward to the next reporting period
C10: art32proc | D10: acq | E10: conv | F10: notheard | G10: proswithd | H10: prosforwpre | I10: prosforwnext
A11: Hospitals | B11: hospitals | I11: =F11 -> 0
A12: Care homes | B12: care | I12: =F12 -> 0
A13: Houses in Multiple Occupation (HMO) | B13: hmo | I13: =F13 -> 0
A14: Purpose built flats 1-3 storeys | I14: =F14 -> 0
A15: Purpose built flats 4-5 storeys | I15: =F15 -> 0
A16: Purpose built flats 6-9 storeys | I16: =F16 -> 0
A17: Purpose built flats >=10 storeys | I17: =F17 -> 0
A18: Purpose built flats >= 4 storeys* | B18: flat | I18: =F18 -> 0
A19: Hostels | B19: hostel | I19: =F19 -> 0
A20: Hotels | B20: hotel | I20: =F20 -> 0
A21: Houses converted to flats | B21: converted | I21: =F21 -> 0
A22: Other sleeping accommodation | B22: othersleep | I22: =F22 -> 0
A23: Further education | B23: fured | I23: =F23 -> 0
A24: Public buildings | B24: public | I24: =F24 -> 0
A25: Licensed premises | B25: licensed | I25: =F25 -> 0
A26: Schools | B26: schools | I26: =F26 -> 0
A27: Shops | B27: shops | I27: =F27 -> 0
A28: Other premises open to public | B28: otherprem | I28: =F28 -> 0
A29: Factories or warehouses | B29: factories | I29: =F29 -> 0
... A31: Other | B31: other | I31: =F31 -> 0
A32: Total | C32: =SUM(C11:C31) -> 0 | D32: =SUM(D11:D31) -> 0 | E32: =SUM(E11:E31) -> 0 | F32: =SUM(F11:F31) -> 0 | G32: =SUM(G11:G31) -> 0 | H32: =SUM(H11:H31) -> 0 | I32: =SUM(I11:I31) -> 0
C37: FRS Notes
M38: Prosecutions brought forward from the previous reporting period match the prosecutions carried forward from the previous year
M39: =IF(H32=I32,TRUE) -> TRUE
M41: The total number of prosecutions brought forward from the previous reporting period should match the prosecutions carried forward from the previous year. If this is not possible for any reason please explain below.

Sheet FS7 PY
A1: Number of prosecutions
C2: Number of Prosecutions under Article 32 | D2: Number of appeals against conviction resulting in acquittal | E2: Number of appeals against conviction resulting in conviction upheld | F2: Number of prosecutions not yet heard/determined | G2: Number of prosecutions withdrawn by enforcing authority | H2: Number of prosecutions carried forward from the previous reporting period | I2: Number of prosecutions carried forward to the next reporting period
C3: art32proc | D3: acq | E3: conv | F3: notheard | G3: proswithd | H3: prosforwpre | I3: prosforwnext
A4: Hospitals | B4: hospitals
A5: Care homes | B5: care
A6: Houses in Multiple Occupation (HMO) | B6: hmo
A7: Purpose built flats 1-3 storeys
A8: Purpose built flats 4-5 storeys
A9: Purpose built flats 6-9 storeys
A10: Purpose built flats >=10 storeys
A11: Purpose built flats >= 4 storeys* | B11: flat
A12: Hostels | B12: hostel
A13: Hotels | B13: hotel
A14: Houses converted to flats | B14: converted
A15: Other sleeping accommodation | B15: othersleep
A16: Further education | B16: fured
A17: Public buildings | B17: public
A18: Licensed premises | B18: licensed
A19: Schools | B19: schools
A20: Shops | B20: shops
A21: Other premises open to public | B21: otherprem
A22: Factories or warehouses | B22: factories
... A24: Other | B24: other
A25: Total | C25: {=SUMPRODUCT(('FS7 - PY data'!$E$2:$E$10000='FS7 PY'!C$2)*('FS7 - PY data'!$F$2:$F$10000))} -> 0 | D25: {=SUMPRODUCT(('FS7 - PY data'!$E$2:$E$10000='FS7 PY'!D$2)*('FS7 - PY data'!$F$2:$F$10000))} -> 0 | E25: {=SUMPRODUCT(('FS7 - PY data'!$E$2:$E$10000='FS7 PY'!E$2)*('FS7 - PY data'!$F$2:$F$10000))} -> 0 | F25: {=SUMPRODUCT(('FS7 - PY data'!$E$2:$E$10000='FS7 PY'!F$2)*('FS7 - PY data'!$F$2:$F$10000))} -> 0 | G25: {=SUMPRODUCT(('FS7 - PY data'!$E$2:$E$10000='FS7 PY'!G$2)*('FS7 - PY data'!$F$2:$F$10000))} -> 0 | H25: {=SUMPRODUCT(('FS7 - PY data'!$E$2:$E$10000='FS7 PY'!H$2)*('FS7 - PY data'!$F$2:$F$10000))} -> 0 | I25: {=SUMPRODUCT(('FS7 - PY data'!$E$2:$E$10000='FS7 PY'!I$2)*('FS7 - PY data'!$F$2:$F$10000))} -> 0

Sheet FS7 - PY data
A1: SHEET | B1: FINANCIAL_YEAR | C1: FRS_NAME | D1: PREMISES_TYPE | E1: ACTION_TYPE | F1: VALUE

Sheet FS8a
D3: =Cover!A10 -> Shropshire
A6: FS8a - Prosecutions - convictions Art.8-19 FSO ONLY
A7: If a cell is highlighted yellow following data entry this indicates the figure inputted is significantly different to the figure inputted in the previous year. Please double check these figures prior to submitting this return.
A8: Number of prosecutions - convictions
C9: Duty to take general fire precautions (Article 8) | D9: Risk Assessment (Article 9) | E9: Principles of prevention to be applied (Article 10) | F9: Fire safety arrangements (Article 11) | G9: Elimination or reduction of risks from dangerous substances (Article 12) | H9: Fire-fighting and fire detection (Article 13) | I9: Emergency routes and exits (Article 14) | J9: Procedures for serious and imminent danger and for danger areas (Article 15) | K9: Additional emergency measures in respect of dangerous substances (Article 16) | L9: Maintenance (Article 17) | M9: Safety assistance (Article 18) | N9: Provision of information to employees (Article 19)
C10: convart8 | D10: convart9 | E10: convart10 | F10: convart11 | G10: convart12 | H10: convart13 | I10: convart14 | J10: convart15 | K10: convart16 | L10: convart17 | M10: convart18 | N10: convart19
A11: Hospitals | B11: hospitals
A12: Care homes | B12: care
A13: Houses in Multiple Occupation (HMO) | B13: hmo
A14: Purpose built flats 1-3 storeys
A15: Purpose built flats 4-5 storeys
A16: Purpose built flats 6-9 storeys
A17: Purpose built flats >=10 storeys
A18: Purpose built flats >= 4 storeys* | B18: flat
A19: Hostels | B19: hostel
A20: Hotels | B20: hotel
A21: Houses converted to flats | B21: converted
A22: Other sleeping accommodation | B22: othersleep
A23: Further education | B23: fured
A24: Public buildings | B24: public
A25: Licensed premises | B25: licensed
A26: Schools | B26: schools
A27: Shops | B27: shops
A28: Other premises open to public | B28: otherprem
A29: Factories or warehouses | B29: factories
... A31: Other | B31: other
A32: Total | C32: =SUM(C11:C31) -> 0 | D32: =SUM(D11:D31) -> 0 | E32: =SUM(E11:E31) -> 0 | F32: =SUM(F11:F31) -> 0 | G32: =SUM(G11:G31) -> 0 | H32: =SUM(H11:H31) -> 0 | I32: =SUM(I11:I31) -> 0 | J32: =SUM(J11:J31) -> 0 | ... N32: =SUM(N11:N31) -> 0
C37: FRS Notes

Sheet FS8b
D3: =Cover!A10 -> Shropshire
A6: FS8b - Prosecutions - convictions Art.20-24, 27, 29-32, 37-38 FSO ONLY
A7: If a cell is highlighted yellow following data entry this indicates the figure inputted is significantly different to the figure inputted in the previous year. Please double check these figures prior to submitting this return.
A8: Number of prosecutions - convictions (continued)
