Workbook
Name _Toc252461075: Guidance!$A$3
Name Data: #REF!
Name Data: #REF!
Name FS3_f: #REF!
Name FS3_formula: #REF!
Name FS4_formula: #REF!
Name FS5_formula: #REF!
Name FS9_f: '[1]FS9 2020-21'!#REF!
Name FS9_formula: [1]FS9!#REF!
Name HR1_formula: #REF!
Name HR2_f: #REF!
Name HR2_formula: #REF!
Name HR2_formula: #REF!
Name HR2_formula: #REF!
Name HR2_formula: #REF!
Name HR2_formula: #REF!
Name HR3_formula: #REF!
Name HR3_formula: #REF!
Name HR3_formula: #REF!
Name HR3_formula: #REF!
Name HR3_formula: #REF!
Name HR3_formula: #REF!
Name HR3_formula: #REF!
Name HR4_formula: #REF!
Name HR4_formula: #REF!
Name HR4_formula: #REF!
Name HR4_formula: #REF!
Name HR4_formula: #REF!
Name HR4_formula: #REF!
Name HR4_formula: #REF!
Name HR5_formula: #REF!
Name HR5_formula: #REF!
Name HR5_formula: #REF!
Name HR5_formula: #REF!
Name HR5_formula: #REF!
Name HR5_formula: #REF!
Name HR5_formula: #REF!

Sheet Cover
A6: 2025_26
A7: Operational Statistics Collection
A8: LE Tables
A10: =VLOOKUP(B250,B251:D316,2,FALSE) -> Shropshire
A11: =VLOOKUP(B250,B251:D316,3,FALSE) -> E31000032
A14: Index of Tables | B14: Description
A15: LE1a | B15: Number of wholetime firefighters leaving by reason
A16: LE1b | B16: Number of wholetime firefighters leaving by gender, age, disability, ethnicity, religion and sexual orientation
A17: LE2a | B17: Number of on call firefighters leaving by reason
A18: LE2b | B18: Number of on call firefighters leaving by gender, age, disability, ethnicity, religion and sexual orientation
A19: LE3a | B19: Number of fire control staff leaving by reason
A20: LE3b | B20: Number of fire control staff leaving by gender, age, disability, ethnicity, religion and sexual orientation
A21: LE4a | B21: Number of support staff leaving by reason
A22: LE4b | B22: Number of support staff leaving by gender, age, disability, ethnicity, religion and sexual orientation
A23: Guidance | B23: Guidance notes
A25: Key
A26: 999999999 | B26: Cells highlighted yellow following data entry indicate a significant change in the figures inputted relative to the previous year. Please double check the relevant figures prior to submitting this return.
A28: Please complete by Friday 12 June 2026 and send the spreadsheet by e-mail to: FireStatistics@homeoffice.gov.uk
A31: Contact
A32: E-mail Address
A34: If you have any comments on the data submitted please provide them in the box below. If not, please leave blank.
G38: 1
G39: 2
G40: 3
G41: 4
A250: FRS Selector>>>>> | B250: 35 | C250: =MAX(B251:B316) -> 45
B251: 1 | C251: Avon | D251: E31000001
B252: 2 | C252: Bedfordshire | D252: E31000002
B253: 3 | C253: Berkshire | D253: E31000003
B254: 4 | C254: Buckinghamshire | D254: E31000004
B255: 5 | C255: Cambridgeshire | D255: E31000005
B256: 6 | C256: Cheshire | D256: E31000006
B257: 7 | C257: Cleveland | D257: E31000007
B258: 8 | C258: Cornwall | D258: E31000008
B259: 9 | C259: Cumbria | D259: E31000009
B260: 10 | C260: Derbyshire | D260: E31000010
B261: 11 | C261: Devon and Somerset | D261: E31000011
B262: 12 | C262: Dorset and Wiltshire | D262: E31000047
... B295: 45 | C295: North West Fire Control | D295: NWFC
B316: 0 | C316: Template FRS | D316: 0
...

Sheet Guidance
A1: Guidance notes for the forms on numbers of leavers (LE1-4)
A3: General guidance
A4: LE1a, LE2a, LE3a & LE4a provide information on the number (headcount) of staff leaving the fire service during the latest reporting period 1 April to 31 March.
A5: These returns enable monitoring of retention of firefighters on a national basis, assessing the reasons for leaving the FRS.
A6: The forms collect information on the following reasons for leaving the service:
A7: 1a. Moving - to another FRS
A8: 1b. Moving - within FRS from operational (firefighter or control) to support staff
A9: 1b. Moving - within FRS from support to operational (firefighter or control) staff [LE4 only]
A10: 2a. Resignation - to take up alternative employment
A11: 2b. Resignation - due to ill health
A12: 2c. Resignation - any other reason (please specify)
A13: 2d. Resignation - issues with primary employment/other work commitments [LE2 only]
... A27: Definitions
A28: Leavers: | C28: All personnel who ceased to be employed by the FRS during the reporting period. Include personnel whose last day of employment in the fire service, regardless of any prior periods of sickness or suspension, falls within the latest period 1 April to 31 March. New temporary and fixed-term staff who leave the service should also be included.
C29: Personnel who's last day is the 31st March should be counted in the workforce total HR return and should then be counted in the leavers return in the following year.
C30: Exclude personnel transferring to other FRSs (e.g. during a merger) or being seconded to Home Office, Fire Service College etc.
C31: Where, at the end of the reporting year, it is known that an appeal is pending over the dismissal of an individual, be it for disciplinary, medical or proficiency reasons, then the person should not to be included in the leavers return until the outcome of the appeal is known, which may be in the following reporting year.
C32: Personnel leaving should only be counted once, even if they have 2 contracts of employment. Personnel who have 2 contracts of employment and leave the service for different reasons for each contract should be counted once under their primary contract. If they only resign from 1 of the 2 contracts, they should not be included in these returns.
A33: Moving to another Fire and Rescue Service: | C33: Resignation to take employment with another FRS, please do not include transfers (e.g. that occur during a merger)
A34: Moving within the same Fire and Rescue Service from operational to support personnel or support to operational personnel: | C34: Where a person leaves to take up another type of employment within the same FRS as support staff (e.g. wholetime staff re-engaged under the FPS scheme) or moves from support to operational staff.
A35: Resignation to take up alternative employment: | C35: Resignation to take any other employment outside the FRS
A36: Resignation - ill health: | C36: Personnel resigning on the grounds of ill-health only
A37: Resignation - any other reason: | C37: Include personnel resigning as a result of harassment or discrimination, not on the grounds of ill-health.
A38: Redundancy - compulsory: | C38: Where a person has been made compulsory redundant by the FRS
A39: Redundancy - voluntary: | C39: Where a person has taken voluntary redundancy
A40: Retirement - early: | C40: Where a person has taken early retirement, this includes due to ill health
A41: Retirement - normal: | C41: Where a person leaves the FRS to take up retirement after having served their eligible length of service to receive a full pension.
A42: Dismissal - poor performance (including failure to maintain fitness): | C42: Termination of the contract of employment with FRS as a consequence of poor performance. This includes failure to maintain fitness.
A43: Dismissal - disciplinary grounds: | C43: Termination of the contract of employment with FRS for disciplinary reasons such as gross misconduct.
A44: Deceased: | C44: Please record if a person had died in the period 1 April 2025 to 31 March 2026.
A45: LE1b, LE2b, LE3b & LE4b provide information on the diversity characteristics of staff leaving the fire service during the latest reporting period 1 April to 31 March.
A46: Gender: | C46: Gender is to be recorded as gender identity.
C47: Guidance on reporting gender identity can be found here:
C48: Gender Identity Data Harmonisation Guidance
C49: The categories provided are "Male", "Female", "Other" and "Unknown". Anyone choosing "prefer not to say" or similar terms should be included in "unknown". While we acknowledge there are many other gender identity categories, the "Other" category is currently being used while the central government Analysis Function draft and update their guidance on gender harmonisation standard.
A50: Age groups: | C50: Staff should be entered in the appropriate age categories in sheets HR2-7.
C51: If the age is not known or staff have opted for "prefer not to say" or similar terms, please record under ‘Not stated’.
A52: Ethnicity: | C52: From the data collection in 2025 (data for 2025/26), the ethnicity categories aligned to the central government Analysis Function ethnicity harmonisation standard.
C53: Data for ethnicity are collected from the following categories and sub-categories:
C54: o White
...

Sheet LE - PY data
A1: SHEET | B1: FINANCIAL_YEAR | C1: FRS_NAME | D1: ROLE | E1: RANK | F1: LEAVING_REASON | G1: TOTAL

Sheet LE1a PY
C4: LE1 | D4: =VLOOKUP(Cover!A6,Cover!B319:D331,2,FALSE) -> 2024/25 | E4: =Cover!A10 -> Shropshire
B7: Brigade Manager | C7: Area Manager | D7: Group Manager | E7: Station Manager | F7: Watch Manager | G7: Crew Manager | H7: Firefighter | I7: Total
A8: 1a. Moving - to another FRS | B8: {=SUMPRODUCT(('LE - PY data'!$A$2:$A$10000='LE1a PY'!$C$4)*('LE - PY data'!$B$2:$B$10000='LE1a PY'!$D$4)*('LE - PY data'!$C$2:$C$10000='LE1a PY'!$E$4)*('LE - PY data'!$E$2:$E$10000='LE1a PY'!B$7)*('LE - PY data'!$F$2:$F$10000='LE1a PY'!$A8)*('LE - PY data'!$G$2:$G$10000))} -> 0 | C8: {=SUMPRODUCT(('LE - PY data'!$A$2:$A$10000='LE1a PY'!$C$4)*('LE - PY data'!$B$2:$B$10000='LE1a PY'!$D$4)*('LE - PY data'!$C$2:$C$10000='LE1a PY'!$E$4)*('LE - PY data'!$E$2:$E$10000='LE1a PY'!C$7)*('LE - PY data'!$F$2:$F$10000='LE1a PY'!$A8)*('LE - PY data'!$G$2:$G$10000))} -> 0 | D8: {=SUMPRODUCT(('LE - PY data'!$A$2:$A$10000='LE1a PY'!$C$4)*('LE - PY data'!$B$2:$B$10000='LE1a PY'!$D$4)*('LE - PY data'!$C$2:$C$10000='LE1a PY'!$E$4)*('LE - PY data'!$E$2:$E$10000='LE1a PY'!D$7)*('LE - PY data'!$F$2:$F$10000='LE1a PY'!$A8)*('LE - PY data'!$G$2:$G$10000))} -> 0 | E8: {=SUMPRODUCT(('LE - PY data'!$A$2:$A$10000='LE1a PY'!$C$4)*('LE - PY data'!$B$2:$B$10000='LE1a PY'!$D$4)*('LE - PY data'!$C$2:$C$10000='LE1a PY'!$E$4)*('LE - PY data'!$E$2:$E$10000='LE1a PY'!E$7)*('LE - PY data'!$F$2:$F$10000='LE1a PY'!$A8)*('LE - PY data'!$G$2:$G$10000))} -> 0 | F8: {=SUMPRODUCT(('LE - PY data'!$A$2:$A$10000='LE1a PY'!$C$4)*('LE - PY data'!$B$2:$B$10000='LE1a PY'!$D$4)*('LE - PY data'!$C$2:$C$10000='LE1a PY'!$E$4)*('LE - PY data'!$E$2:$E$10000='LE1a PY'!F$7)*('LE - PY data'!$F$2:$F$10000='LE1a PY'!$A8)*('LE - PY data'!$G$2:$G$10000))} -> 0 | G8: {=SUMPRODUCT(('LE - PY data'!$A$2:$A$10000='LE1a PY'!$C$4)*('LE - PY data'!$B$2:$B$10000='LE1a PY'!$D$4)*('LE - PY data'!$C$2:$C$10000='LE1a PY'!$E$4)*('LE - PY data'!$E$2:$E$10000='LE1a PY'!G$7)*('LE - PY data'!$F$2:$F$10000='LE1a PY'!$A8)*('LE - PY data'!$G$2:$G$10000))} -> 0 | H8: {=SUMPRODUCT(('LE - PY data'!$A$2:$A$10000='LE1a PY'!$C$4)*('LE - PY data'!$B$2:$B$10000='LE1a PY'!$D$4)*('LE - PY data'!$C$2:$C$10000='LE1a PY'!$E$4)*('LE - PY data'!$E$2:$E$10000='LE1a PY'!H$7)*('LE - PY data'!$F$2:$F$10000='LE1a PY'!$A8)*('LE - PY data'!$G$2:$G$10000))} -> 0 | I8: {=SUMPRODUCT(('LE - PY data'!$A$2:$A$10000='LE1a PY'!$C$4)*('LE - PY data'!$B$2:$B$10000='LE1a PY'!$D$4)*('LE - PY data'!$C$2:$C$10000='LE1a PY'!$E$4)*('LE - PY data'!$F$2:$F$10000='LE1a PY'!$A8)*('LE - PY data'!$G$2:$G$10000))} -> 0
A9: 1b. Moving - within FRS from operational (firefighter or control) to support staff | B9: {=SUMPRODUCT(('LE - PY data'!$A$2:$A$10000='LE1a PY'!$C$4)*('LE - PY data'!$B$2:$B$10000='LE1a PY'!$D$4)*('LE - PY data'!$C$2:$C$10000='LE1a PY'!$E$4)*('LE - PY data'!$E$2:$E$10000='LE1a PY'!B$7)*('LE - PY data'!$F$2:$F$10000='LE1a PY'!$A9)*('LE - PY data'!$G$2:$G$10000))} -> 0 | C9: {=SUMPRODUCT(('LE - PY data'!$A$2:$A$10000='LE1a PY'!$C$4)*('LE - PY data'!$B$2:$B$10000='LE1a PY'!$D$4)*('LE - PY data'!$C$2:$C$10000='LE1a PY'!$E$4)*('LE - PY data'!$E$2:$E$10000='LE1a PY'!C$7)*('LE - PY data'!$F$2:$F$10000='LE1a PY'!$A9)*('LE - PY data'!$G$2:$G$10000))} -> 0 | D9: {=SUMPRODUCT(('LE - PY data'!$A$2:$A$10000='LE1a PY'!$C$4)*('LE - PY data'!$B$2:$B$10000='LE1a PY'!$D$4)*('LE - PY data'!$C$2:$C$10000='LE1a PY'!$E$4)*('LE - PY data'!$E$2:$E$10000='LE1a PY'!D$7)*('LE - PY data'!$F$2:$F$10000='LE1a PY'!$A9)*('LE - PY data'!$G$2:$G$10000))} -> 0 | E9: {=SUMPRODUCT(('LE - PY data'!$A$2:$A$10000='LE1a PY'!$C$4)*('LE - PY data'!$B$2:$B$10000='LE1a PY'!$D$4)*('LE - PY data'!$C$2:$C$10000='LE1a PY'!$E$4)*('LE - PY data'!$E$2:$E$10000='LE1a PY'!E$7)*('LE - PY data'!$F$2:$F$10000='LE1a PY'!$A9)*('LE - PY data'!$G$2:$G$10000))} -> 0 | F9: {=SUMPRODUCT(('LE - PY data'!$A$2:$A$10000='LE1a PY'!$C$4)*('LE - PY data'!$B$2:$B$10000='LE1a PY'!$D$4)*('LE - PY data'!$C$2:$C$10000='LE1a PY'!$E$4)*('LE - PY data'!$E$2:$E$10000='LE1a PY'!F$7)*('LE - PY data'!$F$2:$F$10000='LE1a PY'!$A9)*('LE - PY data'!$G$2:$G$10000))} -> 0 | G9: {=SUMPRODUCT(('LE - PY data'!$A$2:$A$10000='LE1a PY'!$C$4)*('LE - PY data'!$B$2:$B$10000='LE1a PY'!$D$4)*('LE - PY data'!$C$2:$C$10000='LE1a PY'!$E$4)*('LE - PY data'!$E$2:$E$10000='LE1a PY'!G$7)*('LE - PY data'!$F$2:$F$10000='LE1a PY'!$A9)*('LE - PY data'!$G$2:$G$10000))} -> 0 | H9: {=SUMPRODUCT(('LE - PY data'!$A$2:$A$10000='LE1a PY'!$C$4)*('LE - PY data'!$B$2:$B$10000='LE1a PY'!$D$4)*('LE - PY data'!$C$2:$C$10000='LE1a PY'!$E$4)*('LE - PY data'!$E$2:$E$10000='LE1a PY'!H$7)*('LE - PY data'!$F$2:$F$10000='LE1a PY'!$A9)*('LE - PY data'!$G$2:$G$10000))} -> 0 | I9: {=SUMPRODUCT(('LE - PY data'!$A$2:$A$10000='LE1a PY'!$C$4)*('LE - PY data'!$B$2:$B$10000='LE1a PY'!$D$4)*('LE - PY data'!$C$2:$C$10000='LE1a PY'!$E$4)*('LE - PY data'!$F$2:$F$10000='LE1a PY'!$A9)*('LE - PY data'!$G$2:$G$10000))} -> 0
A10: 1. Total moving | B10: {=SUMPRODUCT(('LE - PY data'!$A$2:$A$10000='LE1a PY'!$C$4)*('LE - PY data'!$B$2:$B$10000='LE1a PY'!$D$4)*('LE - PY data'!$C$2:$C$10000='LE1a PY'!$E$4)*('LE - PY data'!$E$2:$E$10000='LE1a PY'!B$7)*('LE - PY data'!$F$2:$F$10000='LE1a PY'!$A10)*('LE - PY data'!$G$2:$G$10000))} -> 0 | C10: {=SUMPRODUCT(('LE - PY data'!$A$2:$A$10000='LE1a PY'!$C$4)*('LE - PY data'!$B$2:$B$10000='LE1a PY'!$D$4)*('LE - PY data'!$C$2:$C$10000='LE1a PY'!$E$4)*('LE - PY data'!$E$2:$E$10000='LE1a PY'!C$7)*('LE - PY data'!$F$2:$F$10000='LE1a PY'!$A10)*('LE - PY data'!$G$2:$G$10000))} -> 0 | D10: {=SUMPRODUCT(('LE - PY data'!$A$2:$A$10000='LE1a PY'!$C$4)*('LE - PY data'!$B$2:$B$10000='LE1a PY'!$D$4)*('LE - PY data'!$C$2:$C$10000='LE1a PY'!$E$4)*('LE - PY data'!$E$2:$E$10000='LE1a PY'!D$7)*('LE - PY data'!$F$2:$F$10000='LE1a PY'!$A10)*('LE - PY data'!$G$2:$G$10000))} -> 0 | E10: {=SUMPRODUCT(('LE - PY data'!$A$2:$A$10000='LE1a PY'!$C$4)*('LE - PY data'!$B$2:$B$10000='LE1a PY'!$D$4)*('LE - PY data'!$C$2:$C$10000='LE1a PY'!$E$4)*('LE - PY data'!$E$2:$E$10000='LE1a PY'!E$7)*('LE - PY data'!$F$2:$F$10000='LE1a PY'!$A10)*('LE - PY data'!$G$2:$G$10000))} -> 0 | F10: {=SUMPRODUCT(('LE - PY data'!$A$2:$A$10000='LE1a PY'!$C$4)*('LE - PY data'!$B$2:$B$10000='LE1a PY'!$D$4)*('LE - PY data'!$C$2:$C$10000='LE1a PY'!$E$4)*('LE - PY data'!$E$2:$E$10000='LE1a PY'!F$7)*('LE - PY data'!$F$2:$F$10000='LE1a PY'!$A10)*('LE - PY data'!$G$2:$G$10000))} -> 0 | G10: {=SUMPRODUCT(('LE - PY data'!$A$2:$A$10000='LE1a PY'!$C$4)*('LE - PY data'!$B$2:$B$10000='LE1a PY'!$D$4)*('LE - PY data'!$C$2:$C$10000='LE1a PY'!$E$4)*('LE - PY data'!$E$2:$E$10000='LE1a PY'!G$7)*('LE - PY data'!$F$2:$F$10000='LE1a PY'!$A10)*('LE - PY data'!$G$2:$G$10000))} -> 0 | H10: {=SUMPRODUCT(('LE - PY data'!$A$2:$A$10000='LE1a PY'!$C$4)*('LE - PY data'!$B$2:$B$10000='LE1a PY'!$D$4)*('LE - PY data'!$C$2:$C$10000='LE1a PY'!$E$4)*('LE - PY data'!$E$2:$E$10000='LE1a PY'!H$7)*('LE - PY data'!$F$2:$F$10000='LE1a PY'!$A10)*('LE - PY data'!$G$2:$G$10000))} -> 0 | I10: {=SUMPRODUCT(('LE - PY data'!$A$2:$A$10000='LE1a PY'!$C$4)*('LE - PY data'!$B$2:$B$10000='LE1a PY'!$D$4)*('LE - PY data'!$C$2:$C$10000='LE1a PY'!$E$4)*('LE - PY data'!$F$2:$F$10000='LE1a PY'!$A10)*('LE - PY data'!$G$2:$G$10000))} -> 0
A11: 2a. Resignation - to take up alternative employment | B11: {=SUMPRODUCT(('LE - PY data'!$A$2:$A$10000='LE1a PY'!$C$4)*('LE - PY data'!$B$2:$B$10000='LE1a PY'!$D$4)*('LE - PY data'!$C$2:$C$10000='LE1a PY'!$E$4)*('LE - PY data'!$E$2:$E$10000='LE1a PY'!B$7)*('LE - PY data'!$F$2:$F$10000='LE1a PY'!$A11)*('LE - PY data'!$G$2:$G$10000))} -> 0 | C11: {=SUMPRODUCT(('LE - PY data'!$A$2:$A$10000='LE1a PY'!$C$4)*('LE - PY data'!$B$2:$B$10000='LE1a PY'!$D$4)*('LE - PY data'!$C$2:$C$10000='LE1a PY'!$E$4)*('LE - PY data'!$E$2:$E$10000='LE1a PY'!C$7)*('LE - PY data'!$F$2:$F$10000='LE1a PY'!$A11)*('LE - PY data'!$G$2:$G$10000))} -> 0 | D11: {=SUMPRODUCT(('LE - PY data'!$A$2:$A$10000='LE1a PY'!$C$4)*('LE - PY data'!$B$2:$B$10000='LE1a PY'!$D$4)*('LE - PY data'!$C$2:$C$10000='LE1a PY'!$E$4)*('LE - PY data'!$E$2:$E$10000='LE1a PY'!D$7)*('LE - PY data'!$F$2:$F$10000='LE1a PY'!$A11)*('LE - PY data'!$G$2:$G$10000))} -> 0 | E11: {=SUMPRODUCT(('LE - PY data'!$A$2:$A$10000='LE1a PY'!$C$4)*('LE - PY data'!$B$2:$B$10000='LE1a PY'!$D$4)*('LE - PY data'!$C$2:$C$10000='LE1a PY'!$E$4)*('LE - PY data'!$E$2:$E$10000='LE1a PY'!E$7)*('LE - PY data'!$F$2:$F$10000='LE1a PY'!$A11)*('LE - PY data'!$G$2:$G$10000))} -> 0 | F11: {=SUMPRODUCT(('LE - PY data'!$A$2:$A$10000='LE1a PY'!$C$4)*('LE - PY data'!$B$2:$B$10000='LE1a PY'!$D$4)*('LE - PY data'!$C$2:$C$10000='LE1a PY'!$E$4)*('LE - PY data'!$E$2:$E$10000='LE1a PY'!F$7)*('LE - PY data'!$F$2:$F$10000='LE1a PY'!$A11)*('LE - PY data'!$G$2:$G$10000))} -> 0 | G11: {=SUMPRODUCT(('LE - PY data'!$A$2:$A$10000='LE1a PY'!$C$4)*('LE - PY data'!$B$2:$B$10000='LE1a PY'!$D$4)*('LE - PY data'!$C$2:$C$10000='LE1a PY'!$E$4)*('LE - PY data'!$E$2:$E$10000='LE1a PY'!G$7)*('LE - PY data'!$F$2:$F$10000='LE1a PY'!$A11)*('LE - PY data'!$G$2:$G$10000))} -> 0 | H11: {=SUMPRODUCT(('LE - PY data'!$A$2:$A$10000='LE1a PY'!$C$4)*('LE - PY data'!$B$2:$B$10000='LE1a PY'!$D$4)*('LE - PY data'!$C$2:$C$10000='LE1a PY'!$E$4)*('LE - PY data'!$E$2:$E$10000='LE1a PY'!H$7)*('LE - PY data'!$F$2:$F$10000='LE1a PY'!$A11)*('LE - PY data'!$G$2:$G$10000))} -> 0 | I11: {=SUMPRODUCT(('LE - PY data'!$A$2:$A$10000='LE1a PY'!$C$4)*('LE - PY data'!$B$2:$B$10000='LE1a PY'!$D$4)*('LE - PY data'!$C$2:$C$10000='LE1a PY'!$E$4)*('LE - PY data'!$F$2:$F$10000='LE1a PY'!$A11)*('LE - PY data'!$G$2:$G$10000))} -> 0
A12: 2b. Resignation - due to ill health | B12: {=SUMPRODUCT(('LE - PY data'!$A$2:$A$10000='LE1a PY'!$C$4)*('LE - PY data'!$B$2:$B$10000='LE1a PY'!$D$4)*('LE - PY data'!$C$2:$C$10000='LE1a PY'!$E$4)*('LE - PY data'!$E$2:$E$10000='LE1a PY'!B$7)*('LE - PY data'!$F$2:$F$10000='LE1a PY'!$A12)*('LE - PY data'!$G$2:$G$10000))} -> 0 | C12: {=SUMPRODUCT(('LE - PY data'!$A$2:$A$10000='LE1a PY'!$C$4)*('LE - PY data'!$B$2:$B$10000='LE1a PY'!$D$4)*('LE - PY data'!$C$2:$C$10000='LE1a PY'!$E$4)*('LE - PY data'!$E$2:$E$10000='LE1a PY'!C$7)*('LE - PY data'!$F$2:$F$10000='LE1a PY'!$A12)*('LE - PY data'!$G$2:$G$10000))} -> 0 | D12: {=SUMPRODUCT(('LE - PY data'!$A$2:$A$10000='LE1a PY'!$C$4)*('LE - PY data'!$B$2:$B$10000='LE1a PY'!$D$4)*('LE - PY data'!$C$2:$C$10000='LE1a PY'!$E$4)*('LE - PY data'!$E$2:$E$10000='LE1a PY'!D$7)*('LE - PY data'!$F$2:$F$10000='LE1a PY'!$A12)*('LE - PY data'!$G$2:$G$10000))} -> 0 | E12: {=SUMPRODUCT(('LE - PY data'!$A$2:$A$10000='LE1a PY'!$C$4)*('LE - PY data'!$B$2:$B$10000='LE1a PY'!$D$4)*('LE - PY data'!$C$2:$C$10000='LE1a PY'!$E$4)*('LE - PY data'!$E$2:$E$10000='LE1a PY'!E$7)*('LE - PY data'!$F$2:$F$10000='LE1a PY'!$A12)*('LE - PY data'!$G$2:$G$10000))} -> 0 | F12: {=SUMPRODUCT(('LE - PY data'!$A$2:$A$10000='LE1a PY'!$C$4)*('LE - PY data'!$B$2:$B$10000='LE1a PY'!$D$4)*('LE - PY data'!$C$2:$C$10000='LE1a PY'!$E$4)*('LE - PY data'!$E$2:$E$10000='LE1a PY'!F$7)*('LE - PY data'!$F$2:$F$10000='LE1a PY'!$A12)*('LE - PY data'!$G$2:$G$10000))} -> 0 | G12: {=SUMPRODUCT(('LE - PY data'!$A$2:$A$10000='LE1a PY'!$C$4)*('LE - PY data'!$B$2:$B$10000='LE1a PY'!$D$4)*('LE - PY data'!$C$2:$C$10000='LE1a PY'!$E$4)*('LE - PY data'!$E$2:$E$10000='LE1a PY'!G$7)*('LE - PY data'!$F$2:$F$10000='LE1a PY'!$A12)*('LE - PY data'!$G$2:$G$10000))} -> 0 | H12: {=SUMPRODUCT(('LE - PY data'!$A$2:$A$10000='LE1a PY'!$C$4)*('LE - PY data'!$B$2:$B$10000='LE1a PY'!$D$4)*('LE - PY data'!$C$2:$C$10000='LE1a PY'!$E$4)*('LE - PY data'!$E$2:$E$10000='LE1a PY'!H$7)*('LE - PY data'!$F$2:$F$10000='LE1a PY'!$A12)*('LE - PY data'!$G$2:$G$10000))} -> 0 | I12: {=SUMPRODUCT(('LE - PY data'!$A$2:$A$10000='LE1a PY'!$C$4)*('LE - PY data'!$B$2:$B$10000='LE1a PY'!$D$4)*('LE - PY data'!$C$2:$C$10000='LE1a PY'!$E$4)*('LE - PY data'!$F$2:$F$10000='LE1a PY'!$A12)*('LE - PY data'!$G$2:$G$10000))} -> 0
A13: 2c. Resignation - any other reason (please specify) | B13: {=SUMPRODUCT(('LE - PY data'!$A$2:$A$10000='LE1a PY'!$C$4)*('LE - PY data'!$B$2:$B$10000='LE1a PY'!$D$4)*('LE - PY data'!$C$2:$C$10000='LE1a PY'!$E$4)*('LE - PY data'!$E$2:$E$10000='LE1a PY'!B$7)*('LE - PY data'!$F$2:$F$10000='LE1a PY'!$A13)*('LE - PY data'!$G$2:$G$10000))} -> 0 | C13: {=SUMPRODUCT(('LE - PY data'!$A$2:$A$10000='LE1a PY'!$C$4)*('LE - PY data'!$B$2:$B$10000='LE1a PY'!$D$4)*('LE - PY data'!$C$2:$C$10000='LE1a PY'!$E$4)*('LE - PY data'!$E$2:$E$10000='LE1a PY'!C$7)*('LE - PY data'!$F$2:$F$10000='LE1a PY'!$A13)*('LE - PY data'!$G$2:$G$10000))} -> 0 | D13: {=SUMPRODUCT(('LE - PY data'!$A$2:$A$10000='LE1a PY'!$C$4)*('LE - PY data'!$B$2:$B$10000='LE1a PY'!$D$4)*('LE - PY data'!$C$2:$C$10000='LE1a PY'!$E$4)*('LE - PY data'!$E$2:$E$10000='LE1a PY'!D$7)*('LE - PY data'!$F$2:$F$10000='LE1a PY'!$A13)*('LE - PY data'!$G$2:$G$10000))} -> 0 | E13: {=SUMPRODUCT(('LE - PY data'!$A$2:$A$10000='LE1a PY'!$C$4)*('LE - PY data'!$B$2:$B$10000='LE1a PY'!$D$4)*('LE - PY data'!$C$2:$C$10000='LE1a PY'!$E$4)*('LE - PY data'!$E$2:$E$10000='LE1a PY'!E$7)*('LE - PY data'!$F$2:$F$10000='LE1a PY'!$A13)*('LE - PY data'!$G$2:$G$10000))} -> 0 | F13: {=SUMPRODUCT(('LE - PY data'!$A$2:$A$10000='LE1a PY'!$C$4)*('LE - PY data'!$B$2:$B$10000='LE1a PY'!$D$4)*('LE - PY data'!$C$2:$C$10000='LE1a PY'!$E$4)*('LE - PY data'!$E$2:$E$10000='LE1a PY'!F$7)*('LE - PY data'!$F$2:$F$10000='LE1a PY'!$A13)*('LE - PY data'!$G$2:$G$10000))} -> 0 | G13: {=SUMPRODUCT(('LE - PY data'!$A$2:$A$10000='LE1a PY'!$C$4)*('LE - PY data'!$B$2:$B$10000='LE1a PY'!$D$4)*('LE - PY data'!$C$2:$C$10000='LE1a PY'!$E$4)*('LE - PY data'!$E$2:$E$10000='LE1a PY'!G$7)*('LE - PY data'!$F$2:$F$10000='LE1a PY'!$A13)*('LE - PY data'!$G$2:$G$10000))} -> 0 | H13: {=SUMPRODUCT(('LE - PY data'!$A$2:$A$10000='LE1a PY'!$C$4)*('LE - PY data'!$B$2:$B$10000='LE1a PY'!$D$4)*('LE - PY data'!$C$2:$C$10000='LE1a PY'!$E$4)*('LE - PY data'!$E$2:$E$10000='LE1a PY'!H$7)*('LE - PY data'!$F$2:$F$10000='LE1a PY'!$A13)*('LE - PY data'!$G$2:$G$10000))} -> 0 | I13: {=SUMPRODUCT(('LE - PY data'!$A$2:$A$10000='LE1a PY'!$C$4)*('LE - PY data'!$B$2:$B$10000='LE1a PY'!$D$4)*('LE - PY data'!$C$2:$C$10000='LE1a PY'!$E$4)*('LE - PY data'!$F$2:$F$10000='LE1a PY'!$A13)*('LE - PY data'!$G$2:$G$10000))} -> 0
A14: 2. Total resignation | B14: {=SUMPRODUCT(('LE - PY data'!$A$2:$A$10000='LE1a PY'!$C$4)*('LE - PY data'!$B$2:$B$10000='LE1a PY'!$D$4)*('LE - PY data'!$C$2:$C$10000='LE1a PY'!$E$4)*('LE - PY data'!$E$2:$E$10000='LE1a PY'!B$7)*('LE - PY data'!$F$2:$F$10000='LE1a PY'!$A14)*('LE - PY data'!$G$2:$G$10000))} -> 0 | C14: {=SUMPRODUCT(('LE - PY data'!$A$2:$A$10000='LE1a PY'!$C$4)*('LE - PY data'!$B$2:$B$10000='LE1a PY'!$D$4)*('LE - PY data'!$C$2:$C$10000='LE1a PY'!$E$4)*('LE - PY data'!$E$2:$E$10000='LE1a PY'!C$7)*('LE - PY data'!$F$2:$F$10000='LE1a PY'!$A14)*('LE - PY data'!$G$2:$G$10000))} -> 0 | D14: {=SUMPRODUCT(('LE - PY data'!$A$2:$A$10000='LE1a PY'!$C$4)*('LE - PY data'!$B$2:$B$10000='LE1a PY'!$D$4)*('LE - PY data'!$C$2:$C$10000='LE1a PY'!$E$4)*('LE - PY data'!$E$2:$E$10000='LE1a PY'!D$7)*('LE - PY data'!$F$2:$F$10000='LE1a PY'!$A14)*('LE - PY data'!$G$2:$G$10000))} -> 0 | E14: {=SUMPRODUCT(('LE - PY data'!$A$2:$A$10000='LE1a PY'!$C$4)*('LE - PY data'!$B$2:$B$10000='LE1a PY'!$D$4)*('LE - PY data'!$C$2:$C$10000='LE1a PY'!$E$4)*('LE - PY data'!$E$2:$E$10000='LE1a PY'!E$7)*('LE - PY data'!$F$2:$F$10000='LE1a PY'!$A14)*('LE - PY data'!$G$2:$G$10000))} -> 0 | F14: {=SUMPRODUCT(('LE - PY data'!$A$2:$A$10000='LE1a PY'!$C$4)*('LE - PY data'!$B$2:$B$10000='LE1a PY'!$D$4)*('LE - PY data'!$C$2:$C$10000='LE1a PY'!$E$4)*('LE - PY data'!$E$2:$E$10000='LE1a PY'!F$7)*('LE - PY data'!$F$2:$F$10000='LE1a PY'!$A14)*('LE - PY data'!$G$2:$G$10000))} -> 0 | G14: {=SUMPRODUCT(('LE - PY data'!$A$2:$A$10000='LE1a PY'!$C$4)*('LE - PY data'!$B$2:$B$10000='LE1a PY'!$D$4)*('LE - PY data'!$C$2:$C$10000='LE1a PY'!$E$4)*('LE - PY data'!$E$2:$E$10000='LE1a PY'!G$7)*('LE - PY data'!$F$2:$F$10000='LE1a PY'!$A14)*('LE - PY data'!$G$2:$G$10000))} -> 0 | H14: {=SUMPRODUCT(('LE - PY data'!$A$2:$A$10000='LE1a PY'!$C$4)*('LE - PY data'!$B$2:$B$10000='LE1a PY'!$D$4)*('LE - PY data'!$C$2:$C$10000='LE1a PY'!$E$4)*('LE - PY data'!$E$2:$E$10000='LE1a PY'!H$7)*('LE - PY data'!$F$2:$F$10000='LE1a PY'!$A14)*('LE - PY data'!$G$2:$G$10000))} -> 0 | I14: {=SUMPRODUCT(('LE - PY data'!$A$2:$A$10000='LE1a PY'!$C$4)*('LE - PY data'!$B$2:$B$10000='LE1a PY'!$D$4)*('LE - PY data'!$C$2:$C$10000='LE1a PY'!$E$4)*('LE - PY data'!$F$2:$F$10000='LE1a PY'!$A14)*('LE - PY data'!$G$2:$G$10000))} -> 0
A15: 3a. Redundancy - compulsory | B15: {=SUMPRODUCT(('LE - PY data'!$A$2:$A$10000='LE1a PY'!$C$4)*('LE - PY data'!$B$2:$B$10000='LE1a PY'!$D$4)*('LE - PY data'!$C$2:$C$10000='LE1a PY'!$E$4)*('LE - PY data'!$E$2:$E$10000='LE1a PY'!B$7)*('LE - PY data'!$F$2:$F$10000='LE1a PY'!$A15)*('LE - PY data'!$G$2:$G$10000))} -> 0 | C15: {=SUMPRODUCT(('LE - PY data'!$A$2:$A$10000='LE1a PY'!$C$4)*('LE - PY data'!$B$2:$B$10000='LE1a PY'!$D$4)*('LE - PY data'!$C$2:$C$10000='LE1a PY'!$E$4)*('LE - PY data'!$E$2:$E$10000='LE1a PY'!C$7)*('LE - PY data'!$F$2:$F$10000='LE1a PY'!$A15)*('LE - PY data'!$G$2:$G$10000))} -> 0 | D15: {=SUMPRODUCT(('LE - PY data'!$A$2:$A$10000='LE1a PY'!$C$4)*('LE - PY data'!$B$2:$B$10000='LE1a PY'!$D$4)*('LE - PY data'!$C$2:$C$10000='LE1a PY'!$E$4)*('LE - PY data'!$E$2:$E$10000='LE1a PY'!D$7)*('LE - PY data'!$F$2:$F$10000='LE1a PY'!$A15)*('LE - PY data'!$G$2:$G$10000))} -> 0 | E15: {=SUMPRODUCT(('LE - PY data'!$A$2:$A$10000='LE1a PY'!$C$4)*('LE - PY data'!$B$2:$B$10000='LE1a PY'!$D$4)*('LE - PY data'!$C$2:$C$10000='LE1a PY'!$E$4)*('LE - PY data'!$E$2:$E$10000='LE1a PY'!E$7)*('LE - PY data'!$F$2:$F$10000='LE1a PY'!$A15)*('LE - PY data'!$G$2:$G$10000))} -> 0 | F15: {=SUMPRODUCT(('LE - PY data'!$A$2:$A$10000='LE1a PY'!$C$4)*('LE - PY data'!$B$2:$B$10000='LE1a PY'!$D$4)*('LE - PY data'!$C$2:$C$10000='LE1a PY'!$E$4)*('LE - PY data'!$E$2:$E$10000='LE1a PY'!F$7)*('LE - PY data'!$F$2:$F$10000='LE1a PY'!$A15)*('LE - PY data'!$G$2:$G$10000))} -> 0 | G15: {=SUMPRODUCT(('LE - PY data'!$A$2:$A$10000='LE1a PY'!$C$4)*('LE - PY data'!$B$2:$B$10000='LE1a PY'!$D$4)*('LE - PY data'!$C$2:$C$10000='LE1a PY'!$E$4)*('LE - PY data'!$E$2:$E$10000='LE1a PY'!G$7)*('LE - PY data'!$F$2:$F$10000='LE1a PY'!$A15)*('LE - PY data'!$G$2:$G$10000))} -> 0 | H15: {=SUMPRODUCT(('LE - PY data'!$A$2:$A$10000='LE1a PY'!$C$4)*('LE - PY data'!$B$2:$B$10000='LE1a PY'!$D$4)*('LE - PY data'!$C$2:$C$10000='LE1a PY'!$E$4)*('LE - PY data'!$E$2:$E$10000='LE1a PY'!H$7)*('LE - PY data'!$F$2:$F$10000='LE1a PY'!$A15)*('LE - PY data'!$G$2:$G$10000))} -> 0 | I15: {=SUMPRODUCT(('LE - PY data'!$A$2:$A$10000='LE1a PY'!$C$4)*('LE - PY data'!$B$2:$B$10000='LE1a PY'!$D$4)*('LE - PY data'!$C$2:$C$10000='LE1a PY'!$E$4)*('LE - PY data'!$F$2:$F$10000='LE1a PY'!$A15)*('LE - PY data'!$G$2:$G$10000))} -> 0
A16: 3b. Redundancy - voluntary | B16: {=SUMPRODUCT(('LE - PY data'!$A$2:$A$10000='LE1a PY'!$C$4)*('LE - PY data'!$B$2:$B$10000='LE1a PY'!$D$4)*('LE - PY data'!$C$2:$C$10000='LE1a PY'!$E$4)*('LE - PY data'!$E$2:$E$10000='LE1a PY'!B$7)*('LE - PY data'!$F$2:$F$10000='LE1a PY'!$A16)*('LE - PY data'!$G$2:$G$10000))} -> 0 | C16: {=SUMPRODUCT(('LE - PY data'!$A$2:$A$10000='LE1a PY'!$C$4)*('LE - PY data'!$B$2:$B$10000='LE1a PY'!$D$4)*('LE - PY data'!$C$2:$C$10000='LE1a PY'!$E$4)*('LE - PY data'!$E$2:$E$10000='LE1a PY'!C$7)*('LE - PY data'!$F$2:$F$10000='LE1a PY'!$A16)*('LE - PY data'!$G$2:$G$10000))} -> 0 | D16: {=SUMPRODUCT(('LE - PY data'!$A$2:$A$10000='LE1a PY'!$C$4)*('LE - PY data'!$B$2:$B$10000='LE1a PY'!$D$4)*('LE - PY data'!$C$2:$C$10000='LE1a PY'!$E$4)*('LE - PY data'!$E$2:$E$10000='LE1a PY'!D$7)*('LE - PY data'!$F$2:$F$10000='LE1a PY'!$A16)*('LE - PY data'!$G$2:$G$10000))} -> 0 | E16: {=SUMPRODUCT(('LE - PY data'!$A$2:$A$10000='LE1a PY'!$C$4)*('LE - PY data'!$B$2:$B$10000='LE1a PY'!$D$4)*('LE - PY data'!$C$2:$C$10000='LE1a PY'!$E$4)*('LE - PY data'!$E$2:$E$10000='LE1a PY'!E$7)*('LE - PY data'!$F$2:$F$10000='LE1a PY'!$A16)*('LE - PY data'!$G$2:$G$10000))} -> 0 | F16: {=SUMPRODUCT(('LE - PY data'!$A$2:$A$10000='LE1a PY'!$C$4)*('LE - PY data'!$B$2:$B$10000='LE1a PY'!$D$4)*('LE - PY data'!$C$2:$C$10000='LE1a PY'!$E$4)*('LE - PY data'!$E$2:$E$10000='LE1a PY'!F$7)*('LE - PY data'!$F$2:$F$10000='LE1a PY'!$A16)*('LE - PY data'!$G$2:$G$10000))} -> 0 | G16: {=SUMPRODUCT(('LE - PY data'!$A$2:$A$10000='LE1a PY'!$C$4)*('LE - PY data'!$B$2:$B$10000='LE1a PY'!$D$4)*('LE - PY data'!$C$2:$C$10000='LE1a PY'!$E$4)*('LE - PY data'!$E$2:$E$10000='LE1a PY'!G$7)*('LE - PY data'!$F$2:$F$10000='LE1a PY'!$A16)*('LE - PY data'!$G$2:$G$10000))} -> 0 | H16: {=SUMPRODUCT(('LE - PY data'!$A$2:$A$10000='LE1a PY'!$C$4)*('LE - PY data'!$B$2:$B$10000='LE1a PY'!$D$4)*('LE - PY data'!$C$2:$C$10000='LE1a PY'!$E$4)*('LE - PY data'!$E$2:$E$10000='LE1a PY'!H$7)*('LE - PY data'!$F$2:$F$10000='LE1a PY'!$A16)*('LE - PY data'!$G$2:$G$10000))} -> 0 | I16: {=SUMPRODUCT(('LE - PY data'!$A$2:$A$10000='LE1a PY'!$C$4)*('LE - PY data'!$B$2:$B$10000='LE1a PY'!$D$4)*('LE - PY data'!$C$2:$C$10000='LE1a PY'!$E$4)*('LE - PY data'!$F$2:$F$10000='LE1a PY'!$A16)*('LE - PY data'!$G$2:$G$10000))} -> 0
A17: 3. Total redundancy | B17: {=SUMPRODUCT(('LE - PY data'!$A$2:$A$10000='LE1a PY'!$C$4)*('LE - PY data'!$B$2:$B$10000='LE1a PY'!$D$4)*('LE - PY data'!$C$2:$C$10000='LE1a PY'!$E$4)*('LE - PY data'!$E$2:$E$10000='LE1a PY'!B$7)*('LE - PY data'!$F$2:$F$10000='LE1a PY'!$A17)*('LE - PY data'!$G$2:$G$10000))} -> 0 | C17: {=SUMPRODUCT(('LE - PY data'!$A$2:$A$10000='LE1a PY'!$C$4)*('LE - PY data'!$B$2:$B$10000='LE1a PY'!$D$4)*('LE - PY data'!$C$2:$C$10000='LE1a PY'!$E$4)*('LE - PY data'!$E$2:$E$10000='LE1a PY'!C$7)*('LE - PY data'!$F$2:$F$10000='LE1a PY'!$A17)*('LE - PY data'!$G$2:$G$10000))} -> 0 | D17: {=SUMPRODUCT(('LE - PY data'!$A$2:$A$10000='LE1a PY'!$C$4)*('LE - PY data'!$B$2:$B$10000='LE1a PY'!$D$4)*('LE - PY data'!$C$2:$C$10000='LE1a PY'!$E$4)*('LE - PY data'!$E$2:$E$10000='LE1a PY'!D$7)*('LE - PY data'!$F$2:$F$10000='LE1a PY'!$A17)*('LE - PY data'!$G$2:$G$10000))} -> 0 | E17: {=SUMPRODUCT(('LE - PY data'!$A$2:$A$10000='LE1a PY'!$C$4)*('LE - PY data'!$B$2:$B$10000='LE1a PY'!$D$4)*('LE - PY data'!$C$2:$C$10000='LE1a PY'!$E$4)*('LE - PY data'!$E$2:$E$10000='LE1a PY'!E$7)*('LE - PY data'!$F$2:$F$10000='LE1a PY'!$A17)*('LE - PY data'!$G$2:$G$10000))} -> 0 | F17: {=SUMPRODUCT(('LE - PY data'!$A$2:$A$10000='LE1a PY'!$C$4)*('LE - PY data'!$B$2:$B$10000='LE1a PY'!$D$4)*('LE - PY data'!$C$2:$C$10000='LE1a PY'!$E$4)*('LE - PY data'!$E$2:$E$10000='LE1a PY'!F$7)*('LE - PY data'!$F$2:$F$10000='LE1a PY'!$A17)*('LE - PY data'!$G$2:$G$10000))} -> 0 | G17: {=SUMPRODUCT(('LE - PY data'!$A$2:$A$10000='LE1a PY'!$C$4)*('LE - PY data'!$B$2:$B$10000='LE1a PY'!$D$4)*('LE - PY data'!$C$2:$C$10000='LE1a PY'!$E$4)*('LE - PY data'!$E$2:$E$10000='LE1a PY'!G$7)*('LE - PY data'!$F$2:$F$10000='LE1a PY'!$A17)*('LE - PY data'!$G$2:$G$10000))} -> 0 | H17: {=SUMPRODUCT(('LE - PY data'!$A$2:$A$10000='LE1a PY'!$C$4)*('LE - PY data'!$B$2:$B$10000='LE1a PY'!$D$4)*('LE - PY data'!$C$2:$C$10000='LE1a PY'!$E$4)*('LE - PY data'!$E$2:$E$10000='LE1a PY'!H$7)*('LE - PY data'!$F$2:$F$10000='LE1a PY'!$A17)*('LE - PY data'!$G$2:$G$10000))} -> 0 | I17: {=SUMPRODUCT(('LE - PY data'!$A$2:$A$10000='LE1a PY'!$C$4)*('LE - PY data'!$B$2:$B$10000='LE1a PY'!$D$4)*('LE - PY data'!$C$2:$C$10000='LE1a PY'!$E$4)*('LE - PY data'!$F$2:$F$10000='LE1a PY'!$A17)*('LE - PY data'!$G$2:$G$10000))} -> 0
A18: 4a. Retirement - early | B18: {=SUMPRODUCT(('LE - PY data'!$A$2:$A$10000='LE1a PY'!$C$4)*('LE - PY data'!$B$2:$B$10000='LE1a PY'!$D$4)*('LE - PY data'!$C$2:$C$10000='LE1a PY'!$E$4)*('LE - PY data'!$E$2:$E$10000='LE1a PY'!B$7)*('LE - PY data'!$F$2:$F$10000='LE1a PY'!$A18)*('LE - PY data'!$G$2:$G$10000))} -> 0 | C18: {=SUMPRODUCT(('LE - PY data'!$A$2:$A$10000='LE1a PY'!$C$4)*('LE - PY data'!$B$2:$B$10000='LE1a PY'!$D$4)*('LE - PY data'!$C$2:$C$10000='LE1a PY'!$E$4)*('LE - PY data'!$E$2:$E$10000='LE1a PY'!C$7)*('LE - PY data'!$F$2:$F$10000='LE1a PY'!$A18)*('LE - PY data'!$G$2:$G$10000))} -> 0 | D18: {=SUMPRODUCT(('LE - PY data'!$A$2:$A$10000='LE1a PY'!$C$4)*('LE - PY data'!$B$2:$B$10000='LE1a PY'!$D$4)*('LE - PY data'!$C$2:$C$10000='LE1a PY'!$E$4)*('LE - PY data'!$E$2:$E$10000='LE1a PY'!D$7)*('LE - PY data'!$F$2:$F$10000='LE1a PY'!$A18)*('LE - PY data'!$G$2:$G$10000))} -> 0 | E18: {=SUMPRODUCT(('LE - PY data'!$A$2:$A$10000='LE1a PY'!$C$4)*('LE - PY data'!$B$2:$B$10000='LE1a PY'!$D$4)*('LE - PY data'!$C$2:$C$10000='LE1a PY'!$E$4)*('LE - PY data'!$E$2:$E$10000='LE1a PY'!E$7)*('LE - PY data'!$F$2:$F$10000='LE1a PY'!$A18)*('LE - PY data'!$G$2:$G$10000))} -> 0 | F18: {=SUMPRODUCT(('LE - PY data'!$A$2:$A$10000='LE1a PY'!$C$4)*('LE - PY data'!$B$2:$B$10000='LE1a PY'!$D$4)*('LE - PY data'!$C$2:$C$10000='LE1a PY'!$E$4)*('LE - PY data'!$E$2:$E$10000='LE1a PY'!F$7)*('LE - PY data'!$F$2:$F$10000='LE1a PY'!$A18)*('LE - PY data'!$G$2:$G$10000))} -> 0 | G18: {=SUMPRODUCT(('LE - PY data'!$A$2:$A$10000='LE1a PY'!$C$4)*('LE - PY data'!$B$2:$B$10000='LE1a PY'!$D$4)*('LE - PY data'!$C$2:$C$10000='LE1a PY'!$E$4)*('LE - PY data'!$E$2:$E$10000='LE1a PY'!G$7)*('LE - PY data'!$F$2:$F$10000='LE1a PY'!$A18)*('LE - PY data'!$G$2:$G$10000))} -> 0 | H18: {=SUMPRODUCT(('LE - PY data'!$A$2:$A$10000='LE1a PY'!$C$4)*('LE - PY data'!$B$2:$B$10000='LE1a PY'!$D$4)*('LE - PY data'!$C$2:$C$10000='LE1a PY'!$E$4)*('LE - PY data'!$E$2:$E$10000='LE1a PY'!H$7)*('LE - PY data'!$F$2:$F$10000='LE1a PY'!$A18)*('LE - PY data'!$G$2:$G$10000))} -> 0 | I18: {=SUMPRODUCT(('LE - PY data'!$A$2:$A$10000='LE1a PY'!$C$4)*('LE - PY data'!$B$2:$B$10000='LE1a PY'!$D$4)*('LE - PY data'!$C$2:$C$10000='LE1a PY'!$E$4)*('LE - PY data'!$F$2:$F$10000='LE1a PY'!$A18)*('LE - PY data'!$G$2:$G$10000))} -> 0
A19: 4b. Retirement - normal | B19: {=SUMPRODUCT(('LE - PY data'!$A$2:$A$10000='LE1a PY'!$C$4)*('LE - PY data'!$B$2:$B$10000='LE1a PY'!$D$4)*('LE - PY data'!$C$2:$C$10000='LE1a PY'!$E$4)*('LE - PY data'!$E$2:$E$10000='LE1a PY'!B$7)*('LE - PY data'!$F$2:$F$10000='LE1a PY'!$A19)*('LE - PY data'!$G$2:$G$10000))} -> 0 | C19: {=SUMPRODUCT(('LE - PY data'!$A$2:$A$10000='LE1a PY'!$C$4)*('LE - PY data'!$B$2:$B$10000='LE1a PY'!$D$4)*('LE - PY data'!$C$2:$C$10000='LE1a PY'!$E$4)*('LE - PY data'!$E$2:$E$10000='LE1a PY'!C$7)*('LE - PY data'!$F$2:$F$10000='LE1a PY'!$A19)*('LE - PY data'!$G$2:$G$10000))} -> 0 | D19: {=SUMPRODUCT(('LE - PY data'!$A$2:$A$10000='LE1a PY'!$C$4)*('LE - PY data'!$B$2:$B$10000='LE1a PY'!$D$4)*('LE - PY data'!$C$2:$C$10000='LE1a PY'!$E$4)*('LE - PY data'!$E$2:$E$10000='LE1a PY'!D$7)*('LE - PY data'!$F$2:$F$10000='LE1a PY'!$A19)*('LE - PY data'!$G$2:$G$10000))} -> 0 | E19: {=SUMPRODUCT(('LE - PY data'!$A$2:$A$10000='LE1a PY'!$C$4)*('LE - PY data'!$B$2:$B$10000='LE1a PY'!$D$4)*('LE - PY data'!$C$2:$C$10000='LE1a PY'!$E$4)*('LE - PY data'!$E$2:$E$10000='LE1a PY'!E$7)*('LE - PY data'!$F$2:$F$10000='LE1a PY'!$A19)*('LE - PY data'!$G$2:$G$10000))} -> 0 | F19: {=SUMPRODUCT(('LE - PY data'!$A$2:$A$10000='LE1a PY'!$C$4)*('LE - PY data'!$B$2:$B$10000='LE1a PY'!$D$4)*('LE - PY data'!$C$2:$C$10000='LE1a PY'!$E$4)*('LE - PY data'!$E$2:$E$10000='LE1a PY'!F$7)*('LE - PY data'!$F$2:$F$10000='LE1a PY'!$A19)*('LE - PY data'!$G$2:$G$10000))} -> 0 | G19: {=SUMPRODUCT(('LE - PY data'!$A$2:$A$10000='LE1a PY'!$C$4)*('LE - PY data'!$B$2:$B$10000='LE1a PY'!$D$4)*('LE - PY data'!$C$2:$C$10000='LE1a PY'!$E$4)*('LE - PY data'!$E$2:$E$10000='LE1a PY'!G$7)*('LE - PY data'!$F$2:$F$10000='LE1a PY'!$A19)*('LE - PY data'!$G$2:$G$10000))} -> 0 | H19: {=SUMPRODUCT(('LE - PY data'!$A$2:$A$10000='LE1a PY'!$C$4)*('LE - PY data'!$B$2:$B$10000='LE1a PY'!$D$4)*('LE - PY data'!$C$2:$C$10000='LE1a PY'!$E$4)*('LE - PY data'!$E$2:$E$10000='LE1a PY'!H$7)*('LE - PY data'!$F$2:$F$10000='LE1a PY'!$A19)*('LE - PY data'!$G$2:$G$10000))} -> 0 | I19: {=SUMPRODUCT(('LE - PY data'!$A$2:$A$10000='LE1a PY'!$C$4)*('LE - PY data'!$B$2:$B$10000='LE1a PY'!$D$4)*('LE - PY data'!$C$2:$C$10000='LE1a PY'!$E$4)*('LE - PY data'!$F$2:$F$10000='LE1a PY'!$A19)*('LE - PY data'!$G$2:$G$10000))} -> 0
... A26: 8. Unknown / Reason for leaving not recorded | B26: {=SUMPRODUCT(('LE - PY data'!$A$2:$A$10000='LE1a PY'!$C$4)*('LE - PY data'!$B$2:$B$10000='LE1a PY'!$D$4)*('LE - PY data'!$C$2:$C$10000='LE1a PY'!$E$4)*('LE - PY data'!$E$2:$E$10000='LE1a PY'!B$7)*('LE - PY data'!$F$2:$F$10000='LE1a PY'!$A26)*('LE - PY data'!$G$2:$G$10000))} -> 0 | C26: {=SUMPRODUCT(('LE - PY data'!$A$2:$A$10000='LE1a PY'!$C$4)*('LE - PY data'!$B$2:$B$10000='LE1a PY'!$D$4)*('LE - PY data'!$C$2:$C$10000='LE1a PY'!$E$4)*('LE - PY data'!$E$2:$E$10000='LE1a PY'!C$7)*('LE - PY data'!$F$2:$F$10000='LE1a PY'!$A26)*('LE - PY data'!$G$2:$G$10000))} -> 0 | D26: {=SUMPRODUCT(('LE - PY data'!$A$2:$A$10000='LE1a PY'!$C$4)*('LE - PY data'!$B$2:$B$10000='LE1a PY'!$D$4)*('LE - PY data'!$C$2:$C$10000='LE1a PY'!$E$4)*('LE - PY data'!$E$2:$E$10000='LE1a PY'!D$7)*('LE - PY data'!$F$2:$F$10000='LE1a PY'!$A26)*('LE - PY data'!$G$2:$G$10000))} -> 0 | E26: {=SUMPRODUCT(('LE - PY data'!$A$2:$A$10000='LE1a PY'!$C$4)*('LE - PY data'!$B$2:$B$10000='LE1a PY'!$D$4)*('LE - PY data'!$C$2:$C$10000='LE1a PY'!$E$4)*('LE - PY data'!$E$2:$E$10000='LE1a PY'!E$7)*('LE - PY data'!$F$2:$F$10000='LE1a PY'!$A26)*('LE - PY data'!$G$2:$G$10000))} -> 0 | F26: {=SUMPRODUCT(('LE - PY data'!$A$2:$A$10000='LE1a PY'!$C$4)*('LE - PY data'!$B$2:$B$10000='LE1a PY'!$D$4)*('LE - PY data'!$C$2:$C$10000='LE1a PY'!$E$4)*('LE - PY data'!$E$2:$E$10000='LE1a PY'!F$7)*('LE - PY data'!$F$2:$F$10000='LE1a PY'!$A26)*('LE - PY data'!$G$2:$G$10000))} -> 0 | G26: {=SUMPRODUCT(('LE - PY data'!$A$2:$A$10000='LE1a PY'!$C$4)*('LE - PY data'!$B$2:$B$10000='LE1a PY'!$D$4)*('LE - PY data'!$C$2:$C$10000='LE1a PY'!$E$4)*('LE - PY data'!$E$2:$E$10000='LE1a PY'!G$7)*('LE - PY data'!$F$2:$F$10000='LE1a PY'!$A26)*('LE - PY data'!$G$2:$G$10000))} -> 0 | H26: {=SUMPRODUCT(('LE - PY data'!$A$2:$A$10000='LE1a PY'!$C$4)*('LE - PY data'!$B$2:$B$10000='LE1a PY'!$D$4)*('LE - PY data'!$C$2:$C$10000='LE1a PY'!$E$4)*('LE - PY data'!$E$2:$E$10000='LE1a PY'!H$7)*('LE - PY data'!$F$2:$F$10000='LE1a PY'!$A26)*('LE - PY data'!$G$2:$G$10000))} -> 0 | I26: {=SUMPRODUCT(('LE - PY data'!$A$2:$A$10000='LE1a PY'!$C$4)*('LE - PY data'!$B$2:$B$10000='LE1a PY'!$D$4)*('LE - PY data'!$C$2:$C$10000='LE1a PY'!$E$4)*('LE - PY data'!$F$2:$F$10000='LE1a PY'!$A26)*('LE - PY data'!$G$2:$G$10000))} -> 0
A27: Total | B27: {=SUMPRODUCT(('LE - PY data'!$A$2:$A$10000='LE1a PY'!$C$4)*('LE - PY data'!$B$2:$B$10000='LE1a PY'!$D$4)*('LE - PY data'!$C$2:$C$10000='LE1a PY'!$E$4)*('LE - PY data'!$E$2:$E$10000='LE1a PY'!B$7)*('LE - PY data'!$G$2:$G$10000))} -> 0 | C27: {=SUMPRODUCT(('LE - PY data'!$A$2:$A$10000='LE1a PY'!$C$4)*('LE - PY data'!$B$2:$B$10000='LE1a PY'!$D$4)*('LE - PY data'!$C$2:$C$10000='LE1a PY'!$E$4)*('LE - PY data'!$E$2:$E$10000='LE1a PY'!C$7)*('LE - PY data'!$G$2:$G$10000))} -> 0 | D27: {=SUMPRODUCT(('LE - PY data'!$A$2:$A$10000='LE1a PY'!$C$4)*('LE - PY data'!$B$2:$B$10000='LE1a PY'!$D$4)*('LE - PY data'!$C$2:$C$10000='LE1a PY'!$E$4)*('LE - PY data'!$E$2:$E$10000='LE1a PY'!D$7)*('LE - PY data'!$G$2:$G$10000))} -> 0 | E27: {=SUMPRODUCT(('LE - PY data'!$A$2:$A$10000='LE1a PY'!$C$4)*('LE - PY data'!$B$2:$B$10000='LE1a PY'!$D$4)*('LE - PY data'!$C$2:$C$10000='LE1a PY'!$E$4)*('LE - PY data'!$E$2:$E$10000='LE1a PY'!E$7)*('LE - PY data'!$G$2:$G$10000))} -> 0 | F27: {=SUMPRODUCT(('LE - PY data'!$A$2:$A$10000='LE1a PY'!$C$4)*('LE - PY data'!$B$2:$B$10000='LE1a PY'!$D$4)*('LE - PY data'!$C$2:$C$10000='LE1a PY'!$E$4)*('LE - PY data'!$E$2:$E$10000='LE1a PY'!F$7)*('LE - PY data'!$G$2:$G$10000))} -> 0 | G27: {=SUMPRODUCT(('LE - PY data'!$A$2:$A$10000='LE1a PY'!$C$4)*('LE - PY data'!$B$2:$B$10000='LE1a PY'!$D$4)*('LE - PY data'!$C$2:$C$10000='LE1a PY'!$E$4)*('LE - PY data'!$E$2:$E$10000='LE1a PY'!G$7)*('LE - PY data'!$G$2:$G$10000))} -> 0 | H27: {=SUMPRODUCT(('LE - PY data'!$A$2:$A$10000='LE1a PY'!$C$4)*('LE - PY data'!$B$2:$B$10000='LE1a PY'!$D$4)*('LE - PY data'!$C$2:$C$10000='LE1a PY'!$E$4)*('LE - PY data'!$E$2:$E$10000='LE1a PY'!H$7)*('LE - PY data'!$G$2:$G$10000))} -> 0 | I27: {=SUMPRODUCT(('LE - PY data'!$A$2:$A$10000='LE1a PY'!$C$4)*('LE - PY data'!$B$2:$B$10000='LE1a PY'!$D$4)*('LE - PY data'!$C$2:$C$10000='LE1a PY'!$E$4)*('LE - PY data'!$G$2:$G$10000))} -> 0

Sheet LE1a
A5: LE1 Number of wholetime firefighters leaving (headcount)
B7: Brigade Manager | C7: Area Manager | D7: Group Manager | E7: Station Manager | F7: Watch Manager | G7: Crew Manager | H7: Firefighter | I7: Total
A8: 1a. Moving - to another FRS | I8: =SUM(B8:H8) -> 0
A9: 1b. Moving - within FRS from operational (firefighter or control) to support staff | I9: =SUM(B9:H9) -> 0
A10: 1. Total moving | B10: =SUM(B8:B9) -> 0 | C10: =SUM(C8:C9) -> 0 | D10: =SUM(D8:D9) -> 0 | E10: =SUM(E8:E9) -> 0 | F10: =SUM(F8:F9) -> 0 | G10: =SUM(G8:G9) -> 0 | H10: =SUM(H8:H9) -> 0 | I10: =SUM(B10:H10) -> 0
A11: 2a. Resignation - to take up alternative employment | I11: =SUM(B11:H11) -> 0
A12: 2b. Resignation - due to ill health | I12: =SUM(B12:H12) -> 0
A13: 2c. Resignation - any other reason (please specify) | I13: =SUM(B13:H13) -> 0
A14: 2. Total resignation | B14: =SUM(B11:B13) -> 0 | C14: =SUM(C11:C13) -> 0 | D14: =SUM(D11:D13) -> 0 | E14: =SUM(E11:E13) -> 0 | F14: =SUM(F11:F13) -> 0 | G14: =SUM(G11:G13) -> 0 | H14: =SUM(H11:H13) -> 0 | I14: =SUM(B14:H14) -> 0
A15: 3a. Redundancy - compulsory | I15: =SUM(B15:H15) -> 0
A16: 3b. Redundancy - voluntary | I16: =SUM(B16:H16) -> 0
A17: 3. Total redundancy | B17: =SUM(B15:B16) -> 0 | C17: =SUM(C15:C16) -> 0 | D17: =SUM(D15:D16) -> 0 | E17: =SUM(E15:E16) -> 0 | F17: =SUM(F15:F16) -> 0 | G17: =SUM(G15:G16) -> 0 | H17: =SUM(H15:H16) -> 0 | I17: =SUM(B17:H17) -> 0
A18: 4a. Retirement - early | I18: =SUM(B18:H18) -> 0
A19: 4b. Retirement - normal | I19: =SUM(B19:H19) -> 0
A20: 4. Total retirement | B20: =SUM(B18:B19) -> 0 | C20: =SUM(C18:C19) -> 0 | D20: =SUM(D18:D19) -> 0 | E20: =SUM(E18:E19) -> 0 | F20: =SUM(F18:F19) -> 0 | G20: =SUM(G18:G19) -> 0 | H20: =SUM(H18:H19) -> 0 | I20: =SUM(B20:H20) -> 0
A21: 5a. Dismissal - poor performance (including failure to maintain fitness) | I21: =SUM(B21:H21) -> 0
A22: 5b. Dismissal - disciplinary grounds | I22: =SUM(B22:H22) -> 0
A23: 5. Total dismissal | B23: =SUM(B21:B22) -> 0 | C23: =SUM(C21:C22) -> 0 | D23: =SUM(D21:D22) -> 0 | E23: =SUM(E21:E22) -> 0 | F23: =SUM(F21:F22) -> 0 | G23: =SUM(G21:G22) -> 0 | H23: =SUM(H21:H22) -> 0 | I23: =SUM(B23:H23) -> 0
A24: 6. Deceased | I24: =SUM(B24:H24) -> 0
A25: 7. Other (please supply details in text box below) | I25: =SUM(B25:H25) -> 0
A26: 8. Unknown / Reason for leaving not recorded | I26: =SUM(B26:H26) -> 0
A27: Total | B27: =SUM(B10,B14,B17,B20,B23,B24:B26) -> 0 | C27: =SUM(C10,C14,C17,C20,C23,C24:C26) -> 0 | D27: =SUM(D10,D14,D17,D20,D23,D24:D26) -> 0 | E27: =SUM(E10,E14,E17,E20,E23,E24:E26) -> 0 | F27: =SUM(F10,F14,F17,F20,F23,F24:F26) -> 0 | G27: =SUM(G10,G14,G17,G20,G23,G24:G26) -> 0 | H27: =SUM(H10,H14,H17,H20,H23,H24:H26) -> 0 | I27: =SUM(B27:H27) -> 0
A29: FRS Notes

Sheet LE1b
A5: LE1 Number of wholetime firefighters leaving by gender, age, disability, ethnicity, religion and sexual orientation
A8: Gender and age of wholetime firefighters leaving in the latest year 1 April to 31 March
C9: Age: 17-24 | H9: Age: 25-35 | M9: Age: 36-45 | R9: Age: 46-55
C10: Men | D10: Women | E10: Other | F10: Unknown | G10: Total | H10: Men | I10: Women | J10: Other | K10: Unknown | L10: Total | M10: Men | N10: Women | O10: Other | P10: Unknown | Q10: Total | R10: Men | S10: Women | T10: Other | U10: Unknown | V10: Total
C11: 17m | D11: 17f | E11: 17f | H11: 25m | I11: 25f | J11: 25f | M11: 36m | N11: 36f | O11: 36f | R11: 46m | S11: 46f | T11: 46f
A12: Brigade Manager | B12: bm | G12: =SUM(C12:F12) -> 0 | L12: =SUM(H12:K12) -> 0 | Q12: =SUM(M12:P12) -> 0 | V12: =SUM(R12:U12) -> 0
A13: Area Manager | B13: am | G13: =SUM(C13:F13) -> 0 | L13: =SUM(H13:K13) -> 0 | Q13: =SUM(M13:P13) -> 0 | V13: =SUM(R13:U13) -> 0
A14: Group Manager | B14: gm | G14: =SUM(C14:F14) -> 0 | L14: =SUM(H14:K14) -> 0 | Q14: =SUM(M14:P14) -> 0 | V14: =SUM(R14:U14) -> 0
A15: Station Manager | B15: sm | G15: =SUM(C15:F15) -> 0 | L15: =SUM(H15:K15) -> 0 | Q15: =SUM(M15:P15) -> 0 | V15: =SUM(R15:U15) -> 0
A16: Watch Manager | B16: wm | G16: =SUM(C16:F16) -> 0 | L16: =SUM(H16:K16) -> 0 | Q16: =SUM(M16:P16) -> 0 | V16: =SUM(R16:U16) -> 0
A17: Crew Manager | B17: cm | G17: =SUM(C17:F17) -> 0 | L17: =SUM(H17:K17) -> 0 | Q17: =SUM(M17:P17) -> 0 | V17: =SUM(R17:U17) -> 0
A18: Firefighter | B18: ff | G18: =SUM(C18:F18) -> 0 | L18: =SUM(H18:K18) -> 0 | Q18: =SUM(M18:P18) -> 0 | V18: =SUM(R18:U18) -> 0
A19: Total | C19: =SUM(C12:C18) -> 0 | D19: =SUM(D12:D18) -> 0 | E19: =SUM(E12:E18) -> 0 | F19: =SUM(F12:F18) -> 0 | G19: =SUM(C19:F19) -> 0 | H19: =SUM(H12:H18) -> 0 | I19: =SUM(I12:I18) -> 0 | J19: =SUM(J12:J18) -> 0 | K19: =SUM(K12:K18) -> 0 | L19: =SUM(H19:K19) -> 0 | M19: =SUM(M12:M18) -> 0 | N19: =SUM(N12:N18) -> 0 | O19: =SUM(O12:O18) -> 0 | P19: =SUM(P12:P18) -> 0 | Q19: =SUM(M19:P19) -> 0 | R19: =SUM(R12:R18) -> 0 | S19: =SUM(S12:S18) -> 0 | T19: =SUM(T12:T18) -> 0 | U19: =SUM(U12:U18) -> 0 | V19: =SUM(R19:U19) -> 0
C22: Age: 56-65 | H22: Age: 66+ | M22: Age not stated
C23: Men | D23: Women | E23: Other | F23: Unknown | G23: Total | H23: Men | I23: Women | J23: Other | K23: Unknown | L23: Total | M23: Men | N23: Women | O23: Other | P23: Unknown | Q23: Total | S23: Consistency QA check
C24: 56m | D24: 56f | E24: 56f | H24: 66m | I24: 66f | J24: 66f
A25: Brigade Manager | B25: bm | G25: =SUM(C25:F25) -> 0 | L25: =SUM(H25:K25) -> 0 | Q25: =SUM(M25:P25) -> 0 | S25: Total wholetime firefighters - all ages | V25: =SUM($G$19+$L$19+$Q$19+$V$19+$G$32+$L$32+$Q$32) -> 0
A26: Area Manager | B26: am | G26: =SUM(C26:F26) -> 0 | L26: =SUM(H26:K26) -> 0 | Q26: =SUM(M26:P26) -> 0 | S26: Total wholetime firefighters - all ethnicities | V26: =SUM(C44+I44+C56+I56+M56+P56) -> 0
A27: Group Manager | B27: gm | G27: =SUM(C27:F27) -> 0 | L27: =SUM(H27:K27) -> 0 | Q27: =SUM(M27:P27) -> 0 | S27: Total wholetime firefighters - all sexual orientations | V27: =SUM($O$69:$S$69) -> 0
A28: Station Manager | B28: sm | G28: =SUM(C28:F28) -> 0 | L28: =SUM(H28:K28) -> 0 | Q28: =SUM(M28:P28) -> 0 | S28: Total wholetime firefighters - all disability statuses | V28: =SUM($C$69:$E$69) -> 0
A29: Watch Manager | B29: wm | G29: =SUM(C29:F29) -> 0 | L29: =SUM(H29:K29) -> 0 | Q29: =SUM(M29:P29) -> 0 | S29: Total wholetime firefighters - all religious identities | V29: =SUM($F$69:$N$69) -> 0
A30: Crew Manager | B30: cm | G30: =SUM(C30:F30) -> 0 | L30: =SUM(H30:K30) -> 0 | Q30: =SUM(M30:P30) -> 0
A31: Firefighter | B31: ff | G31: =SUM(C31:F31) -> 0 | L31: =SUM(H31:K31) -> 0 | Q31: =SUM(M31:P31) -> 0 | S31: Totals for each characteristic match | V31: =IF(AND(V25=V26, V25=V27, V25=V28, V25=V29), "Yes", "No") -> Yes
A32: Total | C32: =SUM(C25:C31) -> 0 | D32: =SUM(D25:D31) -> 0 | E32: =SUM(E25:E31) -> 0 | F32: =SUM(F25:F31) -> 0 | G32: =SUM(C32:F32) -> 0 | H32: =SUM(H25:H31) -> 0 | I32: =SUM(I25:I31) -> 0 | J32: =SUM(J25:J31) -> 0 | K32: =SUM(K25:K31) -> 0 | L32: =SUM(H32:K32) -> 0 | M32: =SUM(M25:M31) -> 0 | N32: =SUM(N25:N31) -> 0 | O32: =SUM(O25:O31) -> 0 | P32: =SUM(P25:P31) -> 0 | Q32: =SUM(M32:P32) -> 0
S33: The total number of wholetime firefighters reported against each diversity characteristic should be the same. If this is not possible for any reason please explain below.
A35: Ethnic origin of wholetime firefighters leaving in the latest year 1 April to 31 March
C36: White | D36: White: English/ Welsh/ Scottish/ Northern Irish/ British | E36: White: Irish | F36: White: Gypsy or Irish Traveller | G36: White: Roma | H36: Any other White background | I36: Mixed or Multiple Ethnic Groups | J36: Mixed or Multiple Ethnic Groups: White and Black Caribbean | K36: Mixed or Multiple Ethnic Groups: White and Black African | L36: Mixed or Multiple Ethnic Groups: White and Asian | M36: Any other Mixed / Multiple ethnic background
A37: Brigade Manager | B37: bm | C37: =SUM(D37:H37) -> 0 | I37: =SUM(J37:M37) -> 0
A38: Area Manager | B38: am | C38: =SUM(D38:H38) -> 0 | I38: =SUM(J38:M38) -> 0
A39: Group Manager | B39: gm | C39: =SUM(D39:H39) -> 0 | I39: =SUM(J39:M39) -> 0
A40: Station Manager | B40: sm | C40: =SUM(D40:H40) -> 0 | I40: =SUM(J40:M40) -> 0
A41: Watch Manager | B41: wm | C41: =SUM(D41:H41) -> 0 | I41: =SUM(J41:M41) -> 0
A42: Crew Manager | B42: cm | C42: =SUM(D42:H42) -> 0 | I42: =SUM(J42:M42) -> 0
A43: Firefighter | B43: ff | C43: =SUM(D43:H43) -> 0 | I43: =SUM(J43:M43) -> 0
A44: Total | C44: =SUM(C37:C43) -> 0 | D44: =SUM(D37:D43) -> 0 | E44: =SUM(E37:E43) -> 0 | F44: =SUM(F37:F43) -> 0 | G44: =SUM(G37:G43) -> 0 | H44: =SUM(H37:H43) -> 0 | I44: =SUM(I37:I43) -> 0 | J44: =SUM(J37:J43) -> 0 | ... M44: =SUM(M37:M43) -> 0
A47: Ethnic origin of wholetime firefighters leaving in the latest year 1 April to 31 March
C48: Asian/Asian British | D48: Asian/Asian British: Indian | E48: Asian/Asian British: Pakistani | F48: Asian/Asian British: Bangladeshi | G48: Asian/Asian British: Chinese | H48: Any other Asian/Asian British background | I48: Black / African / Caribbean / Black British | J48: Black / African / Caribbean / Black British: African | K48: Black / African / Caribbean / Black British: Caribbean | L48: Any other Black/African/ Caribbean background | M48: Other ethnic group | N48: Other ethnic group: Arab | O48: Any other ethnic group | P48: Ethnic origin Not Stated
A49: Brigade Manager | B49: bm | C49: =SUM(D49:H49) -> 0 | I49: =SUM(J49:L49) -> 0 | M49: =SUM(N49:O49) -> 0
A50: Area Manager | B50: am | C50: =SUM(D50:H50) -> 0 | I50: =SUM(J50:L50) -> 0 | M50: =SUM(N50:O50) -> 0
A51: Group Manager | B51: gm | C51: =SUM(D51:H51) -> 0 | I51: =SUM(J51:L51) -> 0 | M51: =SUM(N51:O51) -> 0
...

Sheet LE2a PY
C4: LE2 | D4: =VLOOKUP(Cover!A6,Cover!B319:D331,2,FALSE) -> 2024/25 | E4: =Cover!A10 -> Shropshire
B7: Group Manager | C7: Station Manager | D7: Watch Manager | E7: Crew Manager | F7: Firefighter | G7: Total
A8: 1a. Moving - to another FRS | B8: {=SUMPRODUCT(('LE - PY data'!$A$2:$A$10000='LE2a PY'!$C$4)*('LE - PY data'!$B$2:$B$10000='LE2a PY'!$D$4)*('LE - PY data'!$C$2:$C$10000='LE2a PY'!$E$4)*('LE - PY data'!$E$2:$E$10000='LE2a PY'!B$7)*('LE - PY data'!$F$2:$F$10000='LE2a PY'!$A8)*('LE - PY data'!$G$2:$G$10000))} -> 0 | C8: {=SUMPRODUCT(('LE - PY data'!$A$2:$A$10000='LE2a PY'!$C$4)*('LE - PY data'!$B$2:$B$10000='LE2a PY'!$D$4)*('LE - PY data'!$C$2:$C$10000='LE2a PY'!$E$4)*('LE - PY data'!$E$2:$E$10000='LE2a PY'!C$7)*('LE - PY data'!$F$2:$F$10000='LE2a PY'!$A8)*('LE - PY data'!$G$2:$G$10000))} -> 0 | D8: {=SUMPRODUCT(('LE - PY data'!$A$2:$A$10000='LE2a PY'!$C$4)*('LE - PY data'!$B$2:$B$10000='LE2a PY'!$D$4)*('LE - PY data'!$C$2:$C$10000='LE2a PY'!$E$4)*('LE - PY data'!$E$2:$E$10000='LE2a PY'!D$7)*('LE - PY data'!$F$2:$F$10000='LE2a PY'!$A8)*('LE - PY data'!$G$2:$G$10000))} -> 0 | E8: {=SUMPRODUCT(('LE - PY data'!$A$2:$A$10000='LE2a PY'!$C$4)*('LE - PY data'!$B$2:$B$10000='LE2a PY'!$D$4)*('LE - PY data'!$C$2:$C$10000='LE2a PY'!$E$4)*('LE - PY data'!$E$2:$E$10000='LE2a PY'!E$7)*('LE - PY data'!$F$2:$F$10000='LE2a PY'!$A8)*('LE - PY data'!$G$2:$G$10000))} -> 0 | F8: {=SUMPRODUCT(('LE - PY data'!$A$2:$A$10000='LE2a PY'!$C$4)*('LE - PY data'!$B$2:$B$10000='LE2a PY'!$D$4)*('LE - PY data'!$C$2:$C$10000='LE2a PY'!$E$4)*('LE - PY data'!$E$2:$E$10000='LE2a PY'!F$7)*('LE - PY data'!$F$2:$F$10000='LE2a PY'!$A8)*('LE - PY data'!$G$2:$G$10000))} -> 0 | G8: {=SUMPRODUCT(('LE - PY data'!$A$2:$A$10000='LE2a PY'!$C$4)*('LE - PY data'!$B$2:$B$10000='LE2a PY'!$D$4)*('LE - PY data'!$C$2:$C$10000='LE2a PY'!$E$4)*('LE - PY data'!$F$2:$F$10000='LE2a PY'!$A8)*('LE - PY data'!$G$2:$G$10000))} -> 0
A9: 1b. Moving - within FRS from operational (firefighter or control) to support staff | B9: {=SUMPRODUCT(('LE - PY data'!$A$2:$A$10000='LE2a PY'!$C$4)*('LE - PY data'!$B$2:$B$10000='LE2a PY'!$D$4)*('LE - PY data'!$C$2:$C$10000='LE2a PY'!$E$4)*('LE - PY data'!$E$2:$E$10000='LE2a PY'!B$7)*('LE - PY data'!$F$2:$F$10000='LE2a PY'!$A9)*('LE - PY data'!$G$2:$G$10000))} -> 0 | C9: {=SUMPRODUCT(('LE - PY data'!$A$2:$A$10000='LE2a PY'!$C$4)*('LE - PY data'!$B$2:$B$10000='LE2a PY'!$D$4)*('LE - PY data'!$C$2:$C$10000='LE2a PY'!$E$4)*('LE - PY data'!$E$2:$E$10000='LE2a PY'!C$7)*('LE - PY data'!$F$2:$F$10000='LE2a PY'!$A9)*('LE - PY data'!$G$2:$G$10000))} -> 0 | D9: {=SUMPRODUCT(('LE - PY data'!$A$2:$A$10000='LE2a PY'!$C$4)*('LE - PY data'!$B$2:$B$10000='LE2a PY'!$D$4)*('LE - PY data'!$C$2:$C$10000='LE2a PY'!$E$4)*('LE - PY data'!$E$2:$E$10000='LE2a PY'!D$7)*('LE - PY data'!$F$2:$F$10000='LE2a PY'!$A9)*('LE - PY data'!$G$2:$G$10000))} -> 0 | E9: {=SUMPRODUCT(('LE - PY data'!$A$2:$A$10000='LE2a PY'!$C$4)*('LE - PY data'!$B$2:$B$10000='LE2a PY'!$D$4)*('LE - PY data'!$C$2:$C$10000='LE2a PY'!$E$4)*('LE - PY data'!$E$2:$E$10000='LE2a PY'!E$7)*('LE - PY data'!$F$2:$F$10000='LE2a PY'!$A9)*('LE - PY data'!$G$2:$G$10000))} -> 0 | F9: {=SUMPRODUCT(('LE - PY data'!$A$2:$A$10000='LE2a PY'!$C$4)*('LE - PY data'!$B$2:$B$10000='LE2a PY'!$D$4)*('LE - PY data'!$C$2:$C$10000='LE2a PY'!$E$4)*('LE - PY data'!$E$2:$E$10000='LE2a PY'!F$7)*('LE - PY data'!$F$2:$F$10000='LE2a PY'!$A9)*('LE - PY data'!$G$2:$G$10000))} -> 0 | G9: {=SUMPRODUCT(('LE - PY data'!$A$2:$A$10000='LE2a PY'!$C$4)*('LE - PY data'!$B$2:$B$10000='LE2a PY'!$D$4)*('LE - PY data'!$C$2:$C$10000='LE2a PY'!$E$4)*('LE - PY data'!$F$2:$F$10000='LE2a PY'!$A9)*('LE - PY data'!$G$2:$G$10000))} -> 0
A10: 1. Total moving | B10: {=SUMPRODUCT(('LE - PY data'!$A$2:$A$10000='LE2a PY'!$C$4)*('LE - PY data'!$B$2:$B$10000='LE2a PY'!$D$4)*('LE - PY data'!$C$2:$C$10000='LE2a PY'!$E$4)*('LE - PY data'!$E$2:$E$10000='LE2a PY'!B$7)*('LE - PY data'!$F$2:$F$10000='LE2a PY'!$A10)*('LE - PY data'!$G$2:$G$10000))} -> 0 | C10: {=SUMPRODUCT(('LE - PY data'!$A$2:$A$10000='LE2a PY'!$C$4)*('LE - PY data'!$B$2:$B$10000='LE2a PY'!$D$4)*('LE - PY data'!$C$2:$C$10000='LE2a PY'!$E$4)*('LE - PY data'!$E$2:$E$10000='LE2a PY'!C$7)*('LE - PY data'!$F$2:$F$10000='LE2a PY'!$A10)*('LE - PY data'!$G$2:$G$10000))} -> 0 | D10: {=SUMPRODUCT(('LE - PY data'!$A$2:$A$10000='LE2a PY'!$C$4)*('LE - PY data'!$B$2:$B$10000='LE2a PY'!$D$4)*('LE - PY data'!$C$2:$C$10000='LE2a PY'!$E$4)*('LE - PY data'!$E$2:$E$10000='LE2a PY'!D$7)*('LE - PY data'!$F$2:$F$10000='LE2a PY'!$A10)*('LE - PY data'!$G$2:$G$10000))} -> 0 | E10: {=SUMPRODUCT(('LE - PY data'!$A$2:$A$10000='LE2a PY'!$C$4)*('LE - PY data'!$B$2:$B$10000='LE2a PY'!$D$4)*('LE - PY data'!$C$2:$C$10000='LE2a PY'!$E$4)*('LE - PY data'!$E$2:$E$10000='LE2a PY'!E$7)*('LE - PY data'!$F$2:$F$10000='LE2a PY'!$A10)*('LE - PY data'!$G$2:$G$10000))} -> 0 | F10: {=SUMPRODUCT(('LE - PY data'!$A$2:$A$10000='LE2a PY'!$C$4)*('LE - PY data'!$B$2:$B$10000='LE2a PY'!$D$4)*('LE - PY data'!$C$2:$C$10000='LE2a PY'!$E$4)*('LE - PY data'!$E$2:$E$10000='LE2a PY'!F$7)*('LE - PY data'!$F$2:$F$10000='LE2a PY'!$A10)*('LE - PY data'!$G$2:$G$10000))} -> 0 | G10: {=SUMPRODUCT(('LE - PY data'!$A$2:$A$10000='LE2a PY'!$C$4)*('LE - PY data'!$B$2:$B$10000='LE2a PY'!$D$4)*('LE - PY data'!$C$2:$C$10000='LE2a PY'!$E$4)*('LE - PY data'!$F$2:$F$10000='LE2a PY'!$A10)*('LE - PY data'!$G$2:$G$10000))} -> 0
A11: 2a. Resignation - to take up alternative employment | B11: {=SUMPRODUCT(('LE - PY data'!$A$2:$A$10000='LE2a PY'!$C$4)*('LE - PY data'!$B$2:$B$10000='LE2a PY'!$D$4)*('LE - PY data'!$C$2:$C$10000='LE2a PY'!$E$4)*('LE - PY data'!$E$2:$E$10000='LE2a PY'!B$7)*('LE - PY data'!$F$2:$F$10000='LE2a PY'!$A11)*('LE - PY data'!$G$2:$G$10000))} -> 0 | C11: {=SUMPRODUCT(('LE - PY data'!$A$2:$A$10000='LE2a PY'!$C$4)*('LE - PY data'!$B$2:$B$10000='LE2a PY'!$D$4)*('LE - PY data'!$C$2:$C$10000='LE2a PY'!$E$4)*('LE - PY data'!$E$2:$E$10000='LE2a PY'!C$7)*('LE - PY data'!$F$2:$F$10000='LE2a PY'!$A11)*('LE - PY data'!$G$2:$G$10000))} -> 0 | D11: {=SUMPRODUCT(('LE - PY data'!$A$2:$A$10000='LE2a PY'!$C$4)*('LE - PY data'!$B$2:$B$10000='LE2a PY'!$D$4)*('LE - PY data'!$C$2:$C$10000='LE2a PY'!$E$4)*('LE - PY data'!$E$2:$E$10000='LE2a PY'!D$7)*('LE - PY data'!$F$2:$F$10000='LE2a PY'!$A11)*('LE - PY data'!$G$2:$G$10000))} -> 0 | E11: {=SUMPRODUCT(('LE - PY data'!$A$2:$A$10000='LE2a PY'!$C$4)*('LE - PY data'!$B$2:$B$10000='LE2a PY'!$D$4)*('LE - PY data'!$C$2:$C$10000='LE2a PY'!$E$4)*('LE - PY data'!$E$2:$E$10000='LE2a PY'!E$7)*('LE - PY data'!$F$2:$F$10000='LE2a PY'!$A11)*('LE - PY data'!$G$2:$G$10000))} -> 0 | F11: {=SUMPRODUCT(('LE - PY data'!$A$2:$A$10000='LE2a PY'!$C$4)*('LE - PY data'!$B$2:$B$10000='LE2a PY'!$D$4)*('LE - PY data'!$C$2:$C$10000='LE2a PY'!$E$4)*('LE - PY data'!$E$2:$E$10000='LE2a PY'!F$7)*('LE - PY data'!$F$2:$F$10000='LE2a PY'!$A11)*('LE - PY data'!$G$2:$G$10000))} -> 0 | G11: {=SUMPRODUCT(('LE - PY data'!$A$2:$A$10000='LE2a PY'!$C$4)*('LE - PY data'!$B$2:$B$10000='LE2a PY'!$D$4)*('LE - PY data'!$C$2:$C$10000='LE2a PY'!$E$4)*('LE - PY data'!$F$2:$F$10000='LE2a PY'!$A11)*('LE - PY data'!$G$2:$G$10000))} -> 0
A12: 2b. Resignation - due to ill health | B12: {=SUMPRODUCT(('LE - PY data'!$A$2:$A$10000='LE2a PY'!$C$4)*('LE - PY data'!$B$2:$B$10000='LE2a PY'!$D$4)*('LE - PY data'!$C$2:$C$10000='LE2a PY'!$E$4)*('LE - PY data'!$E$2:$E$10000='LE2a PY'!B$7)*('LE - PY data'!$F$2:$F$10000='LE2a PY'!$A12)*('LE - PY data'!$G$2:$G$10000))} -> 0 | C12: {=SUMPRODUCT(('LE - PY data'!$A$2:$A$10000='LE2a PY'!$C$4)*('LE - PY data'!$B$2:$B$10000='LE2a PY'!$D$4)*('LE - PY data'!$C$2:$C$10000='LE2a PY'!$E$4)*('LE - PY data'!$E$2:$E$10000='LE2a PY'!C$7)*('LE - PY data'!$F$2:$F$10000='LE2a PY'!$A12)*('LE - PY data'!$G$2:$G$10000))} -> 0 | D12: {=SUMPRODUCT(('LE - PY data'!$A$2:$A$10000='LE2a PY'!$C$4)*('LE - PY data'!$B$2:$B$10000='LE2a PY'!$D$4)*('LE - PY data'!$C$2:$C$10000='LE2a PY'!$E$4)*('LE - PY data'!$E$2:$E$10000='LE2a PY'!D$7)*('LE - PY data'!$F$2:$F$10000='LE2a PY'!$A12)*('LE - PY data'!$G$2:$G$10000))} -> 0 | E12: {=SUMPRODUCT(('LE - PY data'!$A$2:$A$10000='LE2a PY'!$C$4)*('LE - PY data'!$B$2:$B$10000='LE2a PY'!$D$4)*('LE - PY data'!$C$2:$C$10000='LE2a PY'!$E$4)*('LE - PY data'!$E$2:$E$10000='LE2a PY'!E$7)*('LE - PY data'!$F$2:$F$10000='LE2a PY'!$A12)*('LE - PY data'!$G$2:$G$10000))} -> 0 | F12: {=SUMPRODUCT(('LE - PY data'!$A$2:$A$10000='LE2a PY'!$C$4)*('LE - PY data'!$B$2:$B$10000='LE2a PY'!$D$4)*('LE - PY data'!$C$2:$C$10000='LE2a PY'!$E$4)*('LE - PY data'!$E$2:$E$10000='LE2a PY'!F$7)*('LE - PY data'!$F$2:$F$10000='LE2a PY'!$A12)*('LE - PY data'!$G$2:$G$10000))} -> 0 | G12: {=SUMPRODUCT(('LE - PY data'!$A$2:$A$10000='LE2a PY'!$C$4)*('LE - PY data'!$B$2:$B$10000='LE2a PY'!$D$4)*('LE - PY data'!$C$2:$C$10000='LE2a PY'!$E$4)*('LE - PY data'!$F$2:$F$10000='LE2a PY'!$A12)*('LE - PY data'!$G$2:$G$10000))} -> 0
