Workbook
Name _ftnref1: Guidance!$A$28
Name _Toc257106260: Guidance!$A$1
Name Data: #REF!
Name Data: #REF!
Name Data: #REF!
Name Data: #REF!
Name FS3_f: #REF!
Name FS3_formula: #REF!
Name FS4_formula: #REF!
Name FS5_formula: #REF!
Name FS9_f: '[1]FS9 2020-21'!#REF!
Name FS9_formula: [1]FS9!#REF!
Name HR1_formula: #REF!
Name HR2_f: #REF!
Name HR2_formula: #REF!
Name HR2_formula: #REF!
Name HR2_formula: #REF!
Name HR3_formula: #REF!
Name HR3_formula: #REF!
Name HR3_formula: #REF!
Name HR4_formula: #REF!
Name HR4_formula: #REF!
Name HR4_formula: #REF!
Name HR5_formula: #REF!
Name HR5_formula: #REF!
Name HR5_formula: #REF!

Sheet Cover
A6: 2025_26
A7: Operational Statistics Collection
A8: Health and safety (HS)
A10: =VLOOKUP(B250,B251:D316,2,FALSE) -> Cumbria
A11: =VLOOKUP(B250,B251:D316,3,FALSE) -> E31000009
A14: Index of Tables | B14: Description
A15: HS1 | B15: Injuries during operational incidents
A16: HS2 | B16: Injuries during training and routine activities
A17: Guidance | B17: Guidance notes
A19: Key
B20: Cells highlighted yellow following data entry indicate a significant change in the figures inputted relative to the previous year. Please double check the relevant figures prior to submitting this return.
A22: Please complete by Friday 12 June 2026 and send the spreadsheet as an attachment via e-mail to firestatistics@homeoffice.gov.uk
A25: Contact
A26: E-mail Address
A28: If you have any comments on the data submitted please provide them in the box below. If not, please leave blank.
A250: FRS Selector>>>>> | B250: 9 | C250: =MAX(B251:B316) -> 45
B251: 1 | C251: Avon | D251: E31000001
B252: 2 | C252: Bedfordshire | D252: E31000002
B253: 3 | C253: Berkshire | D253: E31000003
B254: 4 | C254: Buckinghamshire | D254: E31000004
B255: 5 | C255: Cambridgeshire | D255: E31000005
B256: 6 | C256: Cheshire | D256: E31000006
B257: 7 | C257: Cleveland | D257: E31000007
B258: 8 | C258: Cornwall | D258: E31000008
B259: 9 | C259: Cumbria | D259: E31000009
B260: 10 | C260: Derbyshire | D260: E31000010
B261: 11 | C261: Devon and Somerset | D261: E31000011
B262: 12 | C262: Dorset and Wiltshire | D262: E31000047
... B295: 45 | C295: North West Fire Control | D295: NWFC
B316: 0 | C316: Template FRS | D316: 0
B319: 2023_24 | C319: 2022/23
B320: 2024_25 | C320: 2023/24
B321: 2025_26 | C321: 2024/25
B322: 2026_27 | C322: 2025/26
B323: 2027_28 | C323: 2026/27
B324: 2028_29 | C324: 2027/28

Sheet Guidance
A1: Guidance notes for injuries occurring to FRS staff during operational incidents, training and routine activities (HS1-2)
A3: HS1 and HS2 cover injuries occurring to FRS staff during operational incidents, training and routine activities, during the latest period 1 April to 31 March.
A5: This information is used to monitor health and safety issues.
A7: The form collects information on:
A8: a) Total number of personnel injured
A9: b) Number of "Over 7 day injuries"
A10: c) Number of RIDDOR major injuries
A11: d) Number of fatalities
A13: For more information about RIDDOR (Reporting of Injuries, Diseases and Dangerous Occurrences Regulations) see-
A14: http://www.hse.gov.uk/riddor/key-definitions.htm
A16: Definitions
A18: Wholetime firefighter: | B18: A person employed as a full-time firefighter regardless of their rank (including riders, non-operational staff and flexible duty officers, and recruits in training).
A20: On call firefighter: | B20: On call firefighters (i.e. those on the Retained Duty System, RDS) respond when required during their ‘on call’ hours to their nominated station which should be close to where they live or work. They are trained to deal with a range of situations, including fires, road traffic incidents, dealing with hazardous materials and floods. This may also include fire safety work. On call staff could have an alternative full time employment.
A22: Total number of personnel injured: | B22: Number of individuals sustaining injuries during an activity.
B24: Multiple injuries to an individual sustained during a single event should be counted as a single injury. Please refer to injured persons not injuries e.g. a broken arm and leg = 1 injury.
B26: However, if a person was injured in more than one activity please count more than once. For example, if the same person was injured during three different operational activities, they will be counted three times.
A28: RIDDOR: | B28: The Reporting of Injuries, Diseases and Dangerous Occurrences Regulations 2013 (RIDDOR), place a legal duty on employers, self-employed people, people in control of premises to report:
B30: a) work-related deaths
B31: b) major injuries
B32: c) or over-seven-day injuries,
B33: d) work related diseases,
B34: e) and dangerous occurrences (near miss accidents)
B36: The return should collect all injuries that are classified as RIDDOR and not just RIDDOR reportable. The guidance was updated in 2013 with the latest HSE guidance available here http://www.hse.gov.uk/riddor/
A38: Over 7 day injuries: | B38: This category refers to actual number of injuries sustained during an activity, which were not ‘major’ as defined in RIDDOR, but resulted in the person being unavailable for their normal duties for a period of more than seven days. This was updated for 2018-19 and means the figures are not comparable with pre 2017-18 data.
A40: RIDDOR Major injuries: | B40: Injuries sustained during each activity for each group which resulted in an injury that is defined in RIDDOR as a ‘major’ injury.
B42: The list of ‘specified injuries’ that are 'major injuries' in RIDDOR 2013 replaces the previous list of ‘major injuries’ in RIDDOR 1995. Specified injuries are (regulation 4): Fractures, other than to fingers, thumbs and toes Amputations Any injury likely to lead to permanent loss of sight or reduction in sight Any crush injury to the head or torso causing damage to the brain or internal organs Serious burns (including scalding) which: covers more than 10% of the body Causes significant damage to the eyes, respiratory system or other vital organs Any scalping requiring hospital treatment Any loss of consciousness caused by head injury or asphyxia Any other injury arising from working in an enclosed space which: leads to hypothermia or heat-induced illness Requires resuscitation or admittance to hospital for more than 24 hours Further guidance is available from HSE
A45: Operational incidents: | B45: Incidents recorded by the FRA at fires, road traffic accidents and other special service incidents.
B47: This category includes incidents/injuries occurred while responding to an emergency. Please record in the relevant category depending on whether the fire call was for a fire, a road traffic collision or other special service incidents. For example, injuries occurring whilst responding to fire incidents (e.g. a retained person en route to the fire station) are to be included in HS1 under fire. If an injury occurs whilst returning from an incident, this is to be included under HS1.
B49: The incident is considered to be ongoing until such time as the person is back at the station or, if preceding other duties such as hydrant testing or training, then until commencing that activity.
A51: Fire incidents: | B51: Primary and secondary fire incidents.
A54: Road traffic collisions: | B54: Non-fire incidents which require the attendance of the Fire and Rescue Services for collisions involving road vehicles (i.e. large and small vehicles, including motorbikes).
A56: Other special service incidents: | B56: Non-fire incidents which require the attendance of an appliance or officer and include:
B57: Ø Flooding
B58: Ø Rescue or evacuation from water
B59: Ø Other rescue/release of persons
B60: Ø Animal assistance incidents
B61: Ø Hazardous Materials incident
B62: Ø Spills and Leaks (not RTC)
B63: Ø Lift Release
B64: Ø Making Safe (not RTC)
...

Sheet HS1
A5: HS1 - Health and Safety - Injuries during operational incidents
B7: Injuries at fires | D7: Injuries at road traffic collisions | F7: Injuries at other special service incidents | H7: Total
B8: Wholetime firefighters | C8: On call firefighters | D8: Wholetime firefighters | E8: On call firefighters | F8: Wholetime firefighters | G8: On call firefighters
A9: Total number of personnel injured | H9: =SUM(B9:G9) -> 0
A10: Number of "Over 7 day injuries" | H10: =SUM(B10:G10) -> 0
A11: Number of RIDDOR Major injuries | H11: =SUM(B11:G11) -> 0
A12: Number of fatalities | H12: =SUM(B12:G12) -> 0
A16: FRS Notes

Sheet HS2
A5: HS2 - Health and Safety - Injuries during training and routine activities
B7: Operational training | D7: Fitness training | F7: Injuries during routine activities | H7: Total
B8: Wholetime firefighters | C8: On call firefighters | D8: Wholetime firefighters | E8: On call firefighters | F8: Wholetime firefighters | G8: On call firefighters
A9: Total number of personnel injured | H9: =SUM(B9:G9) -> 0
A10: Number of "Over 7 day injuries" | H10: =SUM(B10:G10) -> 0
A11: Number of RIDDOR Major injuries | H11: =SUM(B11:G11) -> 0
A12: Number of fatalities | H12: =SUM(B12:G12) -> 0
A16: FRS Notes

Sheet QA checks
A1: HS1 sheet | D1: HS2 sheet
A2: Number of injuries at fires look sensible and broadly similar to the previous year | B2: yes | D2: Number of injuries at operational training look sensible and broadly similar to the previous year | E2: yes
A3: Number of injuries at RTCs look sensible and broadly similar to the previous year | D3: Number of injuries at fitness training look sensible and broadly similar to the previous year
A4: Number of injuries at other incidents look sensible and broadly similar to the previous year | D4: Number of injuries during routine activities look sensible and broadly similar to the previous year

Sheet HS - PY data
A1: SHEET | B1: FINANCIAL_YEAR | C1: FRS_NAME | D1: INCIDENT_TYPE_DETAILED | E1: ROLE | F1: INJURY_SEVERITY | G1: TOTAL

Sheet HS1 PY
C4: HS1 | D4: =VLOOKUP(Cover!A6,Cover!B319:D331,2,FALSE) -> 2024/25 | E4: =Cover!A10 -> Cumbria
B7: Fires | C7: Fires | D7: Road traffic collisions | E7: Road traffic collisions | F7: Other non-fire incidents | G7: Other non-fire incidents | H7: Total
B8: Wholetime firefighters | C8: On call firefighters | D8: Wholetime firefighters | E8: On call firefighters | F8: Wholetime firefighters | G8: On call firefighters
A9: Total number of personnel injured | B9: {=SUMPRODUCT(('HS - PY data'!$A$2:$A$49952=$C$4)*('HS - PY data'!$B$2:$B$49952=$D$4)*('HS - PY data'!$C$2:$C$49952=$E$4)*('HS - PY data'!$D$2:$D$49952=B$7)*('HS - PY data'!$F$2:$F$49952=$A9)*('HS - PY data'!$E$2:$E$49952=B$8)*('HS - PY data'!$G$2:$G$49952))} -> 0 | C9: {=SUMPRODUCT(('HS - PY data'!$A$2:$A$49952=$C$4)*('HS - PY data'!$B$2:$B$49952=$D$4)*('HS - PY data'!$C$2:$C$49952=$E$4)*('HS - PY data'!$D$2:$D$49952=C$7)*('HS - PY data'!$F$2:$F$49952=$A9)*('HS - PY data'!$E$2:$E$49952=C$8)*('HS - PY data'!$G$2:$G$49952))} -> 0 | D9: {=SUMPRODUCT(('HS - PY data'!$A$2:$A$49952=$C$4)*('HS - PY data'!$B$2:$B$49952=$D$4)*('HS - PY data'!$C$2:$C$49952=$E$4)*('HS - PY data'!$D$2:$D$49952=D$7)*('HS - PY data'!$F$2:$F$49952=$A9)*('HS - PY data'!$E$2:$E$49952=D$8)*('HS - PY data'!$G$2:$G$49952))} -> 0 | E9: {=SUMPRODUCT(('HS - PY data'!$A$2:$A$49952=$C$4)*('HS - PY data'!$B$2:$B$49952=$D$4)*('HS - PY data'!$C$2:$C$49952=$E$4)*('HS - PY data'!$D$2:$D$49952=E$7)*('HS - PY data'!$F$2:$F$49952=$A9)*('HS - PY data'!$E$2:$E$49952=E$8)*('HS - PY data'!$G$2:$G$49952))} -> 0 | F9: {=SUMPRODUCT(('HS - PY data'!$A$2:$A$49952=$C$4)*('HS - PY data'!$B$2:$B$49952=$D$4)*('HS - PY data'!$C$2:$C$49952=$E$4)*('HS - PY data'!$D$2:$D$49952=F$7)*('HS - PY data'!$F$2:$F$49952=$A9)*('HS - PY data'!$E$2:$E$49952=F$8)*('HS - PY data'!$G$2:$G$49952))} -> 0 | G9: {=SUMPRODUCT(('HS - PY data'!$A$2:$A$49952=$C$4)*('HS - PY data'!$B$2:$B$49952=$D$4)*('HS - PY data'!$C$2:$C$49952=$E$4)*('HS - PY data'!$D$2:$D$49952=G$7)*('HS - PY data'!$F$2:$F$49952=$A9)*('HS - PY data'!$E$2:$E$49952=G$8)*('HS - PY data'!$G$2:$G$49952))} -> 0 | H9: =SUM(B9:G9) -> 0
A10: Number of "Over 3 day injuries" | B10: {=SUMPRODUCT(('HS - PY data'!$A$2:$A$49952=$C$4)*('HS - PY data'!$B$2:$B$49952=$D$4)*('HS - PY data'!$C$2:$C$49952=$E$4)*('HS - PY data'!$D$2:$D$49952=B$7)*('HS - PY data'!$F$2:$F$49952=$A10)*('HS - PY data'!$E$2:$E$49952=B$8)*('HS - PY data'!$G$2:$G$49952))} -> 0 | C10: {=SUMPRODUCT(('HS - PY data'!$A$2:$A$49952=$C$4)*('HS - PY data'!$B$2:$B$49952=$D$4)*('HS - PY data'!$C$2:$C$49952=$E$4)*('HS - PY data'!$D$2:$D$49952=C$7)*('HS - PY data'!$F$2:$F$49952=$A10)*('HS - PY data'!$E$2:$E$49952=C$8)*('HS - PY data'!$G$2:$G$49952))} -> 0 | D10: {=SUMPRODUCT(('HS - PY data'!$A$2:$A$49952=$C$4)*('HS - PY data'!$B$2:$B$49952=$D$4)*('HS - PY data'!$C$2:$C$49952=$E$4)*('HS - PY data'!$D$2:$D$49952=D$7)*('HS - PY data'!$F$2:$F$49952=$A10)*('HS - PY data'!$E$2:$E$49952=D$8)*('HS - PY data'!$G$2:$G$49952))} -> 0 | E10: {=SUMPRODUCT(('HS - PY data'!$A$2:$A$49952=$C$4)*('HS - PY data'!$B$2:$B$49952=$D$4)*('HS - PY data'!$C$2:$C$49952=$E$4)*('HS - PY data'!$D$2:$D$49952=E$7)*('HS - PY data'!$F$2:$F$49952=$A10)*('HS - PY data'!$E$2:$E$49952=E$8)*('HS - PY data'!$G$2:$G$49952))} -> 0 | F10: {=SUMPRODUCT(('HS - PY data'!$A$2:$A$49952=$C$4)*('HS - PY data'!$B$2:$B$49952=$D$4)*('HS - PY data'!$C$2:$C$49952=$E$4)*('HS - PY data'!$D$2:$D$49952=F$7)*('HS - PY data'!$F$2:$F$49952=$A10)*('HS - PY data'!$E$2:$E$49952=F$8)*('HS - PY data'!$G$2:$G$49952))} -> 0 | G10: {=SUMPRODUCT(('HS - PY data'!$A$2:$A$49952=$C$4)*('HS - PY data'!$B$2:$B$49952=$D$4)*('HS - PY data'!$C$2:$C$49952=$E$4)*('HS - PY data'!$D$2:$D$49952=G$7)*('HS - PY data'!$F$2:$F$49952=$A10)*('HS - PY data'!$E$2:$E$49952=G$8)*('HS - PY data'!$G$2:$G$49952))} -> 0 | H10: =SUM(B10:G10) -> 0
A11: Number of RIDDOR Major injuries | B11: {=SUMPRODUCT(('HS - PY data'!$A$2:$A$49952=$C$4)*('HS - PY data'!$B$2:$B$49952=$D$4)*('HS - PY data'!$C$2:$C$49952=$E$4)*('HS - PY data'!$D$2:$D$49952=B$7)*('HS - PY data'!$F$2:$F$49952=$A11)*('HS - PY data'!$E$2:$E$49952=B$8)*('HS - PY data'!$G$2:$G$49952))} -> 0 | C11: {=SUMPRODUCT(('HS - PY data'!$A$2:$A$49952=$C$4)*('HS - PY data'!$B$2:$B$49952=$D$4)*('HS - PY data'!$C$2:$C$49952=$E$4)*('HS - PY data'!$D$2:$D$49952=C$7)*('HS - PY data'!$F$2:$F$49952=$A11)*('HS - PY data'!$E$2:$E$49952=C$8)*('HS - PY data'!$G$2:$G$49952))} -> 0 | D11: {=SUMPRODUCT(('HS - PY data'!$A$2:$A$49952=$C$4)*('HS - PY data'!$B$2:$B$49952=$D$4)*('HS - PY data'!$C$2:$C$49952=$E$4)*('HS - PY data'!$D$2:$D$49952=D$7)*('HS - PY data'!$F$2:$F$49952=$A11)*('HS - PY data'!$E$2:$E$49952=D$8)*('HS - PY data'!$G$2:$G$49952))} -> 0 | E11: {=SUMPRODUCT(('HS - PY data'!$A$2:$A$49952=$C$4)*('HS - PY data'!$B$2:$B$49952=$D$4)*('HS - PY data'!$C$2:$C$49952=$E$4)*('HS - PY data'!$D$2:$D$49952=E$7)*('HS - PY data'!$F$2:$F$49952=$A11)*('HS - PY data'!$E$2:$E$49952=E$8)*('HS - PY data'!$G$2:$G$49952))} -> 0 | F11: {=SUMPRODUCT(('HS - PY data'!$A$2:$A$49952=$C$4)*('HS - PY data'!$B$2:$B$49952=$D$4)*('HS - PY data'!$C$2:$C$49952=$E$4)*('HS - PY data'!$D$2:$D$49952=F$7)*('HS - PY data'!$F$2:$F$49952=$A11)*('HS - PY data'!$E$2:$E$49952=F$8)*('HS - PY data'!$G$2:$G$49952))} -> 0 | G11: {=SUMPRODUCT(('HS - PY data'!$A$2:$A$49952=$C$4)*('HS - PY data'!$B$2:$B$49952=$D$4)*('HS - PY data'!$C$2:$C$49952=$E$4)*('HS - PY data'!$D$2:$D$49952=G$7)*('HS - PY data'!$F$2:$F$49952=$A11)*('HS - PY data'!$E$2:$E$49952=G$8)*('HS - PY data'!$G$2:$G$49952))} -> 0 | H11: =SUM(B11:G11) -> 0
A12: Number of fatalities | B12: {=SUMPRODUCT(('HS - PY data'!$A$2:$A$49952=$C$4)*('HS - PY data'!$B$2:$B$49952=$D$4)*('HS - PY data'!$C$2:$C$49952=$E$4)*('HS - PY data'!$D$2:$D$49952=B$7)*('HS - PY data'!$F$2:$F$49952=$A12)*('HS - PY data'!$E$2:$E$49952=B$8)*('HS - PY data'!$G$2:$G$49952))} -> 0 | C12: {=SUMPRODUCT(('HS - PY data'!$A$2:$A$49952=$C$4)*('HS - PY data'!$B$2:$B$49952=$D$4)*('HS - PY data'!$C$2:$C$49952=$E$4)*('HS - PY data'!$D$2:$D$49952=C$7)*('HS - PY data'!$F$2:$F$49952=$A12)*('HS - PY data'!$E$2:$E$49952=C$8)*('HS - PY data'!$G$2:$G$49952))} -> 0 | D12: {=SUMPRODUCT(('HS - PY data'!$A$2:$A$49952=$C$4)*('HS - PY data'!$B$2:$B$49952=$D$4)*('HS - PY data'!$C$2:$C$49952=$E$4)*('HS - PY data'!$D$2:$D$49952=D$7)*('HS - PY data'!$F$2:$F$49952=$A12)*('HS - PY data'!$E$2:$E$49952=D$8)*('HS - PY data'!$G$2:$G$49952))} -> 0 | E12: {=SUMPRODUCT(('HS - PY data'!$A$2:$A$49952=$C$4)*('HS - PY data'!$B$2:$B$49952=$D$4)*('HS - PY data'!$C$2:$C$49952=$E$4)*('HS - PY data'!$D$2:$D$49952=E$7)*('HS - PY data'!$F$2:$F$49952=$A12)*('HS - PY data'!$E$2:$E$49952=E$8)*('HS - PY data'!$G$2:$G$49952))} -> 0 | F12: {=SUMPRODUCT(('HS - PY data'!$A$2:$A$49952=$C$4)*('HS - PY data'!$B$2:$B$49952=$D$4)*('HS - PY data'!$C$2:$C$49952=$E$4)*('HS - PY data'!$D$2:$D$49952=F$7)*('HS - PY data'!$F$2:$F$49952=$A12)*('HS - PY data'!$E$2:$E$49952=F$8)*('HS - PY data'!$G$2:$G$49952))} -> 0 | G12: {=SUMPRODUCT(('HS - PY data'!$A$2:$A$49952=$C$4)*('HS - PY data'!$B$2:$B$49952=$D$4)*('HS - PY data'!$C$2:$C$49952=$E$4)*('HS - PY data'!$D$2:$D$49952=G$7)*('HS - PY data'!$F$2:$F$49952=$A12)*('HS - PY data'!$E$2:$E$49952=G$8)*('HS - PY data'!$G$2:$G$49952))} -> 0 | H12: =SUM(B12:G12) -> 0

Sheet HS2 PY
C4: HS2 | D4: =VLOOKUP(Cover!A6,Cover!B319:D331,2,FALSE) -> 2024/25 | E4: =Cover!A10 -> Cumbria
B7: Operational training | C7: Operational training | D7: Fitness training | E7: Fitness training | F7: Routine activities | G7: Routine activities | H7: Total
B8: Wholetime firefighters | C8: On call firefighters | D8: Wholetime firefighters | E8: On call firefighters | F8: Wholetime firefighters | G8: On call firefighters
A9: Total number of personnel injured | B9: {=SUMPRODUCT(('HS - PY data'!$A$2:$A$49952=$C$4)*('HS - PY data'!$B$2:$B$49952=$D$4)*('HS - PY data'!$C$2:$C$49952=$E$4)*('HS - PY data'!$D$2:$D$49952=B$7)*('HS - PY data'!$F$2:$F$49952=$A9)*('HS - PY data'!$E$2:$E$49952=B$8)*('HS - PY data'!$G$2:$G$49952))} -> 0 | C9: {=SUMPRODUCT(('HS - PY data'!$A$2:$A$49952=$C$4)*('HS - PY data'!$B$2:$B$49952=$D$4)*('HS - PY data'!$C$2:$C$49952=$E$4)*('HS - PY data'!$D$2:$D$49952=C$7)*('HS - PY data'!$F$2:$F$49952=$A9)*('HS - PY data'!$E$2:$E$49952=C$8)*('HS - PY data'!$G$2:$G$49952))} -> 0 | D9: {=SUMPRODUCT(('HS - PY data'!$A$2:$A$49952=$C$4)*('HS - PY data'!$B$2:$B$49952=$D$4)*('HS - PY data'!$C$2:$C$49952=$E$4)*('HS - PY data'!$D$2:$D$49952=D$7)*('HS - PY data'!$F$2:$F$49952=$A9)*('HS - PY data'!$E$2:$E$49952=D$8)*('HS - PY data'!$G$2:$G$49952))} -> 0 | E9: {=SUMPRODUCT(('HS - PY data'!$A$2:$A$49952=$C$4)*('HS - PY data'!$B$2:$B$49952=$D$4)*('HS - PY data'!$C$2:$C$49952=$E$4)*('HS - PY data'!$D$2:$D$49952=E$7)*('HS - PY data'!$F$2:$F$49952=$A9)*('HS - PY data'!$E$2:$E$49952=E$8)*('HS - PY data'!$G$2:$G$49952))} -> 0 | F9: {=SUMPRODUCT(('HS - PY data'!$A$2:$A$49952=$C$4)*('HS - PY data'!$B$2:$B$49952=$D$4)*('HS - PY data'!$C$2:$C$49952=$E$4)*('HS - PY data'!$D$2:$D$49952=F$7)*('HS - PY data'!$F$2:$F$49952=$A9)*('HS - PY data'!$E$2:$E$49952=F$8)*('HS - PY data'!$G$2:$G$49952))} -> 0 | G9: {=SUMPRODUCT(('HS - PY data'!$A$2:$A$49952=$C$4)*('HS - PY data'!$B$2:$B$49952=$D$4)*('HS - PY data'!$C$2:$C$49952=$E$4)*('HS - PY data'!$D$2:$D$49952=G$7)*('HS - PY data'!$F$2:$F$49952=$A9)*('HS - PY data'!$E$2:$E$49952=G$8)*('HS - PY data'!$G$2:$G$49952))} -> 0 | H9: =SUM(B9:G9) -> 0
A10: Number of "Over 3 day injuries" | B10: {=SUMPRODUCT(('HS - PY data'!$A$2:$A$49952=$C$4)*('HS - PY data'!$B$2:$B$49952=$D$4)*('HS - PY data'!$C$2:$C$49952=$E$4)*('HS - PY data'!$D$2:$D$49952=B$7)*('HS - PY data'!$F$2:$F$49952=$A10)*('HS - PY data'!$E$2:$E$49952=B$8)*('HS - PY data'!$G$2:$G$49952))} -> 0 | C10: {=SUMPRODUCT(('HS - PY data'!$A$2:$A$49952=$C$4)*('HS - PY data'!$B$2:$B$49952=$D$4)*('HS - PY data'!$C$2:$C$49952=$E$4)*('HS - PY data'!$D$2:$D$49952=C$7)*('HS - PY data'!$F$2:$F$49952=$A10)*('HS - PY data'!$E$2:$E$49952=C$8)*('HS - PY data'!$G$2:$G$49952))} -> 0 | D10: {=SUMPRODUCT(('HS - PY data'!$A$2:$A$49952=$C$4)*('HS - PY data'!$B$2:$B$49952=$D$4)*('HS - PY data'!$C$2:$C$49952=$E$4)*('HS - PY data'!$D$2:$D$49952=D$7)*('HS - PY data'!$F$2:$F$49952=$A10)*('HS - PY data'!$E$2:$E$49952=D$8)*('HS - PY data'!$G$2:$G$49952))} -> 0 | E10: {=SUMPRODUCT(('HS - PY data'!$A$2:$A$49952=$C$4)*('HS - PY data'!$B$2:$B$49952=$D$4)*('HS - PY data'!$C$2:$C$49952=$E$4)*('HS - PY data'!$D$2:$D$49952=E$7)*('HS - PY data'!$F$2:$F$49952=$A10)*('HS - PY data'!$E$2:$E$49952=E$8)*('HS - PY data'!$G$2:$G$49952))} -> 0 | F10: {=SUMPRODUCT(('HS - PY data'!$A$2:$A$49952=$C$4)*('HS - PY data'!$B$2:$B$49952=$D$4)*('HS - PY data'!$C$2:$C$49952=$E$4)*('HS - PY data'!$D$2:$D$49952=F$7)*('HS - PY data'!$F$2:$F$49952=$A10)*('HS - PY data'!$E$2:$E$49952=F$8)*('HS - PY data'!$G$2:$G$49952))} -> 0 | G10: {=SUMPRODUCT(('HS - PY data'!$A$2:$A$49952=$C$4)*('HS - PY data'!$B$2:$B$49952=$D$4)*('HS - PY data'!$C$2:$C$49952=$E$4)*('HS - PY data'!$D$2:$D$49952=G$7)*('HS - PY data'!$F$2:$F$49952=$A10)*('HS - PY data'!$E$2:$E$49952=G$8)*('HS - PY data'!$G$2:$G$49952))} -> 0 | H10: =SUM(B10:G10) -> 0
A11: Number of RIDDOR Major injuries | B11: {=SUMPRODUCT(('HS - PY data'!$A$2:$A$49952=$C$4)*('HS - PY data'!$B$2:$B$49952=$D$4)*('HS - PY data'!$C$2:$C$49952=$E$4)*('HS - PY data'!$D$2:$D$49952=B$7)*('HS - PY data'!$F$2:$F$49952=$A11)*('HS - PY data'!$E$2:$E$49952=B$8)*('HS - PY data'!$G$2:$G$49952))} -> 0 | C11: {=SUMPRODUCT(('HS - PY data'!$A$2:$A$49952=$C$4)*('HS - PY data'!$B$2:$B$49952=$D$4)*('HS - PY data'!$C$2:$C$49952=$E$4)*('HS - PY data'!$D$2:$D$49952=C$7)*('HS - PY data'!$F$2:$F$49952=$A11)*('HS - PY data'!$E$2:$E$49952=C$8)*('HS - PY data'!$G$2:$G$49952))} -> 0 | D11: {=SUMPRODUCT(('HS - PY data'!$A$2:$A$49952=$C$4)*('HS - PY data'!$B$2:$B$49952=$D$4)*('HS - PY data'!$C$2:$C$49952=$E$4)*('HS - PY data'!$D$2:$D$49952=D$7)*('HS - PY data'!$F$2:$F$49952=$A11)*('HS - PY data'!$E$2:$E$49952=D$8)*('HS - PY data'!$G$2:$G$49952))} -> 0 | E11: {=SUMPRODUCT(('HS - PY data'!$A$2:$A$49952=$C$4)*('HS - PY data'!$B$2:$B$49952=$D$4)*('HS - PY data'!$C$2:$C$49952=$E$4)*('HS - PY data'!$D$2:$D$49952=E$7)*('HS - PY data'!$F$2:$F$49952=$A11)*('HS - PY data'!$E$2:$E$49952=E$8)*('HS - PY data'!$G$2:$G$49952))} -> 0 | F11: {=SUMPRODUCT(('HS - PY data'!$A$2:$A$49952=$C$4)*('HS - PY data'!$B$2:$B$49952=$D$4)*('HS - PY data'!$C$2:$C$49952=$E$4)*('HS - PY data'!$D$2:$D$49952=F$7)*('HS - PY data'!$F$2:$F$49952=$A11)*('HS - PY data'!$E$2:$E$49952=F$8)*('HS - PY data'!$G$2:$G$49952))} -> 0 | G11: {=SUMPRODUCT(('HS - PY data'!$A$2:$A$49952=$C$4)*('HS - PY data'!$B$2:$B$49952=$D$4)*('HS - PY data'!$C$2:$C$49952=$E$4)*('HS - PY data'!$D$2:$D$49952=G$7)*('HS - PY data'!$F$2:$F$49952=$A11)*('HS - PY data'!$E$2:$E$49952=G$8)*('HS - PY data'!$G$2:$G$49952))} -> 0 | H11: =SUM(B11:G11) -> 0
A12: Number of fatalities | B12: {=SUMPRODUCT(('HS - PY data'!$A$2:$A$49952=$C$4)*('HS - PY data'!$B$2:$B$49952=$D$4)*('HS - PY data'!$C$2:$C$49952=$E$4)*('HS - PY data'!$D$2:$D$49952=B$7)*('HS - PY data'!$F$2:$F$49952=$A12)*('HS - PY data'!$E$2:$E$49952=B$8)*('HS - PY data'!$G$2:$G$49952))} -> 0 | C12: {=SUMPRODUCT(('HS - PY data'!$A$2:$A$49952=$C$4)*('HS - PY data'!$B$2:$B$49952=$D$4)*('HS - PY data'!$C$2:$C$49952=$E$4)*('HS - PY data'!$D$2:$D$49952=C$7)*('HS - PY data'!$F$2:$F$49952=$A12)*('HS - PY data'!$E$2:$E$49952=C$8)*('HS - PY data'!$G$2:$G$49952))} -> 0 | D12: {=SUMPRODUCT(('HS - PY data'!$A$2:$A$49952=$C$4)*('HS - PY data'!$B$2:$B$49952=$D$4)*('HS - PY data'!$C$2:$C$49952=$E$4)*('HS - PY data'!$D$2:$D$49952=D$7)*('HS - PY data'!$F$2:$F$49952=$A12)*('HS - PY data'!$E$2:$E$49952=D$8)*('HS - PY data'!$G$2:$G$49952))} -> 0 | E12: {=SUMPRODUCT(('HS - PY data'!$A$2:$A$49952=$C$4)*('HS - PY data'!$B$2:$B$49952=$D$4)*('HS - PY data'!$C$2:$C$49952=$E$4)*('HS - PY data'!$D$2:$D$49952=E$7)*('HS - PY data'!$F$2:$F$49952=$A12)*('HS - PY data'!$E$2:$E$49952=E$8)*('HS - PY data'!$G$2:$G$49952))} -> 0 | F12: {=SUMPRODUCT(('HS - PY data'!$A$2:$A$49952=$C$4)*('HS - PY data'!$B$2:$B$49952=$D$4)*('HS - PY data'!$C$2:$C$49952=$E$4)*('HS - PY data'!$D$2:$D$49952=F$7)*('HS - PY data'!$F$2:$F$49952=$A12)*('HS - PY data'!$E$2:$E$49952=F$8)*('HS - PY data'!$G$2:$G$49952))} -> 0 | G12: {=SUMPRODUCT(('HS - PY data'!$A$2:$A$49952=$C$4)*('HS - PY data'!$B$2:$B$49952=$D$4)*('HS - PY data'!$C$2:$C$49952=$E$4)*('HS - PY data'!$D$2:$D$49952=G$7)*('HS - PY data'!$F$2:$F$49952=$A12)*('HS - PY data'!$E$2:$E$49952=G$8)*('HS - PY data'!$G$2:$G$49952))} -> 0 | H12: =SUM(B12:G12) -> 0

Sheet QA check thresholds
A5: Absolute value threshold
A6: 40
A7: Percentage thresholds
A8: 0.5
A9: 1.5
